2021-04-15 00:00:19,604 - DEBUG - ServiceRegister - [EtcdSupport.py:196]: outside, time.time()=1618416019.6038241, refresh service dispatcher_service, now_url: http://127.0.0.1:2379/v2/keys/services/dispatcher_service/127.0.0.1|9100
2021-04-15 00:00:19,620 - DEBUG - ServiceRegister - [EtcdSupport.py:214]: time.time()=1618416019.6198661, refresh service success: dispatcher_service: {"action":"set","node":{"key":"/services/dispatcher_service/127.0.0.1|9100","value":"","expiration":"2021-04-14T16:03:19.6138771Z","ttl":180,"modifiedIndex":3687,"createdIndex":3687},"prevNode":{"key":"/services/dispatcher_service/127.0.0.1|9100","value":"","expiration":"2021-04-14T16:01:29.6011434Z","ttl":70,"modifiedIndex":3683,"createdIndex":3683}}
, now_url: http://127.0.0.1:2379/v2/keys/services/dispatcher_service/127.0.0.1|9100
2021-04-15 00:01:00,996 - DEBUG - ServiceFinder - [EtcdSupport.py:475]: etcd watch timeout, rest watch index 3684 -> 3685
2021-04-15 00:01:59,627 - DEBUG - ServiceRegister - [EtcdSupport.py:196]: outside, time.time()=1618416119.6261938, refresh service dispatcher_service, now_url: http://127.0.0.1:2379/v2/keys/services/dispatcher_service/127.0.0.1|9100
2021-04-15 00:01:59,642 - DEBUG - ServiceRegister - [EtcdSupport.py:214]: time.time()=1618416119.6413722, refresh service success: dispatcher_service: {"action":"set","node":{"key":"/services/dispatcher_service/127.0.0.1|9100","value":"","expiration":"2021-04-14T16:04:59.6343836Z","ttl":180,"modifiedIndex":3691,"createdIndex":3691},"prevNode":{"key":"/services/dispatcher_service/127.0.0.1|9100","value":"","expiration":"2021-04-14T16:03:19.6138771Z","ttl":80,"modifiedIndex":3687,"createdIndex":3687}}
, now_url: http://127.0.0.1:2379/v2/keys/services/dispatcher_service/127.0.0.1|9100
2021-04-15 00:02:08,000 - DEBUG - ServiceFinder - [EtcdSupport.py:475]: etcd watch timeout, rest watch index 3685 -> 3688
2021-04-15 00:03:16,996 - DEBUG - ServiceFinder - [EtcdSupport.py:475]: etcd watch timeout, rest watch index 3688 -> 3691
2021-04-15 00:03:46,637 - DEBUG - ServiceRegister - [EtcdSupport.py:196]: outside, time.time()=1618416226.6364422, refresh service dispatcher_service, now_url: http://127.0.0.1:2379/v2/keys/services/dispatcher_service/127.0.0.1|9100
2021-04-15 00:03:46,650 - DEBUG - ServiceRegister - [EtcdSupport.py:214]: time.time()=1618416226.6494114, refresh service success: dispatcher_service: {"action":"set","node":{"key":"/services/dispatcher_service/127.0.0.1|9100","value":"","expiration":"2021-04-14T16:06:46.6443425Z","ttl":180,"modifiedIndex":3695,"createdIndex":3695},"prevNode":{"key":"/services/dispatcher_service/127.0.0.1|9100","value":"","expiration":"2021-04-14T16:04:59.6343836Z","ttl":73,"modifiedIndex":3691,"createdIndex":3691}}
, now_url: http://127.0.0.1:2379/v2/keys/services/dispatcher_service/127.0.0.1|9100
2021-04-15 00:04:19,000 - DEBUG - ServiceFinder - [EtcdSupport.py:475]: etcd watch timeout, rest watch index 3691 -> 3692
2021-04-15 00:05:19,000 - DEBUG - ServiceFinder - [EtcdSupport.py:475]: etcd watch timeout, rest watch index 3692 -> 3696
2021-04-15 00:05:34,655 - DEBUG - ServiceRegister - [EtcdSupport.py:196]: outside, time.time()=1618416334.653309, refresh service dispatcher_service, now_url: http://127.0.0.1:2381/v2/keys/services/dispatcher_service/127.0.0.1|9100
2021-04-15 00:05:34,671 - DEBUG - ServiceRegister - [EtcdSupport.py:214]: time.time()=1618416334.6702101, refresh service success: dispatcher_service: {"action":"set","node":{"key":"/services/dispatcher_service/127.0.0.1|9100","value":"","expiration":"2021-04-14T16:08:34.6622306Z","ttl":180,"modifiedIndex":3699,"createdIndex":3699},"prevNode":{"key":"/services/dispatcher_service/127.0.0.1|9100","value":"","expiration":"2021-04-14T16:06:46.6443425Z","ttl":72,"modifiedIndex":3695,"createdIndex":3695}}
, now_url: http://127.0.0.1:2381/v2/keys/services/dispatcher_service/127.0.0.1|9100
2021-04-15 00:06:25,998 - DEBUG - ServiceFinder - [EtcdSupport.py:475]: etcd watch timeout, rest watch index 3696 -> 3697
2021-04-15 00:07:15,662 - DEBUG - ServiceRegister - [EtcdSupport.py:196]: outside, time.time()=1618416435.6606016, refresh service dispatcher_service, now_url: http://127.0.0.1:2381/v2/keys/services/dispatcher_service/127.0.0.1|9100
2021-04-15 00:07:15,675 - DEBUG - ServiceRegister - [EtcdSupport.py:214]: time.time()=1618416435.6744518, refresh service success: dispatcher_service: {"action":"set","node":{"key":"/services/dispatcher_service/127.0.0.1|9100","value":"","expiration":"2021-04-14T16:10:15.668584Z","ttl":180,"modifiedIndex":3703,"createdIndex":3703},"prevNode":{"key":"/services/dispatcher_service/127.0.0.1|9100","value":"","expiration":"2021-04-14T16:08:34.6622306Z","ttl":79,"modifiedIndex":3699,"createdIndex":3699}}
, now_url: http://127.0.0.1:2381/v2/keys/services/dispatcher_service/127.0.0.1|9100
2021-04-15 00:07:34,004 - DEBUG - ServiceFinder - [EtcdSupport.py:475]: etcd watch timeout, rest watch index 3697 -> 3700
2021-04-15 00:08:39,017 - DEBUG - ServiceFinder - [EtcdSupport.py:475]: etcd watch timeout, rest watch index 3700 -> 3704
2021-04-15 00:09:02,684 - DEBUG - ServiceRegister - [EtcdSupport.py:196]: outside, time.time()=1618416542.6823342, refresh service dispatcher_service, now_url: http://127.0.0.1:2383/v2/keys/services/dispatcher_service/127.0.0.1|9100
2021-04-15 00:09:02,698 - DEBUG - ServiceRegister - [EtcdSupport.py:214]: time.time()=1618416542.6962817, refresh service success: dispatcher_service: {"action":"set","node":{"key":"/services/dispatcher_service/127.0.0.1|9100","value":"","expiration":"2021-04-14T16:12:02.6901845Z","ttl":180,"modifiedIndex":3707,"createdIndex":3707},"prevNode":{"key":"/services/dispatcher_service/127.0.0.1|9100","value":"","expiration":"2021-04-14T16:10:15.668584Z","ttl":73,"modifiedIndex":3703,"createdIndex":3703}}
, now_url: http://127.0.0.1:2383/v2/keys/services/dispatcher_service/127.0.0.1|9100
2021-04-15 00:09:44,023 - DEBUG - ServiceFinder - [EtcdSupport.py:475]: etcd watch timeout, rest watch index 3704 -> 3705
2021-04-15 00:10:43,688 - DEBUG - ServiceRegister - [EtcdSupport.py:196]: outside, time.time()=1618416643.687844, refresh service dispatcher_service, now_url: http://127.0.0.1:2383/v2/keys/services/dispatcher_service/127.0.0.1|9100
2021-04-15 00:10:43,702 - DEBUG - ServiceRegister - [EtcdSupport.py:214]: time.time()=1618416643.7017012, refresh service success: dispatcher_service: {"action":"set","node":{"key":"/services/dispatcher_service/127.0.0.1|9100","value":"","expiration":"2021-04-14T16:13:43.6957211Z","ttl":180,"modifiedIndex":3711,"createdIndex":3711},"prevNode":{"key":"/services/dispatcher_service/127.0.0.1|9100","value":"","expiration":"2021-04-14T16:12:02.6901845Z","ttl":79,"modifiedIndex":3707,"createdIndex":3707}}
, now_url: http://127.0.0.1:2383/v2/keys/services/dispatcher_service/127.0.0.1|9100
2021-04-15 00:10:48,018 - DEBUG - ServiceFinder - [EtcdSupport.py:475]: etcd watch timeout, rest watch index 3705 -> 3708
2021-04-15 00:11:54,018 - DEBUG - ServiceFinder - [EtcdSupport.py:475]: etcd watch timeout, rest watch index 3708 -> 3711
2021-04-15 00:12:28,717 - DEBUG - ServiceRegister - [EtcdSupport.py:196]: outside, time.time()=1618416748.7152731, refresh service dispatcher_service, now_url: http://127.0.0.1:2383/v2/keys/services/dispatcher_service/127.0.0.1|9100
2021-04-15 00:12:28,731 - DEBUG - ServiceRegister - [EtcdSupport.py:214]: time.time()=1618416748.7301285, refresh service success: dispatcher_service: {"action":"set","node":{"key":"/services/dispatcher_service/127.0.0.1|9100","value":"","expiration":"2021-04-14T16:15:28.7241457Z","ttl":180,"modifiedIndex":3715,"createdIndex":3715},"prevNode":{"key":"/services/dispatcher_service/127.0.0.1|9100","value":"","expiration":"2021-04-14T16:13:43.6957211Z","ttl":75,"modifiedIndex":3711,"createdIndex":3711}}
, now_url: http://127.0.0.1:2383/v2/keys/services/dispatcher_service/127.0.0.1|9100
2021-04-15 00:13:04,032 - DEBUG - ServiceFinder - [EtcdSupport.py:475]: etcd watch timeout, rest watch index 3711 -> 3712
2021-04-15 00:14:14,044 - DEBUG - ServiceFinder - [EtcdSupport.py:475]: etcd watch timeout, rest watch index 3712 -> 3716
2021-04-15 00:14:15,719 - DEBUG - ServiceRegister - [EtcdSupport.py:196]: outside, time.time()=1618416855.7179177, refresh service dispatcher_service, now_url: http://127.0.0.1:2381/v2/keys/services/dispatcher_service/127.0.0.1|9100
2021-04-15 00:14:15,733 - DEBUG - ServiceRegister - [EtcdSupport.py:214]: time.time()=1618416855.7318723, refresh service success: dispatcher_service: {"action":"set","node":{"key":"/services/dispatcher_service/127.0.0.1|9100","value":"","expiration":"2021-04-14T16:17:15.7259894Z","ttl":180,"modifiedIndex":3719,"createdIndex":3719},"prevNode":{"key":"/services/dispatcher_service/127.0.0.1|9100","value":"","expiration":"2021-04-14T16:15:28.7241457Z","ttl":73,"modifiedIndex":3715,"createdIndex":3715}}
, now_url: http://127.0.0.1:2381/v2/keys/services/dispatcher_service/127.0.0.1|9100
2021-04-15 00:15:17,057 - DEBUG - ServiceFinder - [EtcdSupport.py:475]: etcd watch timeout, rest watch index 3716 -> 3718
2021-04-15 00:15:56,743 - DEBUG - ServiceRegister - [EtcdSupport.py:196]: outside, time.time()=1618416956.742217, refresh service dispatcher_service, now_url: http://127.0.0.1:2381/v2/keys/services/dispatcher_service/127.0.0.1|9100
2021-04-15 00:15:56,759 - DEBUG - ServiceRegister - [EtcdSupport.py:214]: time.time()=1618416956.7571092, refresh service success: dispatcher_service: {"action":"set","node":{"key":"/services/dispatcher_service/127.0.0.1|9100","value":"","expiration":"2021-04-14T16:18:56.7510683Z","ttl":180,"modifiedIndex":3723,"createdIndex":3723},"prevNode":{"key":"/services/dispatcher_service/127.0.0.1|9100","value":"","expiration":"2021-04-14T16:17:15.7259894Z","ttl":79,"modifiedIndex":3719,"createdIndex":3719}}
, now_url: http://127.0.0.1:2381/v2/keys/services/dispatcher_service/127.0.0.1|9100
2021-04-15 00:16:23,048 - DEBUG - ServiceFinder - [EtcdSupport.py:475]: etcd watch timeout, rest watch index 3718 -> 3720
2021-04-15 00:17:28,063 - DEBUG - ServiceFinder - [EtcdSupport.py:475]: etcd watch timeout, rest watch index 3720 -> 3724
2021-04-15 00:17:43,753 - DEBUG - ServiceRegister - [EtcdSupport.py:196]: outside, time.time()=1618417063.75143, refresh service dispatcher_service, now_url: http://127.0.0.1:2381/v2/keys/services/dispatcher_service/127.0.0.1|9100
2021-04-15 00:17:43,767 - DEBUG - ServiceRegister - [EtcdSupport.py:214]: time.time()=1618417063.7664034, refresh service success: dispatcher_service: {"action":"set","node":{"key":"/services/dispatcher_service/127.0.0.1|9100","value":"","expiration":"2021-04-14T16:20:43.7604897Z","ttl":180,"modifiedIndex":3727,"createdIndex":3727},"prevNode":{"key":"/services/dispatcher_service/127.0.0.1|9100","value":"","expiration":"2021-04-14T16:18:56.7510683Z","ttl":73,"modifiedIndex":3723,"createdIndex":3723}}
, now_url: http://127.0.0.1:2381/v2/keys/services/dispatcher_service/127.0.0.1|9100
2021-04-15 00:18:32,075 - DEBUG - ServiceFinder - [EtcdSupport.py:475]: etcd watch timeout, rest watch index 3724 -> 3726
2021-04-15 00:19:24,773 - DEBUG - ServiceRegister - [EtcdSupport.py:196]: outside, time.time()=1618417164.7715824, refresh service dispatcher_service, now_url: http://127.0.0.1:2379/v2/keys/services/dispatcher_service/127.0.0.1|9100
2021-04-15 00:19:24,787 - DEBUG - ServiceRegister - [EtcdSupport.py:214]: time.time()=1618417164.7864568, refresh service success: dispatcher_service: {"action":"set","node":{"key":"/services/dispatcher_service/127.0.0.1|9100","value":"","expiration":"2021-04-14T16:22:24.7795221Z","ttl":180,"modifiedIndex":3731,"createdIndex":3731},"prevNode":{"key":"/services/dispatcher_service/127.0.0.1|9100","value":"","expiration":"2021-04-14T16:20:43.7604897Z","ttl":79,"modifiedIndex":3727,"createdIndex":3727}}
, now_url: http://127.0.0.1:2379/v2/keys/services/dispatcher_service/127.0.0.1|9100
2021-04-15 00:19:40,086 - DEBUG - ServiceFinder - [EtcdSupport.py:475]: etcd watch timeout, rest watch index 3726 -> 3728
2021-04-15 00:20:49,088 - DEBUG - ServiceFinder - [EtcdSupport.py:475]: etcd watch timeout, rest watch index 3728 -> 3732
2021-04-15 00:21:07,789 - DEBUG - ServiceRegister - [EtcdSupport.py:196]: outside, time.time()=1618417267.7876189, refresh service dispatcher_service, now_url: http://127.0.0.1:2381/v2/keys/services/dispatcher_service/127.0.0.1|9100
2021-04-15 00:21:07,807 - DEBUG - ServiceRegister - [EtcdSupport.py:214]: time.time()=1618417267.805469, refresh service success: dispatcher_service: {"action":"set","node":{"key":"/services/dispatcher_service/127.0.0.1|9100","value":"","expiration":"2021-04-14T16:24:07.7974856Z","ttl":180,"modifiedIndex":3735,"createdIndex":3735},"prevNode":{"key":"/services/dispatcher_service/127.0.0.1|9100","value":"","expiration":"2021-04-14T16:22:24.7795221Z","ttl":77,"modifiedIndex":3731,"createdIndex":3731}}
, now_url: http://127.0.0.1:2381/v2/keys/services/dispatcher_service/127.0.0.1|9100
2021-04-15 00:21:51,091 - DEBUG - ServiceFinder - [EtcdSupport.py:475]: etcd watch timeout, rest watch index 3732 -> 3732
2021-04-15 00:22:46,182 - DEBUG - ServiceNode - [EtcdSupport.py:533]: we have create ServiceFinder
2021-04-15 00:22:46,191 - DEBUG - ServiceFinder - [EtcdSupport.py:352]: _init_info, now_url: http://127.0.0.1:2381/v2/keys?recursive=true
2021-04-15 00:22:46,195 - DEBUG - ServiceRegister - [EtcdSupport.py:155]: _do_regist: now_url: http://127.0.0.1:2381/v2/keys/services/dispatcher_service/127.0.0.1|9100
2021-04-15 00:22:46,201 - DEBUG - TcpServer - [TcpServer.py:189]: Server on ('127.0.0.1', 9100)
2021-04-15 00:22:46,216 - DEBUG - ServiceFinder - [EtcdSupport.py:323]: add service node info--> dispatcher_service: ('127.0.0.1', 9100)
2021-04-15 00:22:46,218 - DEBUG - ServiceFinder - [EtcdSupport.py:323]: add service node info--> battle_server: ('127.0.0.1', 8888)
2021-04-15 00:22:46,220 - DEBUG - ServiceFinder - [EtcdSupport.py:323]: add service node info--> battle_server: ('127.0.0.1', 9003)
2021-04-15 00:22:46,221 - DEBUG - ServiceFinder - [EtcdSupport.py:323]: add service node info--> battle_server: ('127.0.0.1', 9001)
2021-04-15 00:22:46,223 - DEBUG - ServiceFinder - [EtcdSupport.py:277]: init service info from etcd success, will going to watch, at etcd index -> 3738
2021-04-15 00:22:46,230 - DEBUG - ServiceRegister - [EtcdSupport.py:163]: regist service : dispatcher_service success, {"action":"set","node":{"key":"/services/dispatcher_service/127.0.0.1|9100","value":"","expiration":"2021-04-14T16:25:46.2104126Z","ttl":180,"modifiedIndex":3739,"createdIndex":3739},"prevNode":{"key":"/services/dispatcher_service/127.0.0.1|9100","value":"","expiration":"2021-04-14T16:24:07.7974856Z","ttl":82,"modifiedIndex":3735,"createdIndex":3735}}

2021-04-15 00:22:46,239 - DEBUG - ServiceFinder - [EtcdSupport.py:422]: recv watch set service node info--> dispatcher_service: ('127.0.0.1', 9100) - [3739]
2021-04-15 00:22:46,240 - DEBUG - ServiceFinder - [EtcdSupport.py:299]: duplicate service info  -> dispatcher_service:('127.0.0.1', 9100)
2021-04-15 00:22:46,551 - DEBUG - TcpServer - [TcpServer.py:175]: ('127.0.0.1', 3522) is connected !!!!
2021-04-15 00:22:46,560 - DEBUG - TcpServer - [TcpServer.py:175]: ('127.0.0.1', 3521) is connected !!!!
2021-04-15 00:22:46,566 - DEBUG - TcpServer - [TcpServer.py:175]: ('127.0.0.1', 3523) is connected !!!!
2021-04-15 00:22:46,809 - DEBUG - ServerEntity.LoadCollector - [ServerEntity.py:25]: __init__ create entity LoadCollector with id 607716d6d1641203dc5d5b4f mem_id=2265604618608
2021-04-15 00:22:46,812 - DEBUG - server.EntityManager - [EntityManager.py:139]: addentity  entity id  607716d6d1641203dc5d5b4f 
2021-04-15 00:22:48,215 - DEBUG - ServerEntity.LoadCollector - [ServerEntity.py:25]: __init__ create entity LoadCollector with id 607716d8d1641203dc5d5b50 mem_id=2265604103808
2021-04-15 00:22:48,217 - DEBUG - server.EntityManager - [EntityManager.py:139]: addentity  entity id  607716d8d1641203dc5d5b50 
2021-04-15 00:22:50,216 - DEBUG - ServerEntity.LoadCollector - [ServerEntity.py:25]: __init__ create entity LoadCollector with id 607716dad1641203dc5d5b51 mem_id=2265604100400
2021-04-15 00:22:50,217 - DEBUG - server.EntityManager - [EntityManager.py:139]: addentity  entity id  607716dad1641203dc5d5b51 
2021-04-15 00:23:02,009 - DEBUG - ServiceNode - [EtcdSupport.py:533]: we have create ServiceFinder
2021-04-15 00:23:02,014 - DEBUG - ServiceFinder - [EtcdSupport.py:352]: _init_info, now_url: http://127.0.0.1:2383/v2/keys?recursive=true
2021-04-15 00:23:02,017 - DEBUG - ServiceRegister - [EtcdSupport.py:155]: _do_regist: now_url: http://127.0.0.1:2381/v2/keys/services/dispatcher_service/127.0.0.1|9100
2021-04-15 00:23:02,022 - DEBUG - TcpServer - [TcpServer.py:189]: Server on ('127.0.0.1', 9100)
2021-04-15 00:23:02,034 - DEBUG - ServiceFinder - [EtcdSupport.py:323]: add service node info--> dispatcher_service: ('127.0.0.1', 9100)
2021-04-15 00:23:02,036 - DEBUG - ServiceFinder - [EtcdSupport.py:323]: add service node info--> battle_server: ('127.0.0.1', 8888)
2021-04-15 00:23:02,037 - DEBUG - ServiceFinder - [EtcdSupport.py:323]: add service node info--> battle_server: ('127.0.0.1', 9003)
2021-04-15 00:23:02,039 - DEBUG - ServiceFinder - [EtcdSupport.py:323]: add service node info--> battle_server: ('127.0.0.1', 9001)
2021-04-15 00:23:02,041 - DEBUG - ServiceFinder - [EtcdSupport.py:277]: init service info from etcd success, will going to watch, at etcd index -> 3739
2021-04-15 00:23:02,046 - DEBUG - ServiceRegister - [EtcdSupport.py:163]: regist service : dispatcher_service success, {"action":"set","node":{"key":"/services/dispatcher_service/127.0.0.1|9100","value":"","expiration":"2021-04-14T16:26:02.0316478Z","ttl":180,"modifiedIndex":3740,"createdIndex":3740},"prevNode":{"key":"/services/dispatcher_service/127.0.0.1|9100","value":"","expiration":"2021-04-14T16:25:46.2104126Z","ttl":165,"modifiedIndex":3739,"createdIndex":3739}}

2021-04-15 00:23:02,051 - DEBUG - ServiceFinder - [EtcdSupport.py:422]: recv watch set service node info--> dispatcher_service: ('127.0.0.1', 9100) - [3740]
2021-04-15 00:23:02,053 - DEBUG - ServiceFinder - [EtcdSupport.py:299]: duplicate service info  -> dispatcher_service:('127.0.0.1', 9100)
2021-04-15 00:23:50,601 - CRITICAL - ServiceFinder - [EtcdSupport.py:481]: on_traceback, type:<class 'aiohttp.client_exceptions.ClientPayloadError'>, value:Response payload is not completed, traceback:<class 'aiohttp.client_exceptions.ClientPayloadError'>
Response payload is not completed
  File "C:\Users\b\Documents\github\realtime-server\pycharm2020.1.3\script\core\EtcdSupport.py", line 466, in _watch_process
    locals={'self': <core.EtcdSupport.ServiceFinder object at 0x000002802EA41A30>, }
  File "C:\Program Files\Python38\lib\asyncio\tasks.py", line 494, in wait_for
    locals={'fut': <Task finished name='Task-16' coro=<ServiceFinder._watch_process_impl() done, defined at C:\Users\b\Documents\github\realtime-server\pycharm2020.1.3\script\core\EtcdSupport.py:391> exception=ClientPayloadError('Response payload is not completed') created at C:\Program Files\Python38\lib\asyncio\tasks.py:475>, 'timeout': 63, 'loop': <ProactorEventLoop running=True closed=False debug=True>, 'waiter': <Future finished result=None created at C:\Program Files\Python38\lib\asyncio\base_events.py:422>, 'timeout_handle': <TimerHandle cancelled when=437867.187 _release_waiter(<Future finis...events.py:422>) at C:\Program Files\Python38\lib\asyncio\tasks.py:429 created at C:\Program Files\Python38\lib\asyncio\tasks.py:472>, 'cb': functools.partial(<function _release_waiter at 0x000002802DC4FCA0>, <Future finished result=None created at C:\Program Files\Python38\lib\asyncio\base_events.py:422>)}
  File "C:\Users\b\Documents\github\realtime-server\pycharm2020.1.3\script\core\EtcdSupport.py", line 405, in _watch_process_impl
    locals={'self': <core.EtcdSupport.ServiceFinder object at 0x000002802EA41A30>, '_': '{"action":"get","node":{"dir":true,"nodes":[{"key":"/services","dir":true,"modifiedIndex":8,"createdIndex":8}]}}\n', 'r_headers': <CIMultiDictProxy('Content-Type': 'application/json', 'X-Etcd-Cluster-Id': '659fb89f2dd4e446', 'X-Etcd-Index': '3740', 'X-Raft-Index': '80599', 'X-Raft-Term': '5', 'Date': 'Wed, 14 Apr 2021 16:23:02 GMT', 'Content-Length': '113')>, 'now_url': 'http://127.0.0.1:2379/v2/keys?wait=true&recursive=true&waitIndex=3741'}
  File "C:\Users\b\Documents\github\realtime-server\pycharm2020.1.3\script\core\util\UtilApi.py", line 138, in async_http_requests
    locals={'method': 'get', 'url': 'http://127.0.0.1:2379/v2/keys?wait=true&recursive=true&waitIndex=3741', 'session': <aiohttp.client.ClientSession object at 0x000002802EBBC700>, 'kwargs': {}, '_async_http_requests_impl': <function async_http_requests.<locals>._async_http_requests_impl at 0x000002802ECD2EE0>}
  File "C:\Users\b\Documents\github\realtime-server\pycharm2020.1.3\script\core\util\UtilApi.py", line 132, in _async_http_requests_impl
    locals={'_method': 'get', '_url': 'http://127.0.0.1:2379/v2/keys?wait=true&recursive=true&waitIndex=3741', '_session': <aiohttp.client.ClientSession object at 0x000002802EBBC700>, '_kwargs': {}, 'response': <ClientResponse(http://127.0.0.1:2379/v2/keys?wait=true&recursive=true&waitIndex=3741) [200 OK]>
<CIMultiDictProxy('Content-Type': 'application/json', 'X-Etcd-Cluster-Id': '659fb89f2dd4e446', 'X-Etcd-Index': '3740', 'X-Raft-Index': '80599', 'X-Raft-Term': '5', 'Date': 'Wed, 14 Apr 2021 16:23:02 GMT', 'Transfer-Encoding': 'chunked')>
}
  File "C:\Program Files\Python38\lib\site-packages\aiohttp\client_reqrep.py", line 1076, in text
    locals={'self': <ClientResponse(http://127.0.0.1:2379/v2/keys?wait=true&recursive=true&waitIndex=3741) [200 OK]>
<CIMultiDictProxy('Content-Type': 'application/json', 'X-Etcd-Cluster-Id': '659fb89f2dd4e446', 'X-Etcd-Index': '3740', 'X-Raft-Index': '80599', 'X-Raft-Term': '5', 'Date': 'Wed, 14 Apr 2021 16:23:02 GMT', 'Transfer-Encoding': 'chunked')>
, 'encoding': None, 'errors': 'strict'}
  File "C:\Program Files\Python38\lib\site-packages\aiohttp\client_reqrep.py", line 1032, in read
    locals={'self': <ClientResponse(http://127.0.0.1:2379/v2/keys?wait=true&recursive=true&waitIndex=3741) [200 OK]>
<CIMultiDictProxy('Content-Type': 'application/json', 'X-Etcd-Cluster-Id': '659fb89f2dd4e446', 'X-Etcd-Index': '3740', 'X-Raft-Index': '80599', 'X-Raft-Term': '5', 'Date': 'Wed, 14 Apr 2021 16:23:02 GMT', 'Transfer-Encoding': 'chunked')>
, }
  File "C:\Program Files\Python38\lib\site-packages\aiohttp\streams.py", line 370, in read
    locals={'self': <StreamReader e=ClientPayloadError('Response payload is not completed')>, 'n': -1, 'blocks': []}
  File "C:\Program Files\Python38\lib\site-packages\aiohttp\streams.py", line 392, in readany
    locals={'self': <StreamReader e=ClientPayloadError('Response payload is not completed')>, }
  File "C:\Program Files\Python38\lib\site-packages\aiohttp\streams.py", line 306, in _wait
    locals={'self': <StreamReader e=ClientPayloadError('Response payload is not completed')>, 'func_name': 'readany', 'waiter': <Future finished exception=ClientPayloadError('Response payload is not completed') created at C:\Program Files\Python38\lib\asyncio\base_events.py:422>}
2021-04-15 00:23:52,622 - CRITICAL - ServiceFinder - [EtcdSupport.py:481]: on_traceback, type:<class 'aiohttp.client_exceptions.ClientConnectorError'>, value:Cannot connect to host 127.0.0.1:2383 ssl:default [The remote computer refused the network connection], traceback:<class 'aiohttp.client_exceptions.ClientConnectorError'>
Cannot connect to host 127.0.0.1:2383 ssl:default [The remote computer refused the network connection]
  File "C:\Users\b\Documents\github\realtime-server\pycharm2020.1.3\script\core\EtcdSupport.py", line 466, in _watch_process
    locals={'self': <core.EtcdSupport.ServiceFinder object at 0x000002802EA41A30>, }
  File "C:\Program Files\Python38\lib\asyncio\tasks.py", line 494, in wait_for
    locals={'fut': <Task finished name='Task-20' coro=<ServiceFinder._watch_process_impl() done, defined at C:\Users\b\Documents\github\realtime-server\pycharm2020.1.3\script\core\EtcdSupport.py:391> exception=ClientConnectorError(ConnectionKey(host='127.0.0.1', port=2383, is_ssl=False, ssl=None, proxy=None, proxy_auth=None, proxy_headers_hash=None), ConnectionRefusedError(22, 'The remote computer refused the network connection', None, 1225, None)) created at C:\Program Files\Python38\lib\asyncio\tasks.py:475>, 'timeout': 67, 'loop': <ProactorEventLoop running=True closed=False debug=True>, 'waiter': <Future finished result=None created at C:\Program Files\Python38\lib\asyncio\base_events.py:422>, 'timeout_handle': <TimerHandle cancelled when=437919.734 _release_waiter(<Future finis...events.py:422>) at C:\Program Files\Python38\lib\asyncio\tasks.py:429 created at C:\Program Files\Python38\lib\asyncio\tasks.py:472>, 'cb': functools.partial(<function _release_waiter at 0x000002802DC4FCA0>, <Future finished result=None cr...
  File "C:\Users\b\Documents\github\realtime-server\pycharm2020.1.3\script\core\EtcdSupport.py", line 405, in _watch_process_impl
    locals={'self': <core.EtcdSupport.ServiceFinder object at 0x000002802EA41A30>, '_': '{"action":"get","node":{"dir":true,"nodes":[{"key":"/services","dir":true,"modifiedIndex":8,"createdIndex":8}]}}\n', 'r_headers': <CIMultiDictProxy('Content-Type': 'application/json', 'X-Etcd-Cluster-Id': '659fb89f2dd4e446', 'X-Etcd-Index': '3740', 'X-Raft-Index': '80696', 'X-Raft-Term': '5', 'Date': 'Wed, 14 Apr 2021 16:23:50 GMT', 'Content-Length': '113')>, 'now_url': 'http://127.0.0.1:2383/v2/keys?wait=true&recursive=true&waitIndex=3741'}
  File "C:\Users\b\Documents\github\realtime-server\pycharm2020.1.3\script\core\util\UtilApi.py", line 138, in async_http_requests
    locals={'method': 'get', 'url': 'http://127.0.0.1:2383/v2/keys?wait=true&recursive=true&waitIndex=3741', 'session': <aiohttp.client.ClientSession object at 0x000002802EBBC700>, 'kwargs': {}, '_async_http_requests_impl': <function async_http_requests.<locals>._async_http_requests_impl at 0x000002802EC7E8B0>}
  File "C:\Users\b\Documents\github\realtime-server\pycharm2020.1.3\script\core\util\UtilApi.py", line 131, in _async_http_requests_impl
    locals={'_method': 'get', '_url': 'http://127.0.0.1:2383/v2/keys?wait=true&recursive=true&waitIndex=3741', '_session': <aiohttp.client.ClientSession object at 0x000002802EBBC700>, '_kwargs': {}}
  File "C:\Program Files\Python38\lib\site-packages\aiohttp\client.py", line 1117, in __aenter__
    locals={'self': <aiohttp.client._RequestContextManager object at 0x000002802ECF2300>, }
  File "C:\Program Files\Python38\lib\site-packages\aiohttp\client.py", line 520, in _request
    locals={'self': <aiohttp.client.ClientSession object at 0x000002802EBBC700>, 'method': 'GET', 'str_or_url': 'http://127.0.0.1:2383/v2/keys?wait=true&recursive=true&waitIndex=3741', 'params': None, 'data': None, 'json': None, 'cookies': None, 'headers': <CIMultiDict()>, 'skip_auto_headers': None, 'auth': None, 'allow_redirects': True, 'max_redirects': 10, 'compress': None, 'chunked': None, 'expect100': False, 'raise_for_status': None, 'read_until_eof': True, 'proxy': None, 'proxy_auth': None, 'timeout': <object object at 0x000002802E014FC0>, 'verify_ssl': None, 'fingerprint': None, 'ssl_context': None, 'ssl': None, 'proxy_headers': <CIMultiDict()>, 'read_bufsize': 65536, 'redirects': 0, 'history': [], 'version': HttpVersion(major=1, minor=1), 'url': URL('http://127.0.0.1:2383/v2/keys?wait=true&recursive=true&waitIndex=3741'), 'skip_headers': set(), 'real_timeout': ClientTimeout(total=300, connect=None, sock_read=None, sock_connect=None), 'tm': <aiohttp.helpers.TimeoutHandle object at 0x000002802EBBCFD0>, 'handle': No...
  File "C:\Program Files\Python38\lib\site-packages\aiohttp\connector.py", line 535, in connect
    locals={'self': <aiohttp.connector.TCPConnector object at 0x000002802EBBC7C0>, 'req': <aiohttp.client_reqrep.ClientRequest object at 0x000002802EBBCA60>, 'traces': [], 'timeout': ClientTimeout(total=300, connect=None, sock_read=None, sock_connect=None), 'key': ConnectionKey(host='127.0.0.1', port=2383, is_ssl=False, ssl=None, proxy=None, proxy_auth=None, proxy_headers_hash=None), 'available': 100, 'proto': None, 'placeholder': <aiohttp.connector._TransportPlaceholder object at 0x000002802ECB1400>}
  File "C:\Program Files\Python38\lib\site-packages\aiohttp\connector.py", line 892, in _create_connection
    locals={'self': <aiohttp.connector.TCPConnector object at 0x000002802EBBC7C0>, 'req': <aiohttp.client_reqrep.ClientRequest object at 0x000002802EBBCA60>, 'traces': [], 'timeout': ClientTimeout(total=300, connect=None, sock_read=None, sock_connect=None)}
  File "C:\Program Files\Python38\lib\site-packages\aiohttp\connector.py", line 1051, in _create_direct_connection
    locals={'self': <aiohttp.connector.TCPConnector object at 0x000002802EBBC7C0>, 'req': <aiohttp.client_reqrep.ClientRequest object at 0x000002802EBBCA60>, 'traces': [], 'timeout': ClientTimeout(total=300, connect=None, sock_read=None, sock_connect=None), 'client_error': <class 'aiohttp.client_exceptions.ClientConnectorError'>, 'sslcontext': None, 'fingerprint': None, 'host': '127.0.0.1', 'port': 2383, 'host_resolved': <Task finished name='Task-23' coro=<TCPConnector._resolve_host() done, defined at C:\Program Files\Python38\lib\site-packages\aiohttp\connector.py:806> result=[{'family': 0, 'flags': 0, 'host': '127.0.0.1', 'hostname': '127.0.0.1', ...}] created at C:\Program Files\Python38\lib\site-packages\aiohttp\connector.py:992>, 'hosts': [{'hostname': '127.0.0.1', 'host': '127.0.0.1', 'port': 2383, 'family': 0, 'proto': 0, 'flags': 0}], 'last_exc': ClientConnectorError(ConnectionKey(host='127.0.0.1', port=2383, is_ssl=False, ssl=None, proxy=None, proxy_auth=None, proxy_headers_hash=None), ConnectionRefusedError(22...
  File "C:\Program Files\Python38\lib\site-packages\aiohttp\connector.py", line 1020, in _create_direct_connection
    locals={'self': <aiohttp.connector.TCPConnector object at 0x000002802EBBC7C0>, 'req': <aiohttp.client_reqrep.ClientRequest object at 0x000002802EBBCA60>, 'traces': [], 'timeout': ClientTimeout(total=300, connect=None, sock_read=None, sock_connect=None), 'client_error': <class 'aiohttp.client_exceptions.ClientConnectorError'>, 'sslcontext': None, 'fingerprint': None, 'host': '127.0.0.1', 'port': 2383, 'host_resolved': <Task finished name='Task-23' coro=<TCPConnector._resolve_host() done, defined at C:\Program Files\Python38\lib\site-packages\aiohttp\connector.py:806> result=[{'family': 0, 'flags': 0, 'host': '127.0.0.1', 'hostname': '127.0.0.1', ...}] created at C:\Program Files\Python38\lib\site-packages\aiohttp\connector.py:992>, 'hosts': [{'hostname': '127.0.0.1', 'host': '127.0.0.1', 'port': 2383, 'family': 0, 'proto': 0, 'flags': 0}], 'last_exc': ClientConnectorError(ConnectionKey(host='127.0.0.1', port=2383, is_ssl=False, ssl=None, proxy=None, proxy_auth=None, proxy_headers_hash=None), ConnectionRefusedError(22...
  File "C:\Program Files\Python38\lib\site-packages\aiohttp\connector.py", line 975, in _wrap_create_connection
    locals={'self': <aiohttp.connector.TCPConnector object at 0x000002802EBBC7C0>, 'req': <aiohttp.client_reqrep.ClientRequest object at 0x000002802EBBCA60>, 'timeout': ClientTimeout(total=300, connect=None, sock_read=None, sock_connect=None), 'client_error': <class 'aiohttp.client_exceptions.ClientConnectorError'>, 'args': (functools.partial(<class 'aiohttp.client_proto.ResponseHandler'>, loop=<ProactorEventLoop running=True closed=False debug=True>), '127.0.0.1', 2383), 'kwargs': {'ssl': None, 'family': 0, 'proto': 0, 'flags': 0, 'server_hostname': None, 'local_addr': None}}
2021-04-15 00:23:54,632 - CRITICAL - ServiceFinder - [EtcdSupport.py:481]: on_traceback, type:<class 'aiohttp.client_exceptions.ClientConnectorError'>, value:Cannot connect to host 127.0.0.1:2381 ssl:default [The remote computer refused the network connection], traceback:<class 'aiohttp.client_exceptions.ClientConnectorError'>
Cannot connect to host 127.0.0.1:2381 ssl:default [The remote computer refused the network connection]
  File "C:\Users\b\Documents\github\realtime-server\pycharm2020.1.3\script\core\EtcdSupport.py", line 466, in _watch_process
    locals={'self': <core.EtcdSupport.ServiceFinder object at 0x000002802EA41A30>, }
  File "C:\Program Files\Python38\lib\asyncio\tasks.py", line 494, in wait_for
    locals={'fut': <Task finished name='Task-24' coro=<ServiceFinder._watch_process_impl() done, defined at C:\Users\b\Documents\github\realtime-server\pycharm2020.1.3\script\core\EtcdSupport.py:391> exception=ClientConnectorError(ConnectionKey(host='127.0.0.1', port=2381, is_ssl=False, ssl=None, proxy=None, proxy_auth=None, proxy_headers_hash=None), ConnectionRefusedError(22, 'The remote computer refused the network connection', None, 1225, None)) created at C:\Program Files\Python38\lib\asyncio\tasks.py:475>, 'timeout': 65, 'loop': <ProactorEventLoop running=True closed=False debug=True>, 'waiter': <Future finished result=None created at C:\Program Files\Python38\lib\asyncio\base_events.py:422>, 'timeout_handle': <TimerHandle cancelled when=437919.765 _release_waiter(<Future finis...events.py:422>) at C:\Program Files\Python38\lib\asyncio\tasks.py:429 created at C:\Program Files\Python38\lib\asyncio\tasks.py:472>, 'cb': functools.partial(<function _release_waiter at 0x000002802DC4FCA0>, <Future finished result=None cr...
  File "C:\Users\b\Documents\github\realtime-server\pycharm2020.1.3\script\core\EtcdSupport.py", line 395, in _watch_process_impl
    locals={'self': <core.EtcdSupport.ServiceFinder object at 0x000002802EA41A30>, }
  File "C:\Users\b\Documents\github\realtime-server\pycharm2020.1.3\script\core\util\UtilApi.py", line 138, in async_http_requests
    locals={'method': 'get', 'url': 'http://127.0.0.1:2381/v2/keys', 'session': <aiohttp.client.ClientSession object at 0x000002802EBBC700>, 'kwargs': {}, '_async_http_requests_impl': <function async_http_requests.<locals>._async_http_requests_impl at 0x000002802ED19550>}
  File "C:\Users\b\Documents\github\realtime-server\pycharm2020.1.3\script\core\util\UtilApi.py", line 131, in _async_http_requests_impl
    locals={'_method': 'get', '_url': 'http://127.0.0.1:2381/v2/keys', '_session': <aiohttp.client.ClientSession object at 0x000002802EBBC700>, '_kwargs': {}}
  File "C:\Program Files\Python38\lib\site-packages\aiohttp\client.py", line 1117, in __aenter__
    locals={'self': <aiohttp.client._RequestContextManager object at 0x000002802ED20B40>, }
  File "C:\Program Files\Python38\lib\site-packages\aiohttp\client.py", line 520, in _request
    locals={'self': <aiohttp.client.ClientSession object at 0x000002802EBBC700>, 'method': 'GET', 'str_or_url': 'http://127.0.0.1:2381/v2/keys', 'params': None, 'data': None, 'json': None, 'cookies': None, 'headers': <CIMultiDict()>, 'skip_auto_headers': None, 'auth': None, 'allow_redirects': True, 'max_redirects': 10, 'compress': None, 'chunked': None, 'expect100': False, 'raise_for_status': None, 'read_until_eof': True, 'proxy': None, 'proxy_auth': None, 'timeout': <object object at 0x000002802E014FC0>, 'verify_ssl': None, 'fingerprint': None, 'ssl_context': None, 'ssl': None, 'proxy_headers': <CIMultiDict()>, 'read_bufsize': 65536, 'redirects': 0, 'history': [], 'version': HttpVersion(major=1, minor=1), 'url': URL('http://127.0.0.1:2381/v2/keys'), 'skip_headers': set(), 'real_timeout': ClientTimeout(total=300, connect=None, sock_read=None, sock_connect=None), 'tm': <aiohttp.helpers.TimeoutHandle object at 0x000002802ECB1490>, 'handle': None, 'traces': [], 'timer': <aiohttp.helpers.TimerContext object at 0x000002802EC...
  File "C:\Program Files\Python38\lib\site-packages\aiohttp\connector.py", line 535, in connect
    locals={'self': <aiohttp.connector.TCPConnector object at 0x000002802EBBC7C0>, 'req': <aiohttp.client_reqrep.ClientRequest object at 0x000002802ECB1640>, 'traces': [], 'timeout': ClientTimeout(total=300, connect=None, sock_read=None, sock_connect=None), 'key': ConnectionKey(host='127.0.0.1', port=2381, is_ssl=False, ssl=None, proxy=None, proxy_auth=None, proxy_headers_hash=None), 'available': 100, 'proto': None, 'placeholder': <aiohttp.connector._TransportPlaceholder object at 0x000002802ECB16A0>}
  File "C:\Program Files\Python38\lib\site-packages\aiohttp\connector.py", line 892, in _create_connection
    locals={'self': <aiohttp.connector.TCPConnector object at 0x000002802EBBC7C0>, 'req': <aiohttp.client_reqrep.ClientRequest object at 0x000002802ECB1640>, 'traces': [], 'timeout': ClientTimeout(total=300, connect=None, sock_read=None, sock_connect=None)}
  File "C:\Program Files\Python38\lib\site-packages\aiohttp\connector.py", line 1051, in _create_direct_connection
    locals={'self': <aiohttp.connector.TCPConnector object at 0x000002802EBBC7C0>, 'req': <aiohttp.client_reqrep.ClientRequest object at 0x000002802ECB1640>, 'traces': [], 'timeout': ClientTimeout(total=300, connect=None, sock_read=None, sock_connect=None), 'client_error': <class 'aiohttp.client_exceptions.ClientConnectorError'>, 'sslcontext': None, 'fingerprint': None, 'host': '127.0.0.1', 'port': 2381, 'host_resolved': <Task finished name='Task-25' coro=<TCPConnector._resolve_host() done, defined at C:\Program Files\Python38\lib\site-packages\aiohttp\connector.py:806> result=[{'family': 0, 'flags': 0, 'host': '127.0.0.1', 'hostname': '127.0.0.1', ...}] created at C:\Program Files\Python38\lib\site-packages\aiohttp\connector.py:992>, 'hosts': [{'hostname': '127.0.0.1', 'host': '127.0.0.1', 'port': 2381, 'family': 0, 'proto': 0, 'flags': 0}], 'last_exc': ClientConnectorError(ConnectionKey(host='127.0.0.1', port=2381, is_ssl=False, ssl=None, proxy=None, proxy_auth=None, proxy_headers_hash=None), ConnectionRefusedError(22...
  File "C:\Program Files\Python38\lib\site-packages\aiohttp\connector.py", line 1020, in _create_direct_connection
    locals={'self': <aiohttp.connector.TCPConnector object at 0x000002802EBBC7C0>, 'req': <aiohttp.client_reqrep.ClientRequest object at 0x000002802ECB1640>, 'traces': [], 'timeout': ClientTimeout(total=300, connect=None, sock_read=None, sock_connect=None), 'client_error': <class 'aiohttp.client_exceptions.ClientConnectorError'>, 'sslcontext': None, 'fingerprint': None, 'host': '127.0.0.1', 'port': 2381, 'host_resolved': <Task finished name='Task-25' coro=<TCPConnector._resolve_host() done, defined at C:\Program Files\Python38\lib\site-packages\aiohttp\connector.py:806> result=[{'family': 0, 'flags': 0, 'host': '127.0.0.1', 'hostname': '127.0.0.1', ...}] created at C:\Program Files\Python38\lib\site-packages\aiohttp\connector.py:992>, 'hosts': [{'hostname': '127.0.0.1', 'host': '127.0.0.1', 'port': 2381, 'family': 0, 'proto': 0, 'flags': 0}], 'last_exc': ClientConnectorError(ConnectionKey(host='127.0.0.1', port=2381, is_ssl=False, ssl=None, proxy=None, proxy_auth=None, proxy_headers_hash=None), ConnectionRefusedError(22...
  File "C:\Program Files\Python38\lib\site-packages\aiohttp\connector.py", line 975, in _wrap_create_connection
    locals={'self': <aiohttp.connector.TCPConnector object at 0x000002802EBBC7C0>, 'req': <aiohttp.client_reqrep.ClientRequest object at 0x000002802ECB1640>, 'timeout': ClientTimeout(total=300, connect=None, sock_read=None, sock_connect=None), 'client_error': <class 'aiohttp.client_exceptions.ClientConnectorError'>, 'args': (functools.partial(<class 'aiohttp.client_proto.ResponseHandler'>, loop=<ProactorEventLoop running=True closed=False debug=True>), '127.0.0.1', 2381), 'kwargs': {'ssl': None, 'family': 0, 'proto': 0, 'flags': 0, 'server_hostname': None, 'local_addr': None}}
2021-04-15 00:23:56,643 - CRITICAL - ServiceFinder - [EtcdSupport.py:481]: on_traceback, type:<class 'aiohttp.client_exceptions.ClientConnectorError'>, value:Cannot connect to host 127.0.0.1:2383 ssl:default [The remote computer refused the network connection], traceback:<class 'aiohttp.client_exceptions.ClientConnectorError'>
Cannot connect to host 127.0.0.1:2383 ssl:default [The remote computer refused the network connection]
  File "C:\Users\b\Documents\github\realtime-server\pycharm2020.1.3\script\core\EtcdSupport.py", line 466, in _watch_process
    locals={'self': <core.EtcdSupport.ServiceFinder object at 0x000002802EA41A30>, }
  File "C:\Program Files\Python38\lib\asyncio\tasks.py", line 494, in wait_for
    locals={'fut': <Task finished name='Task-26' coro=<ServiceFinder._watch_process_impl() done, defined at C:\Users\b\Documents\github\realtime-server\pycharm2020.1.3\script\core\EtcdSupport.py:391> exception=ClientConnectorError(ConnectionKey(host='127.0.0.1', port=2383, is_ssl=False, ssl=None, proxy=None, proxy_auth=None, proxy_headers_hash=None), ConnectionRefusedError(22, 'The remote computer refused the network connection', None, 1225, None)) created at C:\Program Files\Python38\lib\asyncio\tasks.py:475>, 'timeout': 70, 'loop': <ProactorEventLoop running=True closed=False debug=True>, 'waiter': <Future finished result=None created at C:\Program Files\Python38\lib\asyncio\base_events.py:422>, 'timeout_handle': <TimerHandle cancelled when=437926.765 _release_waiter(<Future finis...events.py:422>) at C:\Program Files\Python38\lib\asyncio\tasks.py:429 created at C:\Program Files\Python38\lib\asyncio\tasks.py:472>, 'cb': functools.partial(<function _release_waiter at 0x000002802DC4FCA0>, <Future finished result=None cr...
  File "C:\Users\b\Documents\github\realtime-server\pycharm2020.1.3\script\core\EtcdSupport.py", line 395, in _watch_process_impl
    locals={'self': <core.EtcdSupport.ServiceFinder object at 0x000002802EA41A30>, }
  File "C:\Users\b\Documents\github\realtime-server\pycharm2020.1.3\script\core\util\UtilApi.py", line 138, in async_http_requests
    locals={'method': 'get', 'url': 'http://127.0.0.1:2383/v2/keys', 'session': <aiohttp.client.ClientSession object at 0x000002802EBBC700>, 'kwargs': {}, '_async_http_requests_impl': <function async_http_requests.<locals>._async_http_requests_impl at 0x000002802EC7EA60>}
  File "C:\Users\b\Documents\github\realtime-server\pycharm2020.1.3\script\core\util\UtilApi.py", line 131, in _async_http_requests_impl
    locals={'_method': 'get', '_url': 'http://127.0.0.1:2383/v2/keys', '_session': <aiohttp.client.ClientSession object at 0x000002802EBBC700>, '_kwargs': {}}
  File "C:\Program Files\Python38\lib\site-packages\aiohttp\client.py", line 1117, in __aenter__
    locals={'self': <aiohttp.client._RequestContextManager object at 0x000002802ED12B80>, }
  File "C:\Program Files\Python38\lib\site-packages\aiohttp\client.py", line 520, in _request
    locals={'self': <aiohttp.client.ClientSession object at 0x000002802EBBC700>, 'method': 'GET', 'str_or_url': 'http://127.0.0.1:2383/v2/keys', 'params': None, 'data': None, 'json': None, 'cookies': None, 'headers': <CIMultiDict()>, 'skip_auto_headers': None, 'auth': None, 'allow_redirects': True, 'max_redirects': 10, 'compress': None, 'chunked': None, 'expect100': False, 'raise_for_status': None, 'read_until_eof': True, 'proxy': None, 'proxy_auth': None, 'timeout': <object object at 0x000002802E014FC0>, 'verify_ssl': None, 'fingerprint': None, 'ssl_context': None, 'ssl': None, 'proxy_headers': <CIMultiDict()>, 'read_bufsize': 65536, 'redirects': 0, 'history': [], 'version': HttpVersion(major=1, minor=1), 'url': URL('http://127.0.0.1:2383/v2/keys'), 'skip_headers': set(), 'real_timeout': ClientTimeout(total=300, connect=None, sock_read=None, sock_connect=None), 'tm': <aiohttp.helpers.TimeoutHandle object at 0x000002802EBBCEE0>, 'handle': None, 'traces': [], 'timer': <aiohttp.helpers.TimerContext object at 0x000002802EB...
  File "C:\Program Files\Python38\lib\site-packages\aiohttp\connector.py", line 535, in connect
    locals={'self': <aiohttp.connector.TCPConnector object at 0x000002802EBBC7C0>, 'req': <aiohttp.client_reqrep.ClientRequest object at 0x000002802ECB1430>, 'traces': [], 'timeout': ClientTimeout(total=300, connect=None, sock_read=None, sock_connect=None), 'key': ConnectionKey(host='127.0.0.1', port=2383, is_ssl=False, ssl=None, proxy=None, proxy_auth=None, proxy_headers_hash=None), 'available': 100, 'proto': None, 'placeholder': <aiohttp.connector._TransportPlaceholder object at 0x000002802ECB1250>}
  File "C:\Program Files\Python38\lib\site-packages\aiohttp\connector.py", line 892, in _create_connection
    locals={'self': <aiohttp.connector.TCPConnector object at 0x000002802EBBC7C0>, 'req': <aiohttp.client_reqrep.ClientRequest object at 0x000002802ECB1430>, 'traces': [], 'timeout': ClientTimeout(total=300, connect=None, sock_read=None, sock_connect=None)}
  File "C:\Program Files\Python38\lib\site-packages\aiohttp\connector.py", line 1051, in _create_direct_connection
    locals={'self': <aiohttp.connector.TCPConnector object at 0x000002802EBBC7C0>, 'req': <aiohttp.client_reqrep.ClientRequest object at 0x000002802ECB1430>, 'traces': [], 'timeout': ClientTimeout(total=300, connect=None, sock_read=None, sock_connect=None), 'client_error': <class 'aiohttp.client_exceptions.ClientConnectorError'>, 'sslcontext': None, 'fingerprint': None, 'host': '127.0.0.1', 'port': 2383, 'host_resolved': <Task finished name='Task-27' coro=<TCPConnector._resolve_host() done, defined at C:\Program Files\Python38\lib\site-packages\aiohttp\connector.py:806> result=[{'family': 0, 'flags': 0, 'host': '127.0.0.1', 'hostname': '127.0.0.1', ...}] created at C:\Program Files\Python38\lib\site-packages\aiohttp\connector.py:992>, 'hosts': [{'hostname': '127.0.0.1', 'host': '127.0.0.1', 'port': 2383, 'family': 0, 'proto': 0, 'flags': 0}], 'last_exc': ClientConnectorError(ConnectionKey(host='127.0.0.1', port=2383, is_ssl=False, ssl=None, proxy=None, proxy_auth=None, proxy_headers_hash=None), ConnectionRefusedError(22...
  File "C:\Program Files\Python38\lib\site-packages\aiohttp\connector.py", line 1020, in _create_direct_connection
    locals={'self': <aiohttp.connector.TCPConnector object at 0x000002802EBBC7C0>, 'req': <aiohttp.client_reqrep.ClientRequest object at 0x000002802ECB1430>, 'traces': [], 'timeout': ClientTimeout(total=300, connect=None, sock_read=None, sock_connect=None), 'client_error': <class 'aiohttp.client_exceptions.ClientConnectorError'>, 'sslcontext': None, 'fingerprint': None, 'host': '127.0.0.1', 'port': 2383, 'host_resolved': <Task finished name='Task-27' coro=<TCPConnector._resolve_host() done, defined at C:\Program Files\Python38\lib\site-packages\aiohttp\connector.py:806> result=[{'family': 0, 'flags': 0, 'host': '127.0.0.1', 'hostname': '127.0.0.1', ...}] created at C:\Program Files\Python38\lib\site-packages\aiohttp\connector.py:992>, 'hosts': [{'hostname': '127.0.0.1', 'host': '127.0.0.1', 'port': 2383, 'family': 0, 'proto': 0, 'flags': 0}], 'last_exc': ClientConnectorError(ConnectionKey(host='127.0.0.1', port=2383, is_ssl=False, ssl=None, proxy=None, proxy_auth=None, proxy_headers_hash=None), ConnectionRefusedError(22...
  File "C:\Program Files\Python38\lib\site-packages\aiohttp\connector.py", line 975, in _wrap_create_connection
    locals={'self': <aiohttp.connector.TCPConnector object at 0x000002802EBBC7C0>, 'req': <aiohttp.client_reqrep.ClientRequest object at 0x000002802ECB1430>, 'timeout': ClientTimeout(total=300, connect=None, sock_read=None, sock_connect=None), 'client_error': <class 'aiohttp.client_exceptions.ClientConnectorError'>, 'args': (functools.partial(<class 'aiohttp.client_proto.ResponseHandler'>, loop=<ProactorEventLoop running=True closed=False debug=True>), '127.0.0.1', 2383), 'kwargs': {'ssl': None, 'family': 0, 'proto': 0, 'flags': 0, 'server_hostname': None, 'local_addr': None}}
2021-04-15 00:23:58,652 - CRITICAL - ServiceFinder - [EtcdSupport.py:481]: on_traceback, type:<class 'aiohttp.client_exceptions.ClientConnectorError'>, value:Cannot connect to host 127.0.0.1:2383 ssl:default [The remote computer refused the network connection], traceback:<class 'aiohttp.client_exceptions.ClientConnectorError'>
Cannot connect to host 127.0.0.1:2383 ssl:default [The remote computer refused the network connection]
  File "C:\Users\b\Documents\github\realtime-server\pycharm2020.1.3\script\core\EtcdSupport.py", line 466, in _watch_process
    locals={'self': <core.EtcdSupport.ServiceFinder object at 0x000002802EA41A30>, }
  File "C:\Program Files\Python38\lib\asyncio\tasks.py", line 494, in wait_for
    locals={'fut': <Task finished name='Task-28' coro=<ServiceFinder._watch_process_impl() done, defined at C:\Users\b\Documents\github\realtime-server\pycharm2020.1.3\script\core\EtcdSupport.py:391> exception=ClientConnectorError(ConnectionKey(host='127.0.0.1', port=2383, is_ssl=False, ssl=None, proxy=None, proxy_auth=None, proxy_headers_hash=None), ConnectionRefusedError(22, 'The remote computer refused the network connection', None, 1225, None)) created at C:\Program Files\Python38\lib\asyncio\tasks.py:475>, 'timeout': 63, 'loop': <ProactorEventLoop running=True closed=False debug=True>, 'waiter': <Future finished result=None created at C:\Program Files\Python38\lib\asyncio\base_events.py:422>, 'timeout_handle': <TimerHandle cancelled when=437921.781 _release_waiter(<Future finis...events.py:422>) at C:\Program Files\Python38\lib\asyncio\tasks.py:429 created at C:\Program Files\Python38\lib\asyncio\tasks.py:472>, 'cb': functools.partial(<function _release_waiter at 0x000002802DC4FCA0>, <Future finished result=None cr...
  File "C:\Users\b\Documents\github\realtime-server\pycharm2020.1.3\script\core\EtcdSupport.py", line 395, in _watch_process_impl
    locals={'self': <core.EtcdSupport.ServiceFinder object at 0x000002802EA41A30>, }
  File "C:\Users\b\Documents\github\realtime-server\pycharm2020.1.3\script\core\util\UtilApi.py", line 138, in async_http_requests
    locals={'method': 'get', 'url': 'http://127.0.0.1:2383/v2/keys', 'session': <aiohttp.client.ClientSession object at 0x000002802EBBC700>, 'kwargs': {}, '_async_http_requests_impl': <function async_http_requests.<locals>._async_http_requests_impl at 0x000002802EC7E550>}
  File "C:\Users\b\Documents\github\realtime-server\pycharm2020.1.3\script\core\util\UtilApi.py", line 131, in _async_http_requests_impl
    locals={'_method': 'get', '_url': 'http://127.0.0.1:2383/v2/keys', '_session': <aiohttp.client.ClientSession object at 0x000002802EBBC700>, '_kwargs': {}}
  File "C:\Program Files\Python38\lib\site-packages\aiohttp\client.py", line 1117, in __aenter__
    locals={'self': <aiohttp.client._RequestContextManager object at 0x000002802ED20400>, }
  File "C:\Program Files\Python38\lib\site-packages\aiohttp\client.py", line 520, in _request
    locals={'self': <aiohttp.client.ClientSession object at 0x000002802EBBC700>, 'method': 'GET', 'str_or_url': 'http://127.0.0.1:2383/v2/keys', 'params': None, 'data': None, 'json': None, 'cookies': None, 'headers': <CIMultiDict()>, 'skip_auto_headers': None, 'auth': None, 'allow_redirects': True, 'max_redirects': 10, 'compress': None, 'chunked': None, 'expect100': False, 'raise_for_status': None, 'read_until_eof': True, 'proxy': None, 'proxy_auth': None, 'timeout': <object object at 0x000002802E014FC0>, 'verify_ssl': None, 'fingerprint': None, 'ssl_context': None, 'ssl': None, 'proxy_headers': <CIMultiDict()>, 'read_bufsize': 65536, 'redirects': 0, 'history': [], 'version': HttpVersion(major=1, minor=1), 'url': URL('http://127.0.0.1:2383/v2/keys'), 'skip_headers': set(), 'real_timeout': ClientTimeout(total=300, connect=None, sock_read=None, sock_connect=None), 'tm': <aiohttp.helpers.TimeoutHandle object at 0x000002802ECB1700>, 'handle': None, 'traces': [], 'timer': <aiohttp.helpers.TimerContext object at 0x000002802EC...
  File "C:\Program Files\Python38\lib\site-packages\aiohttp\connector.py", line 535, in connect
    locals={'self': <aiohttp.connector.TCPConnector object at 0x000002802EBBC7C0>, 'req': <aiohttp.client_reqrep.ClientRequest object at 0x000002802ECB1820>, 'traces': [], 'timeout': ClientTimeout(total=300, connect=None, sock_read=None, sock_connect=None), 'key': ConnectionKey(host='127.0.0.1', port=2383, is_ssl=False, ssl=None, proxy=None, proxy_auth=None, proxy_headers_hash=None), 'available': 100, 'proto': None, 'placeholder': <aiohttp.connector._TransportPlaceholder object at 0x000002802ECB15E0>}
  File "C:\Program Files\Python38\lib\site-packages\aiohttp\connector.py", line 892, in _create_connection
    locals={'self': <aiohttp.connector.TCPConnector object at 0x000002802EBBC7C0>, 'req': <aiohttp.client_reqrep.ClientRequest object at 0x000002802ECB1820>, 'traces': [], 'timeout': ClientTimeout(total=300, connect=None, sock_read=None, sock_connect=None)}
  File "C:\Program Files\Python38\lib\site-packages\aiohttp\connector.py", line 1051, in _create_direct_connection
    locals={'self': <aiohttp.connector.TCPConnector object at 0x000002802EBBC7C0>, 'req': <aiohttp.client_reqrep.ClientRequest object at 0x000002802ECB1820>, 'traces': [], 'timeout': ClientTimeout(total=300, connect=None, sock_read=None, sock_connect=None), 'client_error': <class 'aiohttp.client_exceptions.ClientConnectorError'>, 'sslcontext': None, 'fingerprint': None, 'host': '127.0.0.1', 'port': 2383, 'host_resolved': <Task finished name='Task-29' coro=<TCPConnector._resolve_host() done, defined at C:\Program Files\Python38\lib\site-packages\aiohttp\connector.py:806> result=[{'family': 0, 'flags': 0, 'host': '127.0.0.1', 'hostname': '127.0.0.1', ...}] created at C:\Program Files\Python38\lib\site-packages\aiohttp\connector.py:992>, 'hosts': [{'hostname': '127.0.0.1', 'host': '127.0.0.1', 'port': 2383, 'family': 0, 'proto': 0, 'flags': 0}], 'last_exc': ClientConnectorError(ConnectionKey(host='127.0.0.1', port=2383, is_ssl=False, ssl=None, proxy=None, proxy_auth=None, proxy_headers_hash=None), ConnectionRefusedError(22...
  File "C:\Program Files\Python38\lib\site-packages\aiohttp\connector.py", line 1020, in _create_direct_connection
    locals={'self': <aiohttp.connector.TCPConnector object at 0x000002802EBBC7C0>, 'req': <aiohttp.client_reqrep.ClientRequest object at 0x000002802ECB1820>, 'traces': [], 'timeout': ClientTimeout(total=300, connect=None, sock_read=None, sock_connect=None), 'client_error': <class 'aiohttp.client_exceptions.ClientConnectorError'>, 'sslcontext': None, 'fingerprint': None, 'host': '127.0.0.1', 'port': 2383, 'host_resolved': <Task finished name='Task-29' coro=<TCPConnector._resolve_host() done, defined at C:\Program Files\Python38\lib\site-packages\aiohttp\connector.py:806> result=[{'family': 0, 'flags': 0, 'host': '127.0.0.1', 'hostname': '127.0.0.1', ...}] created at C:\Program Files\Python38\lib\site-packages\aiohttp\connector.py:992>, 'hosts': [{'hostname': '127.0.0.1', 'host': '127.0.0.1', 'port': 2383, 'family': 0, 'proto': 0, 'flags': 0}], 'last_exc': ClientConnectorError(ConnectionKey(host='127.0.0.1', port=2383, is_ssl=False, ssl=None, proxy=None, proxy_auth=None, proxy_headers_hash=None), ConnectionRefusedError(22...
  File "C:\Program Files\Python38\lib\site-packages\aiohttp\connector.py", line 975, in _wrap_create_connection
    locals={'self': <aiohttp.connector.TCPConnector object at 0x000002802EBBC7C0>, 'req': <aiohttp.client_reqrep.ClientRequest object at 0x000002802ECB1820>, 'timeout': ClientTimeout(total=300, connect=None, sock_read=None, sock_connect=None), 'client_error': <class 'aiohttp.client_exceptions.ClientConnectorError'>, 'args': (functools.partial(<class 'aiohttp.client_proto.ResponseHandler'>, loop=<ProactorEventLoop running=True closed=False debug=True>), '127.0.0.1', 2383), 'kwargs': {'ssl': None, 'family': 0, 'proto': 0, 'flags': 0, 'server_hostname': None, 'local_addr': None}}
2021-04-15 00:24:00,660 - CRITICAL - ServiceFinder - [EtcdSupport.py:481]: on_traceback, type:<class 'aiohttp.client_exceptions.ClientConnectorError'>, value:Cannot connect to host 127.0.0.1:2383 ssl:default [The remote computer refused the network connection], traceback:<class 'aiohttp.client_exceptions.ClientConnectorError'>
Cannot connect to host 127.0.0.1:2383 ssl:default [The remote computer refused the network connection]
  File "C:\Users\b\Documents\github\realtime-server\pycharm2020.1.3\script\core\EtcdSupport.py", line 466, in _watch_process
    locals={'self': <core.EtcdSupport.ServiceFinder object at 0x000002802EA41A30>, }
  File "C:\Program Files\Python38\lib\asyncio\tasks.py", line 494, in wait_for
    locals={'fut': <Task finished name='Task-30' coro=<ServiceFinder._watch_process_impl() done, defined at C:\Users\b\Documents\github\realtime-server\pycharm2020.1.3\script\core\EtcdSupport.py:391> exception=ClientConnectorError(ConnectionKey(host='127.0.0.1', port=2383, is_ssl=False, ssl=None, proxy=None, proxy_auth=None, proxy_headers_hash=None), ConnectionRefusedError(22, 'The remote computer refused the network connection', None, 1225, None)) created at C:\Program Files\Python38\lib\asyncio\tasks.py:475>, 'timeout': 70, 'loop': <ProactorEventLoop running=True closed=False debug=True>, 'waiter': <Future finished result=None created at C:\Program Files\Python38\lib\asyncio\base_events.py:422>, 'timeout_handle': <TimerHandle cancelled when=437930.796 _release_waiter(<Future finis...events.py:422>) at C:\Program Files\Python38\lib\asyncio\tasks.py:429 created at C:\Program Files\Python38\lib\asyncio\tasks.py:472>, 'cb': functools.partial(<function _release_waiter at 0x000002802DC4FCA0>, <Future finished result=None cr...
  File "C:\Users\b\Documents\github\realtime-server\pycharm2020.1.3\script\core\EtcdSupport.py", line 395, in _watch_process_impl
    locals={'self': <core.EtcdSupport.ServiceFinder object at 0x000002802EA41A30>, }
  File "C:\Users\b\Documents\github\realtime-server\pycharm2020.1.3\script\core\util\UtilApi.py", line 138, in async_http_requests
    locals={'method': 'get', 'url': 'http://127.0.0.1:2383/v2/keys', 'session': <aiohttp.client.ClientSession object at 0x000002802EBBC700>, 'kwargs': {}, '_async_http_requests_impl': <function async_http_requests.<locals>._async_http_requests_impl at 0x000002802ED19040>}
  File "C:\Users\b\Documents\github\realtime-server\pycharm2020.1.3\script\core\util\UtilApi.py", line 131, in _async_http_requests_impl
    locals={'_method': 'get', '_url': 'http://127.0.0.1:2383/v2/keys', '_session': <aiohttp.client.ClientSession object at 0x000002802EBBC700>, '_kwargs': {}}
  File "C:\Program Files\Python38\lib\site-packages\aiohttp\client.py", line 1117, in __aenter__
    locals={'self': <aiohttp.client._RequestContextManager object at 0x000002802ED2BB00>, }
  File "C:\Program Files\Python38\lib\site-packages\aiohttp\client.py", line 520, in _request
    locals={'self': <aiohttp.client.ClientSession object at 0x000002802EBBC700>, 'method': 'GET', 'str_or_url': 'http://127.0.0.1:2383/v2/keys', 'params': None, 'data': None, 'json': None, 'cookies': None, 'headers': <CIMultiDict()>, 'skip_auto_headers': None, 'auth': None, 'allow_redirects': True, 'max_redirects': 10, 'compress': None, 'chunked': None, 'expect100': False, 'raise_for_status': None, 'read_until_eof': True, 'proxy': None, 'proxy_auth': None, 'timeout': <object object at 0x000002802E014FC0>, 'verify_ssl': None, 'fingerprint': None, 'ssl_context': None, 'ssl': None, 'proxy_headers': <CIMultiDict()>, 'read_bufsize': 65536, 'redirects': 0, 'history': [], 'version': HttpVersion(major=1, minor=1), 'url': URL('http://127.0.0.1:2383/v2/keys'), 'skip_headers': set(), 'real_timeout': ClientTimeout(total=300, connect=None, sock_read=None, sock_connect=None), 'tm': <aiohttp.helpers.TimeoutHandle object at 0x000002802ECB18B0>, 'handle': None, 'traces': [], 'timer': <aiohttp.helpers.TimerContext object at 0x000002802EC...
  File "C:\Program Files\Python38\lib\site-packages\aiohttp\connector.py", line 535, in connect
    locals={'self': <aiohttp.connector.TCPConnector object at 0x000002802EBBC7C0>, 'req': <aiohttp.client_reqrep.ClientRequest object at 0x000002802ECB1880>, 'traces': [], 'timeout': ClientTimeout(total=300, connect=None, sock_read=None, sock_connect=None), 'key': ConnectionKey(host='127.0.0.1', port=2383, is_ssl=False, ssl=None, proxy=None, proxy_auth=None, proxy_headers_hash=None), 'available': 100, 'proto': None, 'placeholder': <aiohttp.connector._TransportPlaceholder object at 0x000002802ECB1940>}
  File "C:\Program Files\Python38\lib\site-packages\aiohttp\connector.py", line 892, in _create_connection
    locals={'self': <aiohttp.connector.TCPConnector object at 0x000002802EBBC7C0>, 'req': <aiohttp.client_reqrep.ClientRequest object at 0x000002802ECB1880>, 'traces': [], 'timeout': ClientTimeout(total=300, connect=None, sock_read=None, sock_connect=None)}
  File "C:\Program Files\Python38\lib\site-packages\aiohttp\connector.py", line 1051, in _create_direct_connection
    locals={'self': <aiohttp.connector.TCPConnector object at 0x000002802EBBC7C0>, 'req': <aiohttp.client_reqrep.ClientRequest object at 0x000002802ECB1880>, 'traces': [], 'timeout': ClientTimeout(total=300, connect=None, sock_read=None, sock_connect=None), 'client_error': <class 'aiohttp.client_exceptions.ClientConnectorError'>, 'sslcontext': None, 'fingerprint': None, 'host': '127.0.0.1', 'port': 2383, 'host_resolved': <Task finished name='Task-31' coro=<TCPConnector._resolve_host() done, defined at C:\Program Files\Python38\lib\site-packages\aiohttp\connector.py:806> result=[{'family': 0, 'flags': 0, 'host': '127.0.0.1', 'hostname': '127.0.0.1', ...}] created at C:\Program Files\Python38\lib\site-packages\aiohttp\connector.py:992>, 'hosts': [{'hostname': '127.0.0.1', 'host': '127.0.0.1', 'port': 2383, 'family': 0, 'proto': 0, 'flags': 0}], 'last_exc': ClientConnectorError(ConnectionKey(host='127.0.0.1', port=2383, is_ssl=False, ssl=None, proxy=None, proxy_auth=None, proxy_headers_hash=None), ConnectionRefusedError(22...
  File "C:\Program Files\Python38\lib\site-packages\aiohttp\connector.py", line 1020, in _create_direct_connection
    locals={'self': <aiohttp.connector.TCPConnector object at 0x000002802EBBC7C0>, 'req': <aiohttp.client_reqrep.ClientRequest object at 0x000002802ECB1880>, 'traces': [], 'timeout': ClientTimeout(total=300, connect=None, sock_read=None, sock_connect=None), 'client_error': <class 'aiohttp.client_exceptions.ClientConnectorError'>, 'sslcontext': None, 'fingerprint': None, 'host': '127.0.0.1', 'port': 2383, 'host_resolved': <Task finished name='Task-31' coro=<TCPConnector._resolve_host() done, defined at C:\Program Files\Python38\lib\site-packages\aiohttp\connector.py:806> result=[{'family': 0, 'flags': 0, 'host': '127.0.0.1', 'hostname': '127.0.0.1', ...}] created at C:\Program Files\Python38\lib\site-packages\aiohttp\connector.py:992>, 'hosts': [{'hostname': '127.0.0.1', 'host': '127.0.0.1', 'port': 2383, 'family': 0, 'proto': 0, 'flags': 0}], 'last_exc': ClientConnectorError(ConnectionKey(host='127.0.0.1', port=2383, is_ssl=False, ssl=None, proxy=None, proxy_auth=None, proxy_headers_hash=None), ConnectionRefusedError(22...
  File "C:\Program Files\Python38\lib\site-packages\aiohttp\connector.py", line 975, in _wrap_create_connection
    locals={'self': <aiohttp.connector.TCPConnector object at 0x000002802EBBC7C0>, 'req': <aiohttp.client_reqrep.ClientRequest object at 0x000002802ECB1880>, 'timeout': ClientTimeout(total=300, connect=None, sock_read=None, sock_connect=None), 'client_error': <class 'aiohttp.client_exceptions.ClientConnectorError'>, 'args': (functools.partial(<class 'aiohttp.client_proto.ResponseHandler'>, loop=<ProactorEventLoop running=True closed=False debug=True>), '127.0.0.1', 2383), 'kwargs': {'ssl': None, 'family': 0, 'proto': 0, 'flags': 0, 'server_hostname': None, 'local_addr': None}}
2021-04-15 00:24:02,668 - CRITICAL - ServiceFinder - [EtcdSupport.py:481]: on_traceback, type:<class 'aiohttp.client_exceptions.ClientConnectorError'>, value:Cannot connect to host 127.0.0.1:2381 ssl:default [The remote computer refused the network connection], traceback:<class 'aiohttp.client_exceptions.ClientConnectorError'>
Cannot connect to host 127.0.0.1:2381 ssl:default [The remote computer refused the network connection]
  File "C:\Users\b\Documents\github\realtime-server\pycharm2020.1.3\script\core\EtcdSupport.py", line 466, in _watch_process
    locals={'self': <core.EtcdSupport.ServiceFinder object at 0x000002802EA41A30>, }
  File "C:\Program Files\Python38\lib\asyncio\tasks.py", line 494, in wait_for
    locals={'fut': <Task finished name='Task-32' coro=<ServiceFinder._watch_process_impl() done, defined at C:\Users\b\Documents\github\realtime-server\pycharm2020.1.3\script\core\EtcdSupport.py:391> exception=ClientConnectorError(ConnectionKey(host='127.0.0.1', port=2381, is_ssl=False, ssl=None, proxy=None, proxy_auth=None, proxy_headers_hash=None), ConnectionRefusedError(22, 'The remote computer refused the network connection', None, 1225, None)) created at C:\Program Files\Python38\lib\asyncio\tasks.py:475>, 'timeout': 62, 'loop': <ProactorEventLoop running=True closed=False debug=True>, 'waiter': <Future finished result=None created at C:\Program Files\Python38\lib\asyncio\base_events.py:422>, 'timeout_handle': <TimerHandle cancelled when=437924.796 _release_waiter(<Future finis...events.py:422>) at C:\Program Files\Python38\lib\asyncio\tasks.py:429 created at C:\Program Files\Python38\lib\asyncio\tasks.py:472>, 'cb': functools.partial(<function _release_waiter at 0x000002802DC4FCA0>, <Future finished result=None cr...
  File "C:\Users\b\Documents\github\realtime-server\pycharm2020.1.3\script\core\EtcdSupport.py", line 395, in _watch_process_impl
    locals={'self': <core.EtcdSupport.ServiceFinder object at 0x000002802EA41A30>, }
  File "C:\Users\b\Documents\github\realtime-server\pycharm2020.1.3\script\core\util\UtilApi.py", line 138, in async_http_requests
    locals={'method': 'get', 'url': 'http://127.0.0.1:2381/v2/keys', 'session': <aiohttp.client.ClientSession object at 0x000002802EBBC700>, 'kwargs': {}, '_async_http_requests_impl': <function async_http_requests.<locals>._async_http_requests_impl at 0x000002802ED193A0>}
  File "C:\Users\b\Documents\github\realtime-server\pycharm2020.1.3\script\core\util\UtilApi.py", line 131, in _async_http_requests_impl
    locals={'_method': 'get', '_url': 'http://127.0.0.1:2381/v2/keys', '_session': <aiohttp.client.ClientSession object at 0x000002802EBBC700>, '_kwargs': {}}
  File "C:\Program Files\Python38\lib\site-packages\aiohttp\client.py", line 1117, in __aenter__
    locals={'self': <aiohttp.client._RequestContextManager object at 0x000002802ED2FBC0>, }
  File "C:\Program Files\Python38\lib\site-packages\aiohttp\client.py", line 520, in _request
    locals={'self': <aiohttp.client.ClientSession object at 0x000002802EBBC700>, 'method': 'GET', 'str_or_url': 'http://127.0.0.1:2381/v2/keys', 'params': None, 'data': None, 'json': None, 'cookies': None, 'headers': <CIMultiDict()>, 'skip_auto_headers': None, 'auth': None, 'allow_redirects': True, 'max_redirects': 10, 'compress': None, 'chunked': None, 'expect100': False, 'raise_for_status': None, 'read_until_eof': True, 'proxy': None, 'proxy_auth': None, 'timeout': <object object at 0x000002802E014FC0>, 'verify_ssl': None, 'fingerprint': None, 'ssl_context': None, 'ssl': None, 'proxy_headers': <CIMultiDict()>, 'read_bufsize': 65536, 'redirects': 0, 'history': [], 'version': HttpVersion(major=1, minor=1), 'url': URL('http://127.0.0.1:2381/v2/keys'), 'skip_headers': set(), 'real_timeout': ClientTimeout(total=300, connect=None, sock_read=None, sock_connect=None), 'tm': <aiohttp.helpers.TimeoutHandle object at 0x000002802ECB1A30>, 'handle': None, 'traces': [], 'timer': <aiohttp.helpers.TimerContext object at 0x000002802EC...
  File "C:\Program Files\Python38\lib\site-packages\aiohttp\connector.py", line 535, in connect
    locals={'self': <aiohttp.connector.TCPConnector object at 0x000002802EBBC7C0>, 'req': <aiohttp.client_reqrep.ClientRequest object at 0x000002802ECB1C70>, 'traces': [], 'timeout': ClientTimeout(total=300, connect=None, sock_read=None, sock_connect=None), 'key': ConnectionKey(host='127.0.0.1', port=2381, is_ssl=False, ssl=None, proxy=None, proxy_auth=None, proxy_headers_hash=None), 'available': 100, 'proto': None, 'placeholder': <aiohttp.connector._TransportPlaceholder object at 0x000002802ECB1D30>}
  File "C:\Program Files\Python38\lib\site-packages\aiohttp\connector.py", line 892, in _create_connection
    locals={'self': <aiohttp.connector.TCPConnector object at 0x000002802EBBC7C0>, 'req': <aiohttp.client_reqrep.ClientRequest object at 0x000002802ECB1C70>, 'traces': [], 'timeout': ClientTimeout(total=300, connect=None, sock_read=None, sock_connect=None)}
  File "C:\Program Files\Python38\lib\site-packages\aiohttp\connector.py", line 1051, in _create_direct_connection
    locals={'self': <aiohttp.connector.TCPConnector object at 0x000002802EBBC7C0>, 'req': <aiohttp.client_reqrep.ClientRequest object at 0x000002802ECB1C70>, 'traces': [], 'timeout': ClientTimeout(total=300, connect=None, sock_read=None, sock_connect=None), 'client_error': <class 'aiohttp.client_exceptions.ClientConnectorError'>, 'sslcontext': None, 'fingerprint': None, 'host': '127.0.0.1', 'port': 2381, 'host_resolved': <Task finished name='Task-33' coro=<TCPConnector._resolve_host() done, defined at C:\Program Files\Python38\lib\site-packages\aiohttp\connector.py:806> result=[{'family': 0, 'flags': 0, 'host': '127.0.0.1', 'hostname': '127.0.0.1', ...}] created at C:\Program Files\Python38\lib\site-packages\aiohttp\connector.py:992>, 'hosts': [{'hostname': '127.0.0.1', 'host': '127.0.0.1', 'port': 2381, 'family': 0, 'proto': 0, 'flags': 0}], 'last_exc': ClientConnectorError(ConnectionKey(host='127.0.0.1', port=2381, is_ssl=False, ssl=None, proxy=None, proxy_auth=None, proxy_headers_hash=None), ConnectionRefusedError(22...
  File "C:\Program Files\Python38\lib\site-packages\aiohttp\connector.py", line 1020, in _create_direct_connection
    locals={'self': <aiohttp.connector.TCPConnector object at 0x000002802EBBC7C0>, 'req': <aiohttp.client_reqrep.ClientRequest object at 0x000002802ECB1C70>, 'traces': [], 'timeout': ClientTimeout(total=300, connect=None, sock_read=None, sock_connect=None), 'client_error': <class 'aiohttp.client_exceptions.ClientConnectorError'>, 'sslcontext': None, 'fingerprint': None, 'host': '127.0.0.1', 'port': 2381, 'host_resolved': <Task finished name='Task-33' coro=<TCPConnector._resolve_host() done, defined at C:\Program Files\Python38\lib\site-packages\aiohttp\connector.py:806> result=[{'family': 0, 'flags': 0, 'host': '127.0.0.1', 'hostname': '127.0.0.1', ...}] created at C:\Program Files\Python38\lib\site-packages\aiohttp\connector.py:992>, 'hosts': [{'hostname': '127.0.0.1', 'host': '127.0.0.1', 'port': 2381, 'family': 0, 'proto': 0, 'flags': 0}], 'last_exc': ClientConnectorError(ConnectionKey(host='127.0.0.1', port=2381, is_ssl=False, ssl=None, proxy=None, proxy_auth=None, proxy_headers_hash=None), ConnectionRefusedError(22...
  File "C:\Program Files\Python38\lib\site-packages\aiohttp\connector.py", line 975, in _wrap_create_connection
    locals={'self': <aiohttp.connector.TCPConnector object at 0x000002802EBBC7C0>, 'req': <aiohttp.client_reqrep.ClientRequest object at 0x000002802ECB1C70>, 'timeout': ClientTimeout(total=300, connect=None, sock_read=None, sock_connect=None), 'client_error': <class 'aiohttp.client_exceptions.ClientConnectorError'>, 'args': (functools.partial(<class 'aiohttp.client_proto.ResponseHandler'>, loop=<ProactorEventLoop running=True closed=False debug=True>), '127.0.0.1', 2381), 'kwargs': {'ssl': None, 'family': 0, 'proto': 0, 'flags': 0, 'server_hostname': None, 'local_addr': None}}
2021-04-15 00:24:04,677 - CRITICAL - ServiceFinder - [EtcdSupport.py:481]: on_traceback, type:<class 'aiohttp.client_exceptions.ClientConnectorError'>, value:Cannot connect to host 127.0.0.1:2383 ssl:default [The remote computer refused the network connection], traceback:<class 'aiohttp.client_exceptions.ClientConnectorError'>
Cannot connect to host 127.0.0.1:2383 ssl:default [The remote computer refused the network connection]
  File "C:\Users\b\Documents\github\realtime-server\pycharm2020.1.3\script\core\EtcdSupport.py", line 466, in _watch_process
    locals={'self': <core.EtcdSupport.ServiceFinder object at 0x000002802EA41A30>, }
  File "C:\Program Files\Python38\lib\asyncio\tasks.py", line 494, in wait_for
    locals={'fut': <Task finished name='Task-34' coro=<ServiceFinder._watch_process_impl() done, defined at C:\Users\b\Documents\github\realtime-server\pycharm2020.1.3\script\core\EtcdSupport.py:391> exception=ClientConnectorError(ConnectionKey(host='127.0.0.1', port=2383, is_ssl=False, ssl=None, proxy=None, proxy_auth=None, proxy_headers_hash=None), ConnectionRefusedError(22, 'The remote computer refused the network connection', None, 1225, None)) created at C:\Program Files\Python38\lib\asyncio\tasks.py:475>, 'timeout': 68, 'loop': <ProactorEventLoop running=True closed=False debug=True>, 'waiter': <Future finished result=None created at C:\Program Files\Python38\lib\asyncio\base_events.py:422>, 'timeout_handle': <TimerHandle cancelled when=437932.812 _release_waiter(<Future finis...events.py:422>) at C:\Program Files\Python38\lib\asyncio\tasks.py:429 created at C:\Program Files\Python38\lib\asyncio\tasks.py:472>, 'cb': functools.partial(<function _release_waiter at 0x000002802DC4FCA0>, <Future finished result=None cr...
  File "C:\Users\b\Documents\github\realtime-server\pycharm2020.1.3\script\core\EtcdSupport.py", line 395, in _watch_process_impl
    locals={'self': <core.EtcdSupport.ServiceFinder object at 0x000002802EA41A30>, }
  File "C:\Users\b\Documents\github\realtime-server\pycharm2020.1.3\script\core\util\UtilApi.py", line 138, in async_http_requests
    locals={'method': 'get', 'url': 'http://127.0.0.1:2383/v2/keys', 'session': <aiohttp.client.ClientSession object at 0x000002802EBBC700>, 'kwargs': {}, '_async_http_requests_impl': <function async_http_requests.<locals>._async_http_requests_impl at 0x000002802EC7E700>}
  File "C:\Users\b\Documents\github\realtime-server\pycharm2020.1.3\script\core\util\UtilApi.py", line 131, in _async_http_requests_impl
    locals={'_method': 'get', '_url': 'http://127.0.0.1:2383/v2/keys', '_session': <aiohttp.client.ClientSession object at 0x000002802EBBC700>, '_kwargs': {}}
  File "C:\Program Files\Python38\lib\site-packages\aiohttp\client.py", line 1117, in __aenter__
    locals={'self': <aiohttp.client._RequestContextManager object at 0x000002802ED12E80>, }
  File "C:\Program Files\Python38\lib\site-packages\aiohttp\client.py", line 520, in _request
    locals={'self': <aiohttp.client.ClientSession object at 0x000002802EBBC700>, 'method': 'GET', 'str_or_url': 'http://127.0.0.1:2383/v2/keys', 'params': None, 'data': None, 'json': None, 'cookies': None, 'headers': <CIMultiDict()>, 'skip_auto_headers': None, 'auth': None, 'allow_redirects': True, 'max_redirects': 10, 'compress': None, 'chunked': None, 'expect100': False, 'raise_for_status': None, 'read_until_eof': True, 'proxy': None, 'proxy_auth': None, 'timeout': <object object at 0x000002802E014FC0>, 'verify_ssl': None, 'fingerprint': None, 'ssl_context': None, 'ssl': None, 'proxy_headers': <CIMultiDict()>, 'read_bufsize': 65536, 'redirects': 0, 'history': [], 'version': HttpVersion(major=1, minor=1), 'url': URL('http://127.0.0.1:2383/v2/keys'), 'skip_headers': set(), 'real_timeout': ClientTimeout(total=300, connect=None, sock_read=None, sock_connect=None), 'tm': <aiohttp.helpers.TimeoutHandle object at 0x000002802ECB1370>, 'handle': None, 'traces': [], 'timer': <aiohttp.helpers.TimerContext object at 0x000002802EC...
  File "C:\Program Files\Python38\lib\site-packages\aiohttp\connector.py", line 535, in connect
    locals={'self': <aiohttp.connector.TCPConnector object at 0x000002802EBBC7C0>, 'req': <aiohttp.client_reqrep.ClientRequest object at 0x000002802ECB1550>, 'traces': [], 'timeout': ClientTimeout(total=300, connect=None, sock_read=None, sock_connect=None), 'key': ConnectionKey(host='127.0.0.1', port=2383, is_ssl=False, ssl=None, proxy=None, proxy_auth=None, proxy_headers_hash=None), 'available': 100, 'proto': None, 'placeholder': <aiohttp.connector._TransportPlaceholder object at 0x000002802ECB1CD0>}
  File "C:\Program Files\Python38\lib\site-packages\aiohttp\connector.py", line 892, in _create_connection
    locals={'self': <aiohttp.connector.TCPConnector object at 0x000002802EBBC7C0>, 'req': <aiohttp.client_reqrep.ClientRequest object at 0x000002802ECB1550>, 'traces': [], 'timeout': ClientTimeout(total=300, connect=None, sock_read=None, sock_connect=None)}
  File "C:\Program Files\Python38\lib\site-packages\aiohttp\connector.py", line 1051, in _create_direct_connection
    locals={'self': <aiohttp.connector.TCPConnector object at 0x000002802EBBC7C0>, 'req': <aiohttp.client_reqrep.ClientRequest object at 0x000002802ECB1550>, 'traces': [], 'timeout': ClientTimeout(total=300, connect=None, sock_read=None, sock_connect=None), 'client_error': <class 'aiohttp.client_exceptions.ClientConnectorError'>, 'sslcontext': None, 'fingerprint': None, 'host': '127.0.0.1', 'port': 2383, 'host_resolved': <Task finished name='Task-35' coro=<TCPConnector._resolve_host() done, defined at C:\Program Files\Python38\lib\site-packages\aiohttp\connector.py:806> result=[{'family': 0, 'flags': 0, 'host': '127.0.0.1', 'hostname': '127.0.0.1', ...}] created at C:\Program Files\Python38\lib\site-packages\aiohttp\connector.py:992>, 'hosts': [{'hostname': '127.0.0.1', 'host': '127.0.0.1', 'port': 2383, 'family': 0, 'proto': 0, 'flags': 0}], 'last_exc': ClientConnectorError(ConnectionKey(host='127.0.0.1', port=2383, is_ssl=False, ssl=None, proxy=None, proxy_auth=None, proxy_headers_hash=None), ConnectionRefusedError(22...
  File "C:\Program Files\Python38\lib\site-packages\aiohttp\connector.py", line 1020, in _create_direct_connection
    locals={'self': <aiohttp.connector.TCPConnector object at 0x000002802EBBC7C0>, 'req': <aiohttp.client_reqrep.ClientRequest object at 0x000002802ECB1550>, 'traces': [], 'timeout': ClientTimeout(total=300, connect=None, sock_read=None, sock_connect=None), 'client_error': <class 'aiohttp.client_exceptions.ClientConnectorError'>, 'sslcontext': None, 'fingerprint': None, 'host': '127.0.0.1', 'port': 2383, 'host_resolved': <Task finished name='Task-35' coro=<TCPConnector._resolve_host() done, defined at C:\Program Files\Python38\lib\site-packages\aiohttp\connector.py:806> result=[{'family': 0, 'flags': 0, 'host': '127.0.0.1', 'hostname': '127.0.0.1', ...}] created at C:\Program Files\Python38\lib\site-packages\aiohttp\connector.py:992>, 'hosts': [{'hostname': '127.0.0.1', 'host': '127.0.0.1', 'port': 2383, 'family': 0, 'proto': 0, 'flags': 0}], 'last_exc': ClientConnectorError(ConnectionKey(host='127.0.0.1', port=2383, is_ssl=False, ssl=None, proxy=None, proxy_auth=None, proxy_headers_hash=None), ConnectionRefusedError(22...
  File "C:\Program Files\Python38\lib\site-packages\aiohttp\connector.py", line 975, in _wrap_create_connection
    locals={'self': <aiohttp.connector.TCPConnector object at 0x000002802EBBC7C0>, 'req': <aiohttp.client_reqrep.ClientRequest object at 0x000002802ECB1550>, 'timeout': ClientTimeout(total=300, connect=None, sock_read=None, sock_connect=None), 'client_error': <class 'aiohttp.client_exceptions.ClientConnectorError'>, 'args': (functools.partial(<class 'aiohttp.client_proto.ResponseHandler'>, loop=<ProactorEventLoop running=True closed=False debug=True>), '127.0.0.1', 2383), 'kwargs': {'ssl': None, 'family': 0, 'proto': 0, 'flags': 0, 'server_hostname': None, 'local_addr': None}}
2021-04-15 00:28:14,708 - DEBUG - ServiceNode - [EtcdSupport.py:533]: we have create ServiceFinder
2021-04-15 00:28:14,737 - DEBUG - ServiceFinder - [EtcdSupport.py:352]: _init_info, now_url: http://127.0.0.1:2381/v2/keys?recursive=true
2021-04-15 00:28:14,741 - DEBUG - ServiceRegister - [EtcdSupport.py:155]: _do_regist: now_url: http://127.0.0.1:2381/v2/keys/services/dispatcher_service/127.0.0.1|9100
2021-04-15 00:28:14,748 - DEBUG - TcpServer - [TcpServer.py:189]: Server on ('127.0.0.1', 9100)
2021-04-15 00:28:16,747 - ERROR - ServiceRegister - [EtcdSupport.py:172]: regist service : dispatcher_service error
2021-04-15 00:28:16,749 - CRITICAL - ServiceRegister - [EtcdSupport.py:173]: on_traceback, type:<class 'asyncio.exceptions.TimeoutError'>, value:, traceback:<class 'asyncio.exceptions.TimeoutError'>

  File "C:\Users\b\Documents\github\realtime-server\pycharm2020.1.3\script\core\EtcdSupport.py", line 158, in _do_regist
    locals={'self': <core.EtcdSupport.ServiceRegister object at 0x0000022596061550>, 'service_name': 'dispatcher_service', 'data': 'ttl=180', 'now_url': 'http://127.0.0.1:2381/v2/keys/services/dispatcher_service/127.0.0.1|9100'}
  File "C:\Users\b\Documents\github\realtime-server\pycharm2020.1.3\script\core\util\UtilApi.py", line 138, in async_http_requests
    locals={'method': 'put', 'url': 'http://127.0.0.1:2381/v2/keys/services/dispatcher_service/127.0.0.1|9100', 'session': <aiohttp.client.ClientSession object at 0x000002259606C700>, 'kwargs': {'data': 'ttl=180', 'headers': {'Content-Type': 'application/x-www-form-urlencoded'}, 'timeout': 2}, '_async_http_requests_impl': <function async_http_requests.<locals>._async_http_requests_impl at 0x000002259612E940>}
  File "C:\Users\b\Documents\github\realtime-server\pycharm2020.1.3\script\core\util\UtilApi.py", line 131, in _async_http_requests_impl
    locals={'_method': 'put', '_url': 'http://127.0.0.1:2381/v2/keys/services/dispatcher_service/127.0.0.1|9100', '_session': <aiohttp.client.ClientSession object at 0x000002259606C700>, '_kwargs': {'data': 'ttl=180', 'headers': {'Content-Type': 'application/x-www-form-urlencoded'}, 'timeout': 2}}
  File "C:\Program Files\Python38\lib\site-packages\aiohttp\client.py", line 1117, in __aenter__
    locals={'self': <aiohttp.client._RequestContextManager object at 0x0000022596162200>, }
  File "C:\Program Files\Python38\lib\site-packages\aiohttp\client.py", line 619, in _request
    locals={'self': <aiohttp.client.ClientSession object at 0x000002259606C700>, 'method': 'PUT', 'str_or_url': 'http://127.0.0.1:2381/v2/keys/services/dispatcher_service/127.0.0.1|9100', 'params': None, 'data': 'ttl=180', 'json': None, 'cookies': None, 'headers': <CIMultiDict('Content-Type': 'application/x-www-form-urlencoded')>, 'skip_auto_headers': None, 'auth': None, 'allow_redirects': True, 'max_redirects': 10, 'compress': None, 'chunked': None, 'expect100': False, 'raise_for_status': None, 'read_until_eof': True, 'proxy': None, 'proxy_auth': None, 'timeout': 2, 'verify_ssl': None, 'fingerprint': None, 'ssl_context': None, 'ssl': None, 'proxy_headers': <CIMultiDict()>, 'read_bufsize': 65536, 'redirects': 0, 'history': [], 'version': HttpVersion(major=1, minor=1), 'url': URL('http://127.0.0.1:2381/v2/keys/services/dispatcher_service/127.0.0.1%7C9100'), 'skip_headers': set(), 'real_timeout': ClientTimeout(total=2, connect=None, sock_read=None, sock_connect=None), 'tm': <aiohttp.helpers.TimeoutHandle object at 0x00000...
  File "C:\Program Files\Python38\lib\site-packages\aiohttp\helpers.py", line 656, in __exit__
    locals={'self': <aiohttp.helpers.TimerContext object at 0x000002259606CF40>, 'exc_type': <class 'asyncio.exceptions.CancelledError'>, 'exc_val': CancelledError(), 'exc_tb': <traceback object at 0x0000022596172240>}
2021-04-15 00:28:16,750 - DEBUG - ServiceRegister - [EtcdSupport.py:155]: _do_regist: now_url: http://127.0.0.1:2381/v2/keys/services/dispatcher_service/127.0.0.1|9100
2021-04-15 00:28:16,754 - CRITICAL - ServiceFinder - [EtcdSupport.py:370]: on_traceback, type:<class 'aiohttp.client_exceptions.ClientConnectorError'>, value:Cannot connect to host 127.0.0.1:2381 ssl:default [The remote computer refused the network connection], traceback:<class 'aiohttp.client_exceptions.ClientConnectorError'>
Cannot connect to host 127.0.0.1:2381 ssl:default [The remote computer refused the network connection]
  File "C:\Users\b\Documents\github\realtime-server\pycharm2020.1.3\script\core\EtcdSupport.py", line 354, in _init_info
    locals={'self': <core.EtcdSupport.ServiceFinder object at 0x0000022595EF1A30>, 'now_url': 'http://127.0.0.1:2381/v2/keys?recursive=true'}
  File "C:\Users\b\Documents\github\realtime-server\pycharm2020.1.3\script\core\util\UtilApi.py", line 138, in async_http_requests
    locals={'method': 'get', 'url': 'http://127.0.0.1:2381/v2/keys?recursive=true', 'session': <aiohttp.client.ClientSession object at 0x000002259606C700>, 'kwargs': {}, '_async_http_requests_impl': <function async_http_requests.<locals>._async_http_requests_impl at 0x000002259612E550>}
  File "C:\Users\b\Documents\github\realtime-server\pycharm2020.1.3\script\core\util\UtilApi.py", line 131, in _async_http_requests_impl
    locals={'_method': 'get', '_url': 'http://127.0.0.1:2381/v2/keys?recursive=true', '_session': <aiohttp.client.ClientSession object at 0x000002259606C700>, '_kwargs': {}}
  File "C:\Program Files\Python38\lib\site-packages\aiohttp\client.py", line 1117, in __aenter__
    locals={'self': <aiohttp.client._RequestContextManager object at 0x000002259614AB40>, }
  File "C:\Program Files\Python38\lib\site-packages\aiohttp\client.py", line 520, in _request
    locals={'self': <aiohttp.client.ClientSession object at 0x000002259606C700>, 'method': 'GET', 'str_or_url': 'http://127.0.0.1:2381/v2/keys?recursive=true', 'params': None, 'data': None, 'json': None, 'cookies': None, 'headers': <CIMultiDict()>, 'skip_auto_headers': None, 'auth': None, 'allow_redirects': True, 'max_redirects': 10, 'compress': None, 'chunked': None, 'expect100': False, 'raise_for_status': None, 'read_until_eof': True, 'proxy': None, 'proxy_auth': None, 'timeout': <object object at 0x00000225954C4FC0>, 'verify_ssl': None, 'fingerprint': None, 'ssl_context': None, 'ssl': None, 'proxy_headers': <CIMultiDict()>, 'read_bufsize': 65536, 'redirects': 0, 'history': [], 'version': HttpVersion(major=1, minor=1), 'url': URL('http://127.0.0.1:2381/v2/keys?recursive=true'), 'skip_headers': set(), 'real_timeout': ClientTimeout(total=300, connect=None, sock_read=None, sock_connect=None), 'tm': <aiohttp.helpers.TimeoutHandle object at 0x000002259606CE80>, 'handle': None, 'traces': [], 'timer': <aiohttp.helpers.TimerC...
  File "C:\Program Files\Python38\lib\site-packages\aiohttp\connector.py", line 535, in connect
    locals={'self': <aiohttp.connector.TCPConnector object at 0x000002259606C7C0>, 'req': <aiohttp.client_reqrep.ClientRequest object at 0x000002259606CC70>, 'traces': [], 'timeout': ClientTimeout(total=300, connect=None, sock_read=None, sock_connect=None), 'key': ConnectionKey(host='127.0.0.1', port=2381, is_ssl=False, ssl=None, proxy=None, proxy_auth=None, proxy_headers_hash=None), 'available': 100, 'proto': None, 'placeholder': <aiohttp.connector._TransportPlaceholder object at 0x000002259606CEE0>}
  File "C:\Program Files\Python38\lib\site-packages\aiohttp\connector.py", line 892, in _create_connection
    locals={'self': <aiohttp.connector.TCPConnector object at 0x000002259606C7C0>, 'req': <aiohttp.client_reqrep.ClientRequest object at 0x000002259606CC70>, 'traces': [], 'timeout': ClientTimeout(total=300, connect=None, sock_read=None, sock_connect=None)}
  File "C:\Program Files\Python38\lib\site-packages\aiohttp\connector.py", line 1051, in _create_direct_connection
    locals={'self': <aiohttp.connector.TCPConnector object at 0x000002259606C7C0>, 'req': <aiohttp.client_reqrep.ClientRequest object at 0x000002259606CC70>, 'traces': [], 'timeout': ClientTimeout(total=300, connect=None, sock_read=None, sock_connect=None), 'client_error': <class 'aiohttp.client_exceptions.ClientConnectorError'>, 'sslcontext': None, 'fingerprint': None, 'host': '127.0.0.1', 'port': 2381, 'host_resolved': <Task finished name='Task-8' coro=<TCPConnector._resolve_host() done, defined at C:\Program Files\Python38\lib\site-packages\aiohttp\connector.py:806> result=[{'family': 0, 'flags': 0, 'host': '127.0.0.1', 'hostname': '127.0.0.1', ...}] created at C:\Program Files\Python38\lib\site-packages\aiohttp\connector.py:992>, 'hosts': [{'hostname': '127.0.0.1', 'host': '127.0.0.1', 'port': 2381, 'family': 0, 'proto': 0, 'flags': 0}], 'last_exc': ClientConnectorError(ConnectionKey(host='127.0.0.1', port=2381, is_ssl=False, ssl=None, proxy=None, proxy_auth=None, proxy_headers_hash=None), ConnectionRefusedError(22,...
  File "C:\Program Files\Python38\lib\site-packages\aiohttp\connector.py", line 1020, in _create_direct_connection
    locals={'self': <aiohttp.connector.TCPConnector object at 0x000002259606C7C0>, 'req': <aiohttp.client_reqrep.ClientRequest object at 0x000002259606CC70>, 'traces': [], 'timeout': ClientTimeout(total=300, connect=None, sock_read=None, sock_connect=None), 'client_error': <class 'aiohttp.client_exceptions.ClientConnectorError'>, 'sslcontext': None, 'fingerprint': None, 'host': '127.0.0.1', 'port': 2381, 'host_resolved': <Task finished name='Task-8' coro=<TCPConnector._resolve_host() done, defined at C:\Program Files\Python38\lib\site-packages\aiohttp\connector.py:806> result=[{'family': 0, 'flags': 0, 'host': '127.0.0.1', 'hostname': '127.0.0.1', ...}] created at C:\Program Files\Python38\lib\site-packages\aiohttp\connector.py:992>, 'hosts': [{'hostname': '127.0.0.1', 'host': '127.0.0.1', 'port': 2381, 'family': 0, 'proto': 0, 'flags': 0}], 'last_exc': ClientConnectorError(ConnectionKey(host='127.0.0.1', port=2381, is_ssl=False, ssl=None, proxy=None, proxy_auth=None, proxy_headers_hash=None), ConnectionRefusedError(22,...
  File "C:\Program Files\Python38\lib\site-packages\aiohttp\connector.py", line 975, in _wrap_create_connection
    locals={'self': <aiohttp.connector.TCPConnector object at 0x000002259606C7C0>, 'req': <aiohttp.client_reqrep.ClientRequest object at 0x000002259606CC70>, 'timeout': ClientTimeout(total=300, connect=None, sock_read=None, sock_connect=None), 'client_error': <class 'aiohttp.client_exceptions.ClientConnectorError'>, 'args': (functools.partial(<class 'aiohttp.client_proto.ResponseHandler'>, loop=<ProactorEventLoop running=True closed=False debug=True>), '127.0.0.1', 2381), 'kwargs': {'ssl': None, 'family': 0, 'proto': 0, 'flags': 0, 'server_hostname': None, 'local_addr': None}}
2021-04-15 00:28:16,758 - DEBUG - ServiceFinder - [EtcdSupport.py:352]: _init_info, now_url: http://127.0.0.1:2383/v2/keys?recursive=true
2021-04-15 00:28:18,761 - ERROR - ServiceRegister - [EtcdSupport.py:172]: regist service : dispatcher_service error
2021-04-15 00:28:18,763 - CRITICAL - ServiceRegister - [EtcdSupport.py:173]: on_traceback, type:<class 'asyncio.exceptions.TimeoutError'>, value:, traceback:<class 'asyncio.exceptions.TimeoutError'>

  File "C:\Users\b\Documents\github\realtime-server\pycharm2020.1.3\script\core\EtcdSupport.py", line 158, in _do_regist
    locals={'self': <core.EtcdSupport.ServiceRegister object at 0x0000022596061550>, 'service_name': 'dispatcher_service', 'data': 'ttl=180', 'now_url': 'http://127.0.0.1:2381/v2/keys/services/dispatcher_service/127.0.0.1|9100'}
  File "C:\Users\b\Documents\github\realtime-server\pycharm2020.1.3\script\core\util\UtilApi.py", line 138, in async_http_requests
    locals={'method': 'put', 'url': 'http://127.0.0.1:2381/v2/keys/services/dispatcher_service/127.0.0.1|9100', 'session': <aiohttp.client.ClientSession object at 0x000002259606C700>, 'kwargs': {'data': 'ttl=180', 'headers': {'Content-Type': 'application/x-www-form-urlencoded'}, 'timeout': 2}, '_async_http_requests_impl': <function async_http_requests.<locals>._async_http_requests_impl at 0x000002259612E940>}
  File "C:\Users\b\Documents\github\realtime-server\pycharm2020.1.3\script\core\util\UtilApi.py", line 131, in _async_http_requests_impl
    locals={'_method': 'put', '_url': 'http://127.0.0.1:2381/v2/keys/services/dispatcher_service/127.0.0.1|9100', '_session': <aiohttp.client.ClientSession object at 0x000002259606C700>, '_kwargs': {'data': 'ttl=180', 'headers': {'Content-Type': 'application/x-www-form-urlencoded'}, 'timeout': 2}}
  File "C:\Program Files\Python38\lib\site-packages\aiohttp\client.py", line 1117, in __aenter__
    locals={'self': <aiohttp.client._RequestContextManager object at 0x000002259615DB00>, }
  File "C:\Program Files\Python38\lib\site-packages\aiohttp\client.py", line 619, in _request
    locals={'self': <aiohttp.client.ClientSession object at 0x000002259606C700>, 'method': 'PUT', 'str_or_url': 'http://127.0.0.1:2381/v2/keys/services/dispatcher_service/127.0.0.1|9100', 'params': None, 'data': 'ttl=180', 'json': None, 'cookies': None, 'headers': <CIMultiDict('Content-Type': 'application/x-www-form-urlencoded')>, 'skip_auto_headers': None, 'auth': None, 'allow_redirects': True, 'max_redirects': 10, 'compress': None, 'chunked': None, 'expect100': False, 'raise_for_status': None, 'read_until_eof': True, 'proxy': None, 'proxy_auth': None, 'timeout': 2, 'verify_ssl': None, 'fingerprint': None, 'ssl_context': None, 'ssl': None, 'proxy_headers': <CIMultiDict()>, 'read_bufsize': 65536, 'redirects': 0, 'history': [], 'version': HttpVersion(major=1, minor=1), 'url': URL('http://127.0.0.1:2381/v2/keys/services/dispatcher_service/127.0.0.1%7C9100'), 'skip_headers': set(), 'real_timeout': ClientTimeout(total=2, connect=None, sock_read=None, sock_connect=None), 'tm': <aiohttp.helpers.TimeoutHandle object at 0x00000...
  File "C:\Program Files\Python38\lib\site-packages\aiohttp\helpers.py", line 656, in __exit__
    locals={'self': <aiohttp.helpers.TimerContext object at 0x000002259606C850>, 'exc_type': <class 'asyncio.exceptions.CancelledError'>, 'exc_val': CancelledError(), 'exc_tb': <traceback object at 0x000002259618BA00>}
2021-04-15 00:28:18,765 - DEBUG - ServiceRegister - [EtcdSupport.py:155]: _do_regist: now_url: http://127.0.0.1:2383/v2/keys/services/dispatcher_service/127.0.0.1|9100
2021-04-15 00:28:18,770 - CRITICAL - ServiceFinder - [EtcdSupport.py:370]: on_traceback, type:<class 'aiohttp.client_exceptions.ClientConnectorError'>, value:Cannot connect to host 127.0.0.1:2383 ssl:default [The remote computer refused the network connection], traceback:<class 'aiohttp.client_exceptions.ClientConnectorError'>
Cannot connect to host 127.0.0.1:2383 ssl:default [The remote computer refused the network connection]
  File "C:\Users\b\Documents\github\realtime-server\pycharm2020.1.3\script\core\EtcdSupport.py", line 354, in _init_info
    locals={'self': <core.EtcdSupport.ServiceFinder object at 0x0000022595EF1A30>, 'now_url': 'http://127.0.0.1:2383/v2/keys?recursive=true'}
  File "C:\Users\b\Documents\github\realtime-server\pycharm2020.1.3\script\core\util\UtilApi.py", line 138, in async_http_requests
    locals={'method': 'get', 'url': 'http://127.0.0.1:2383/v2/keys?recursive=true', 'session': <aiohttp.client.ClientSession object at 0x000002259606C700>, 'kwargs': {}, '_async_http_requests_impl': <function async_http_requests.<locals>._async_http_requests_impl at 0x0000022596179700>}
  File "C:\Users\b\Documents\github\realtime-server\pycharm2020.1.3\script\core\util\UtilApi.py", line 131, in _async_http_requests_impl
    locals={'_method': 'get', '_url': 'http://127.0.0.1:2383/v2/keys?recursive=true', '_session': <aiohttp.client.ClientSession object at 0x000002259606C700>, '_kwargs': {}}
  File "C:\Program Files\Python38\lib\site-packages\aiohttp\client.py", line 1117, in __aenter__
    locals={'self': <aiohttp.client._RequestContextManager object at 0x0000022596181D80>, }
  File "C:\Program Files\Python38\lib\site-packages\aiohttp\client.py", line 520, in _request
    locals={'self': <aiohttp.client.ClientSession object at 0x000002259606C700>, 'method': 'GET', 'str_or_url': 'http://127.0.0.1:2383/v2/keys?recursive=true', 'params': None, 'data': None, 'json': None, 'cookies': None, 'headers': <CIMultiDict()>, 'skip_auto_headers': None, 'auth': None, 'allow_redirects': True, 'max_redirects': 10, 'compress': None, 'chunked': None, 'expect100': False, 'raise_for_status': None, 'read_until_eof': True, 'proxy': None, 'proxy_auth': None, 'timeout': <object object at 0x00000225954C4FC0>, 'verify_ssl': None, 'fingerprint': None, 'ssl_context': None, 'ssl': None, 'proxy_headers': <CIMultiDict()>, 'read_bufsize': 65536, 'redirects': 0, 'history': [], 'version': HttpVersion(major=1, minor=1), 'url': URL('http://127.0.0.1:2383/v2/keys?recursive=true'), 'skip_headers': set(), 'real_timeout': ClientTimeout(total=300, connect=None, sock_read=None, sock_connect=None), 'tm': <aiohttp.helpers.TimeoutHandle object at 0x00000225961610D0>, 'handle': None, 'traces': [], 'timer': <aiohttp.helpers.TimerC...
  File "C:\Program Files\Python38\lib\site-packages\aiohttp\connector.py", line 535, in connect
    locals={'self': <aiohttp.connector.TCPConnector object at 0x000002259606C7C0>, 'req': <aiohttp.client_reqrep.ClientRequest object at 0x0000022596161130>, 'traces': [], 'timeout': ClientTimeout(total=300, connect=None, sock_read=None, sock_connect=None), 'key': ConnectionKey(host='127.0.0.1', port=2383, is_ssl=False, ssl=None, proxy=None, proxy_auth=None, proxy_headers_hash=None), 'available': 99, 'proto': None, 'placeholder': <aiohttp.connector._TransportPlaceholder object at 0x0000022596161610>}
  File "C:\Program Files\Python38\lib\site-packages\aiohttp\connector.py", line 892, in _create_connection
    locals={'self': <aiohttp.connector.TCPConnector object at 0x000002259606C7C0>, 'req': <aiohttp.client_reqrep.ClientRequest object at 0x0000022596161130>, 'traces': [], 'timeout': ClientTimeout(total=300, connect=None, sock_read=None, sock_connect=None)}
  File "C:\Program Files\Python38\lib\site-packages\aiohttp\connector.py", line 1051, in _create_direct_connection
    locals={'self': <aiohttp.connector.TCPConnector object at 0x000002259606C7C0>, 'req': <aiohttp.client_reqrep.ClientRequest object at 0x0000022596161130>, 'traces': [], 'timeout': ClientTimeout(total=300, connect=None, sock_read=None, sock_connect=None), 'client_error': <class 'aiohttp.client_exceptions.ClientConnectorError'>, 'sslcontext': None, 'fingerprint': None, 'host': '127.0.0.1', 'port': 2383, 'host_resolved': <Task finished name='Task-12' coro=<TCPConnector._resolve_host() done, defined at C:\Program Files\Python38\lib\site-packages\aiohttp\connector.py:806> result=[{'family': 0, 'flags': 0, 'host': '127.0.0.1', 'hostname': '127.0.0.1', ...}] created at C:\Program Files\Python38\lib\site-packages\aiohttp\connector.py:992>, 'hosts': [{'hostname': '127.0.0.1', 'host': '127.0.0.1', 'port': 2383, 'family': 0, 'proto': 0, 'flags': 0}], 'last_exc': ClientConnectorError(ConnectionKey(host='127.0.0.1', port=2383, is_ssl=False, ssl=None, proxy=None, proxy_auth=None, proxy_headers_hash=None), ConnectionRefusedError(22...
  File "C:\Program Files\Python38\lib\site-packages\aiohttp\connector.py", line 1020, in _create_direct_connection
    locals={'self': <aiohttp.connector.TCPConnector object at 0x000002259606C7C0>, 'req': <aiohttp.client_reqrep.ClientRequest object at 0x0000022596161130>, 'traces': [], 'timeout': ClientTimeout(total=300, connect=None, sock_read=None, sock_connect=None), 'client_error': <class 'aiohttp.client_exceptions.ClientConnectorError'>, 'sslcontext': None, 'fingerprint': None, 'host': '127.0.0.1', 'port': 2383, 'host_resolved': <Task finished name='Task-12' coro=<TCPConnector._resolve_host() done, defined at C:\Program Files\Python38\lib\site-packages\aiohttp\connector.py:806> result=[{'family': 0, 'flags': 0, 'host': '127.0.0.1', 'hostname': '127.0.0.1', ...}] created at C:\Program Files\Python38\lib\site-packages\aiohttp\connector.py:992>, 'hosts': [{'hostname': '127.0.0.1', 'host': '127.0.0.1', 'port': 2383, 'family': 0, 'proto': 0, 'flags': 0}], 'last_exc': ClientConnectorError(ConnectionKey(host='127.0.0.1', port=2383, is_ssl=False, ssl=None, proxy=None, proxy_auth=None, proxy_headers_hash=None), ConnectionRefusedError(22...
  File "C:\Program Files\Python38\lib\site-packages\aiohttp\connector.py", line 975, in _wrap_create_connection
    locals={'self': <aiohttp.connector.TCPConnector object at 0x000002259606C7C0>, 'req': <aiohttp.client_reqrep.ClientRequest object at 0x0000022596161130>, 'timeout': ClientTimeout(total=300, connect=None, sock_read=None, sock_connect=None), 'client_error': <class 'aiohttp.client_exceptions.ClientConnectorError'>, 'args': (functools.partial(<class 'aiohttp.client_proto.ResponseHandler'>, loop=<ProactorEventLoop running=True closed=False debug=True>), '127.0.0.1', 2383), 'kwargs': {'ssl': None, 'family': 0, 'proto': 0, 'flags': 0, 'server_hostname': None, 'local_addr': None}}
2021-04-15 00:28:18,773 - DEBUG - ServiceFinder - [EtcdSupport.py:352]: _init_info, now_url: http://127.0.0.1:2381/v2/keys?recursive=true
2021-04-15 00:28:53,336 - DEBUG - ServiceNode - [EtcdSupport.py:533]: we have create ServiceFinder
2021-04-15 00:28:53,342 - DEBUG - ServiceFinder - [EtcdSupport.py:352]: _init_info, now_url: http://127.0.0.1:2381/v2/keys?recursive=true
2021-04-15 00:28:53,345 - DEBUG - ServiceRegister - [EtcdSupport.py:155]: _do_regist: now_url: http://127.0.0.1:2381/v2/keys/services/dispatcher_service/127.0.0.1|9100
2021-04-15 00:28:53,350 - DEBUG - TcpServer - [TcpServer.py:189]: Server on ('127.0.0.1', 9100)
2021-04-15 00:28:53,395 - DEBUG - ServiceFinder - [EtcdSupport.py:277]: init service info from etcd success, will going to watch, at etcd index -> 7
2021-04-15 00:28:53,399 - DEBUG - ServiceRegister - [EtcdSupport.py:163]: regist service : dispatcher_service success, {"action":"set","node":{"key":"/services/dispatcher_service/127.0.0.1|9100","value":"","expiration":"2021-04-14T16:31:53.3824999Z","ttl":180,"modifiedIndex":8,"createdIndex":8}}

2021-04-15 00:28:53,411 - DEBUG - ServiceFinder - [EtcdSupport.py:422]: recv watch set service node info--> dispatcher_service: ('127.0.0.1', 9100) - [8]
2021-04-15 00:29:05,144 - DEBUG - ServiceNode - [EtcdSupport.py:533]: we have create ServiceFinder
2021-04-15 00:29:05,150 - DEBUG - ServiceFinder - [EtcdSupport.py:352]: _init_info, now_url: http://127.0.0.1:2381/v2/keys?recursive=true
2021-04-15 00:29:05,156 - DEBUG - ServiceRegister - [EtcdSupport.py:155]: _do_regist: now_url: http://127.0.0.1:2381/v2/keys/services/dispatcher_service/127.0.0.1|9100
2021-04-15 00:29:05,167 - DEBUG - TcpServer - [TcpServer.py:189]: Server on ('127.0.0.1', 9100)
2021-04-15 00:29:05,186 - DEBUG - ServiceFinder - [EtcdSupport.py:323]: add service node info--> dispatcher_service: ('127.0.0.1', 9100)
2021-04-15 00:29:05,189 - DEBUG - ServiceFinder - [EtcdSupport.py:277]: init service info from etcd success, will going to watch, at etcd index -> 8
2021-04-15 00:29:05,199 - DEBUG - ServiceRegister - [EtcdSupport.py:163]: regist service : dispatcher_service success, {"action":"set","node":{"key":"/services/dispatcher_service/127.0.0.1|9100","value":"","expiration":"2021-04-14T16:32:05.181665Z","ttl":180,"modifiedIndex":9,"createdIndex":9},"prevNode":{"key":"/services/dispatcher_service/127.0.0.1|9100","value":"","expiration":"2021-04-14T16:31:53.3824999Z","ttl":169,"modifiedIndex":8,"createdIndex":8}}

2021-04-15 00:29:05,214 - DEBUG - ServiceFinder - [EtcdSupport.py:422]: recv watch set service node info--> dispatcher_service: ('127.0.0.1', 9100) - [9]
2021-04-15 00:29:05,217 - DEBUG - ServiceFinder - [EtcdSupport.py:299]: duplicate service info  -> dispatcher_service:('127.0.0.1', 9100)
2021-04-15 00:29:20,905 - DEBUG - ServiceNode - [EtcdSupport.py:533]: we have create ServiceFinder
2021-04-15 00:29:20,913 - DEBUG - ServiceFinder - [EtcdSupport.py:352]: _init_info, now_url: http://127.0.0.1:2383/v2/keys?recursive=true
2021-04-15 00:29:20,919 - DEBUG - ServiceRegister - [EtcdSupport.py:155]: _do_regist: now_url: http://127.0.0.1:2381/v2/keys/services/dispatcher_service/127.0.0.1|9100
2021-04-15 00:29:20,929 - DEBUG - TcpServer - [TcpServer.py:189]: Server on ('127.0.0.1', 9100)
2021-04-15 00:29:20,949 - DEBUG - ServiceFinder - [EtcdSupport.py:323]: add service node info--> dispatcher_service: ('127.0.0.1', 9100)
2021-04-15 00:29:20,952 - DEBUG - ServiceFinder - [EtcdSupport.py:277]: init service info from etcd success, will going to watch, at etcd index -> 9
2021-04-15 00:29:20,960 - DEBUG - ServiceRegister - [EtcdSupport.py:163]: regist service : dispatcher_service success, {"action":"set","node":{"key":"/services/dispatcher_service/127.0.0.1|9100","value":"","expiration":"2021-04-14T16:32:20.9431691Z","ttl":180,"modifiedIndex":10,"createdIndex":10},"prevNode":{"key":"/services/dispatcher_service/127.0.0.1|9100","value":"","expiration":"2021-04-14T16:32:05.181665Z","ttl":165,"modifiedIndex":9,"createdIndex":9}}

2021-04-15 00:29:20,978 - DEBUG - ServiceFinder - [EtcdSupport.py:422]: recv watch set service node info--> dispatcher_service: ('127.0.0.1', 9100) - [10]
2021-04-15 00:29:20,981 - DEBUG - ServiceFinder - [EtcdSupport.py:299]: duplicate service info  -> dispatcher_service:('127.0.0.1', 9100)
2021-04-15 00:29:43,458 - DEBUG - ServiceFinder - [EtcdSupport.py:422]: recv watch set service node info--> battle_server: ('127.0.0.1', 8888) - [11]
2021-04-15 00:30:02,056 - DEBUG - TcpServer - [TcpServer.py:175]: ('127.0.0.1', 1373) is connected !!!!
2021-04-15 00:30:02,070 - DEBUG - TcpServer - [TcpServer.py:175]: ('127.0.0.1', 1375) is connected !!!!
2021-04-15 00:30:02,095 - DEBUG - ServerEntity.LoadCollector - [ServerEntity.py:25]: __init__ create entity LoadCollector with id 6077188ad16412278c05c13a mem_id=2621317145120
2021-04-15 00:30:02,099 - DEBUG - server.EntityManager - [EntityManager.py:139]: addentity  entity id  6077188ad16412278c05c13a 
2021-04-15 00:30:23,778 - WARNING - TcpConn - [TcpConn.py:173]: the peer has performed an orderly shutdown (recv 0 byte).
2021-04-15 00:30:35,379 - DEBUG - ServerEntity.LoadCollector - [ServerEntity.py:25]: __init__ create entity LoadCollector with id 607718abd16412278c05c13b mem_id=2621317495920
2021-04-15 00:30:35,384 - DEBUG - server.EntityManager - [EntityManager.py:139]: addentity  entity id  607718abd16412278c05c13b 
2021-04-15 00:30:42,493 - DEBUG - TcpServer - [TcpServer.py:175]: ('127.0.0.1', 1376) is connected !!!!
2021-04-15 00:30:42,497 - WARNING - TcpConn - [TcpConn.py:173]: heartbeat timeout
2021-04-15 00:30:45,102 - DEBUG - TcpServer - [TcpServer.py:175]: ('127.0.0.1', 1378) is connected !!!!
2021-04-15 00:30:45,123 - DEBUG - TcpServer - [TcpServer.py:175]: ('127.0.0.1', 1379) is connected !!!!
2021-04-15 00:30:45,134 - DEBUG - ServerEntity.LoadCollector - [ServerEntity.py:25]: __init__ create entity LoadCollector with id 607718b5d16412278c05c13c mem_id=2621317494048
2021-04-15 00:30:45,138 - DEBUG - server.EntityManager - [EntityManager.py:139]: addentity  entity id  607718b5d16412278c05c13c 
2021-04-15 00:30:46,589 - WARNING - TcpConn - [TcpConn.py:173]: the peer has performed an orderly shutdown (recv 0 byte).
2021-04-15 00:30:46,602 - DEBUG - TcpServer - [TcpServer.py:175]: ('127.0.0.1', 1380) is connected !!!!
2021-04-15 00:30:47,321 - DEBUG - ServerEntity.LoadCollector - [ServerEntity.py:25]: __init__ create entity LoadCollector with id 607718b7d16412278c05c13d mem_id=2621316157984
2021-04-15 00:30:47,324 - DEBUG - server.EntityManager - [EntityManager.py:139]: addentity  entity id  607718b7d16412278c05c13d 
2021-04-15 00:30:48,270 - WARNING - TcpConn - [TcpConn.py:173]: the peer has performed an orderly shutdown (recv 0 byte).
2021-04-15 00:30:48,279 - DEBUG - TcpServer - [TcpServer.py:175]: ('127.0.0.1', 1382) is connected !!!!
2021-04-15 00:31:39,305 - DEBUG - ServiceNode - [EtcdSupport.py:533]: we have create ServiceFinder
2021-04-15 00:31:39,310 - DEBUG - ServiceFinder - [EtcdSupport.py:352]: _init_info, now_url: http://127.0.0.1:2379/v2/keys?recursive=true
2021-04-15 00:31:39,314 - DEBUG - ServiceRegister - [EtcdSupport.py:155]: _do_regist: now_url: http://127.0.0.1:2379/v2/keys/services/dispatcher_service/127.0.0.1|9100
2021-04-15 00:31:39,320 - DEBUG - TcpServer - [TcpServer.py:189]: Server on ('127.0.0.1', 9100)
2021-04-15 00:31:39,334 - DEBUG - ServiceFinder - [EtcdSupport.py:323]: add service node info--> battle_server: ('127.0.0.1', 8888)
2021-04-15 00:31:39,336 - DEBUG - ServiceFinder - [EtcdSupport.py:323]: add service node info--> dispatcher_service: ('127.0.0.1', 9100)
2021-04-15 00:31:39,337 - DEBUG - ServiceFinder - [EtcdSupport.py:277]: init service info from etcd success, will going to watch, at etcd index -> 11
2021-04-15 00:31:39,344 - DEBUG - ServiceRegister - [EtcdSupport.py:163]: regist service : dispatcher_service success, {"action":"set","node":{"key":"/services/dispatcher_service/127.0.0.1|9100","value":"","expiration":"2021-04-14T16:34:39.3314451Z","ttl":180,"modifiedIndex":12,"createdIndex":12},"prevNode":{"key":"/services/dispatcher_service/127.0.0.1|9100","value":"","expiration":"2021-04-14T16:32:20.9431691Z","ttl":42,"modifiedIndex":10,"createdIndex":10}}

2021-04-15 00:31:39,354 - DEBUG - ServiceFinder - [EtcdSupport.py:422]: recv watch set service node info--> dispatcher_service: ('127.0.0.1', 9100) - [12]
2021-04-15 00:31:39,356 - DEBUG - ServiceFinder - [EtcdSupport.py:299]: duplicate service info  -> dispatcher_service:('127.0.0.1', 9100)
2021-04-15 00:31:41,842 - DEBUG - ServiceFinder - [EtcdSupport.py:422]: recv watch set service node info--> battle_server: ('127.0.0.1', 8888) - [13]
2021-04-15 00:31:41,843 - DEBUG - ServiceFinder - [EtcdSupport.py:299]: duplicate service info  -> battle_server:('127.0.0.1', 8888)
2021-04-15 00:31:47,815 - DEBUG - TcpServer - [TcpServer.py:175]: ('127.0.0.1', 1405) is connected !!!!
2021-04-15 00:31:47,829 - DEBUG - ServerEntity.LoadCollector - [ServerEntity.py:25]: __init__ create entity LoadCollector with id 607718f3d1641234f00917c5 mem_id=1476449796784
2021-04-15 00:31:47,831 - DEBUG - server.EntityManager - [EntityManager.py:139]: addentity  entity id  607718f3d1641234f00917c5 
2021-04-15 00:32:36,109 - DEBUG - ServiceNode - [EtcdSupport.py:533]: we have create ServiceFinder
2021-04-15 00:32:36,114 - DEBUG - ServiceFinder - [EtcdSupport.py:352]: _init_info, now_url: http://127.0.0.1:2383/v2/keys?recursive=true
2021-04-15 00:32:36,117 - DEBUG - ServiceRegister - [EtcdSupport.py:155]: _do_regist: now_url: http://127.0.0.1:2379/v2/keys/services/dispatcher_service/127.0.0.1|9100
2021-04-15 00:32:36,123 - DEBUG - TcpServer - [TcpServer.py:189]: Server on ('127.0.0.1', 9100)
2021-04-15 00:32:36,134 - DEBUG - ServiceFinder - [EtcdSupport.py:323]: add service node info--> dispatcher_service: ('127.0.0.1', 9100)
2021-04-15 00:32:36,136 - DEBUG - ServiceFinder - [EtcdSupport.py:323]: add service node info--> battle_server: ('127.0.0.1', 8888)
2021-04-15 00:32:36,137 - DEBUG - ServiceFinder - [EtcdSupport.py:277]: init service info from etcd success, will going to watch, at etcd index -> 13
2021-04-15 00:32:36,142 - DEBUG - ServiceRegister - [EtcdSupport.py:163]: regist service : dispatcher_service success, {"action":"set","node":{"key":"/services/dispatcher_service/127.0.0.1|9100","value":"","expiration":"2021-04-14T16:35:36.1318934Z","ttl":180,"modifiedIndex":14,"createdIndex":14},"prevNode":{"key":"/services/dispatcher_service/127.0.0.1|9100","value":"","expiration":"2021-04-14T16:34:39.3314451Z","ttl":124,"modifiedIndex":12,"createdIndex":12}}

2021-04-15 00:32:36,148 - DEBUG - ServiceFinder - [EtcdSupport.py:422]: recv watch set service node info--> dispatcher_service: ('127.0.0.1', 9100) - [14]
2021-04-15 00:32:36,149 - DEBUG - ServiceFinder - [EtcdSupport.py:299]: duplicate service info  -> dispatcher_service:('127.0.0.1', 9100)
2021-04-15 00:32:38,077 - DEBUG - ServiceFinder - [EtcdSupport.py:422]: recv watch set service node info--> battle_server: ('127.0.0.1', 8888) - [15]
2021-04-15 00:32:38,078 - DEBUG - ServiceFinder - [EtcdSupport.py:299]: duplicate service info  -> battle_server:('127.0.0.1', 8888)
2021-04-15 00:32:44,048 - DEBUG - TcpServer - [TcpServer.py:175]: ('127.0.0.1', 1426) is connected !!!!
2021-04-15 00:32:44,062 - DEBUG - ServerEntity.LoadCollector - [ServerEntity.py:25]: __init__ create entity LoadCollector with id 6077192cd164121b0cc946aa mem_id=1936024870576
2021-04-15 00:32:44,064 - DEBUG - server.EntityManager - [EntityManager.py:139]: addentity  entity id  6077192cd164121b0cc946aa 
2021-04-15 00:33:31,234 - DEBUG - ServiceNode - [EtcdSupport.py:533]: we have create ServiceFinder
2021-04-15 00:33:31,239 - DEBUG - ServiceFinder - [EtcdSupport.py:352]: _init_info, now_url: http://127.0.0.1:2381/v2/keys?recursive=true
2021-04-15 00:33:31,242 - DEBUG - ServiceRegister - [EtcdSupport.py:155]: _do_regist: now_url: http://127.0.0.1:2379/v2/keys/services/dispatcher_service/127.0.0.1|9100
2021-04-15 00:33:31,248 - DEBUG - TcpServer - [TcpServer.py:189]: Server on ('127.0.0.1', 9100)
2021-04-15 00:33:31,259 - DEBUG - ServiceFinder - [EtcdSupport.py:323]: add service node info--> dispatcher_service: ('127.0.0.1', 9100)
2021-04-15 00:33:31,261 - DEBUG - ServiceFinder - [EtcdSupport.py:323]: add service node info--> battle_server: ('127.0.0.1', 8888)
2021-04-15 00:33:31,263 - DEBUG - ServiceFinder - [EtcdSupport.py:277]: init service info from etcd success, will going to watch, at etcd index -> 16
2021-04-15 00:33:31,269 - DEBUG - ServiceRegister - [EtcdSupport.py:163]: regist service : dispatcher_service success, {"action":"set","node":{"key":"/services/dispatcher_service/127.0.0.1|9100","value":"","expiration":"2021-04-14T16:36:31.2562872Z","ttl":180,"modifiedIndex":17,"createdIndex":17},"prevNode":{"key":"/services/dispatcher_service/127.0.0.1|9100","value":"","expiration":"2021-04-14T16:35:36.1318934Z","ttl":125,"modifiedIndex":14,"createdIndex":14}}

2021-04-15 00:33:31,278 - DEBUG - ServiceFinder - [EtcdSupport.py:422]: recv watch set service node info--> dispatcher_service: ('127.0.0.1', 9100) - [17]
2021-04-15 00:33:31,279 - DEBUG - ServiceFinder - [EtcdSupport.py:299]: duplicate service info  -> dispatcher_service:('127.0.0.1', 9100)
2021-04-15 00:33:35,378 - DEBUG - TcpServer - [TcpServer.py:175]: ('127.0.0.1', 1444) is connected !!!!
2021-04-15 00:33:35,392 - DEBUG - ServerEntity.LoadCollector - [ServerEntity.py:25]: __init__ create entity LoadCollector with id 6077195fd1641212d4c7d691 mem_id=1807043337760
2021-04-15 00:33:35,394 - DEBUG - server.EntityManager - [EntityManager.py:139]: addentity  entity id  6077195fd1641212d4c7d691 
2021-04-15 00:45:18,801 - DEBUG - ServiceNode - [EtcdSupport.py:533]: we have create ServiceFinder
2021-04-15 00:45:18,828 - DEBUG - ServiceFinder - [EtcdSupport.py:352]: _init_info, now_url: http://127.0.0.1:2379/v2/keys?recursive=true
2021-04-15 00:45:18,832 - DEBUG - ServiceRegister - [EtcdSupport.py:155]: _do_regist: now_url: http://127.0.0.1:2381/v2/keys/services/dispatcher_service/127.0.0.1|9100
2021-04-15 00:45:18,837 - DEBUG - TcpServer - [TcpServer.py:189]: Server on ('127.0.0.1', 9100)
2021-04-15 00:45:18,892 - DEBUG - ServiceFinder - [EtcdSupport.py:277]: init service info from etcd success, will going to watch, at etcd index -> 19
2021-04-15 00:45:18,897 - DEBUG - ServiceRegister - [EtcdSupport.py:163]: regist service : dispatcher_service success, {"action":"set","node":{"key":"/services/dispatcher_service/127.0.0.1|9100","value":"","expiration":"2021-04-14T16:48:18.8718423Z","ttl":180,"modifiedIndex":20,"createdIndex":20}}

2021-04-15 00:45:18,906 - DEBUG - ServiceFinder - [EtcdSupport.py:422]: recv watch set service node info--> dispatcher_service: ('127.0.0.1', 9100) - [20]
2021-04-15 00:45:22,454 - DEBUG - ServiceFinder - [EtcdSupport.py:422]: recv watch set service node info--> battle_server: ('127.0.0.1', 8888) - [21]
2021-04-15 00:45:28,423 - DEBUG - TcpServer - [TcpServer.py:175]: ('127.0.0.1', 1538) is connected !!!!
2021-04-15 00:45:28,436 - DEBUG - ServerEntity.LoadCollector - [ServerEntity.py:25]: __init__ create entity LoadCollector with id 60771c28d16412360c49a060 mem_id=1616365885856
2021-04-15 00:45:28,439 - DEBUG - server.EntityManager - [EntityManager.py:139]: addentity  entity id  60771c28d16412360c49a060 
2021-04-15 00:45:28,442 - ERROR - RpcHandler - [RpcHandler.py:272]: Exception AttributeError("'NoneType' object has no attribute 'zadd'") in call handler 'report_load'
2021-04-15 00:45:34,437 - ERROR - RpcHandler - [RpcHandler.py:272]: Exception TypeError("Argument {'battle_0|127.0.0.1|8888': 0.15610179963918608} expected to be of bytearray, bytes, float, int, or str type") in call handler 'report_load'
2021-04-15 00:45:40,423 - ERROR - RpcHandler - [RpcHandler.py:272]: Exception TypeError("Argument {'battle_0|127.0.0.1|8888': 0.15751097284464297} expected to be of bytearray, bytes, float, int, or str type") in call handler 'report_load'
2021-04-15 00:45:46,421 - ERROR - RpcHandler - [RpcHandler.py:272]: Exception TypeError("Argument {'battle_0|127.0.0.1|8888': 0.15716817181443432} expected to be of bytearray, bytes, float, int, or str type") in call handler 'report_load'
2021-04-15 00:45:52,416 - ERROR - RpcHandler - [RpcHandler.py:272]: Exception TypeError("Argument {'battle_0|127.0.0.1|8888': 0.0} expected to be of bytearray, bytes, float, int, or str type") in call handler 'report_load'
2021-04-15 00:45:58,416 - ERROR - RpcHandler - [RpcHandler.py:272]: Exception TypeError("Argument {'battle_0|127.0.0.1|8888': 0.15655532420922075} expected to be of bytearray, bytes, float, int, or str type") in call handler 'report_load'
2021-04-15 00:46:04,420 - ERROR - RpcHandler - [RpcHandler.py:272]: Exception TypeError("Argument {'battle_0|127.0.0.1|8888': 0.1566668515355914} expected to be of bytearray, bytes, float, int, or str type") in call handler 'report_load'
2021-04-15 00:46:10,420 - ERROR - RpcHandler - [RpcHandler.py:272]: Exception TypeError("Argument {'battle_0|127.0.0.1|8888': 0.0} expected to be of bytearray, bytes, float, int, or str type") in call handler 'report_load'
2021-04-15 00:46:16,417 - ERROR - RpcHandler - [RpcHandler.py:272]: Exception TypeError("Argument {'battle_0|127.0.0.1|8888': 0.1571937311516115} expected to be of bytearray, bytes, float, int, or str type") in call handler 'report_load'
2021-04-15 00:46:22,418 - ERROR - RpcHandler - [RpcHandler.py:272]: Exception TypeError("Argument {'battle_0|127.0.0.1|8888': 0.1565846502315224} expected to be of bytearray, bytes, float, int, or str type") in call handler 'report_load'
2021-04-15 00:46:27,458 - DEBUG - ServiceFinder - [EtcdSupport.py:475]: etcd watch timeout, rest watch index 21 -> 21
2021-04-15 00:46:28,419 - ERROR - RpcHandler - [RpcHandler.py:272]: Exception TypeError("Argument {'battle_0|127.0.0.1|8888': 0.3137464420710157} expected to be of bytearray, bytes, float, int, or str type") in call handler 'report_load'
2021-04-15 00:46:32,451 - DEBUG - ServiceNode - [EtcdSupport.py:533]: we have create ServiceFinder
2021-04-15 00:46:32,459 - DEBUG - ServiceFinder - [EtcdSupport.py:352]: _init_info, now_url: http://127.0.0.1:2381/v2/keys?recursive=true
2021-04-15 00:46:32,464 - DEBUG - ServiceRegister - [EtcdSupport.py:155]: _do_regist: now_url: http://127.0.0.1:2381/v2/keys/services/dispatcher_service/127.0.0.1|9100
2021-04-15 00:46:32,473 - DEBUG - TcpServer - [TcpServer.py:189]: Server on ('127.0.0.1', 9100)
2021-04-15 00:46:32,491 - DEBUG - ServiceFinder - [EtcdSupport.py:323]: add service node info--> battle_server: ('127.0.0.1', 8888)
2021-04-15 00:46:32,493 - DEBUG - ServiceFinder - [EtcdSupport.py:323]: add service node info--> dispatcher_service: ('127.0.0.1', 9100)
2021-04-15 00:46:32,496 - DEBUG - ServiceFinder - [EtcdSupport.py:277]: init service info from etcd success, will going to watch, at etcd index -> 21
2021-04-15 00:46:32,513 - DEBUG - TcpServer - [TcpServer.py:175]: ('127.0.0.1', 1543) is connected !!!!
2021-04-15 00:46:32,516 - DEBUG - ServiceRegister - [EtcdSupport.py:163]: regist service : dispatcher_service success, {"action":"set","node":{"key":"/services/dispatcher_service/127.0.0.1|9100","value":"","expiration":"2021-04-14T16:49:32.4871418Z","ttl":180,"modifiedIndex":22,"createdIndex":22},"prevNode":{"key":"/services/dispatcher_service/127.0.0.1|9100","value":"","expiration":"2021-04-14T16:48:18.8718423Z","ttl":107,"modifiedIndex":20,"createdIndex":20}}

2021-04-15 00:46:32,528 - DEBUG - ServiceFinder - [EtcdSupport.py:422]: recv watch set service node info--> dispatcher_service: ('127.0.0.1', 9100) - [22]
2021-04-15 00:46:32,530 - DEBUG - ServiceFinder - [EtcdSupport.py:299]: duplicate service info  -> dispatcher_service:('127.0.0.1', 9100)
2021-04-15 00:46:34,425 - DEBUG - ServerEntity.LoadCollector - [ServerEntity.py:25]: __init__ create entity LoadCollector with id 60771c6ad1641204a82659b4 mem_id=1932060529472
2021-04-15 00:46:34,428 - DEBUG - server.EntityManager - [EntityManager.py:139]: addentity  entity id  60771c6ad1641204a82659b4 
2021-04-15 00:46:34,431 - ERROR - RpcHandler - [RpcHandler.py:272]: Exception AttributeError("'NoneType' object has no attribute 'zadd'") in call handler 'report_load'
2021-04-15 00:46:34,530 - WARNING - TcpConn - [TcpConn.py:173]: connection is closed by error: [WinError 64] The specified network name is no longer available
2021-04-15 00:46:35,505 - DEBUG - ServiceFinder - [EtcdSupport.py:422]: recv watch set service node info--> battle_server: ('127.0.0.1', 8888) - [23]
2021-04-15 00:46:35,507 - DEBUG - ServiceFinder - [EtcdSupport.py:299]: duplicate service info  -> battle_server:('127.0.0.1', 8888)
2021-04-15 00:46:41,446 - DEBUG - TcpServer - [TcpServer.py:175]: ('127.0.0.1', 1559) is connected !!!!
2021-04-15 00:46:41,449 - DEBUG - ServerEntity.LoadCollector - [ServerEntity.py:25]: __init__ create entity LoadCollector with id 60771c71d1641204a82659b5 mem_id=1932061043152
2021-04-15 00:46:41,451 - DEBUG - server.EntityManager - [EntityManager.py:139]: addentity  entity id  60771c71d1641204a82659b5 
2021-04-15 00:46:41,454 - ERROR - RpcHandler - [RpcHandler.py:272]: Exception AttributeError("'NoneType' object has no attribute 'zadd'") in call handler 'report_load'
2021-04-15 00:46:47,455 - ERROR - RpcHandler - [RpcHandler.py:272]: Exception TypeError("Argument {'battle_0|127.0.0.1|8888': 0.0} expected to be of bytearray, bytes, float, int, or str type") in call handler 'report_load'
2021-04-15 00:46:53,449 - ERROR - RpcHandler - [RpcHandler.py:272]: Exception TypeError("Argument {'battle_0|127.0.0.1|8888': 0.15677084965465968} expected to be of bytearray, bytes, float, int, or str type") in call handler 'report_load'
2021-04-15 00:58:38,046 - DEBUG - ServerEntity.LoadCollector - [ServerEntity.py:25]: __init__ create entity LoadCollector with id 60771f3ed164121744da4853 mem_id=2443478590848
2021-04-15 00:58:38,047 - DEBUG - server.EntityManager - [EntityManager.py:139]: addentity  entity id  60771f3ed164121744da4853 
2021-04-15 00:58:38,056 - DEBUG - ServiceNode - [EtcdSupport.py:533]: we have create ServiceFinder
2021-04-15 00:58:38,061 - DEBUG - ServiceFinder - [EtcdSupport.py:352]: _init_info, now_url: http://127.0.0.1:2379/v2/keys?recursive=true
2021-04-15 00:58:38,064 - DEBUG - ServiceRegister - [EtcdSupport.py:155]: _do_regist: now_url: http://127.0.0.1:2379/v2/keys/services/dispatcher_service/127.0.0.1|9100
2021-04-15 00:58:38,071 - DEBUG - TcpServer - [TcpServer.py:189]: Server on ('127.0.0.1', 9100)
2021-04-15 00:58:38,083 - DEBUG - ServiceFinder - [EtcdSupport.py:277]: init service info from etcd success, will going to watch, at etcd index -> 25
2021-04-15 00:58:38,089 - DEBUG - ServiceRegister - [EtcdSupport.py:163]: regist service : dispatcher_service success, {"action":"set","node":{"key":"/services/dispatcher_service/127.0.0.1|9100","value":"","expiration":"2021-04-14T17:01:38.0809715Z","ttl":180,"modifiedIndex":26,"createdIndex":26}}

2021-04-15 00:58:38,097 - DEBUG - ServiceFinder - [EtcdSupport.py:422]: recv watch set service node info--> dispatcher_service: ('127.0.0.1', 9100) - [26]
2021-04-15 00:58:44,755 - DEBUG - ServiceFinder - [EtcdSupport.py:422]: recv watch set service node info--> battle_server: ('127.0.0.1', 8888) - [27]
2021-04-15 00:58:50,726 - DEBUG - TcpServer - [TcpServer.py:175]: ('127.0.0.1', 1587) is connected !!!!
2021-04-15 00:58:50,729 - ERROR - RpcHandler - [RpcHandler.py:273]: Exception TypeError("Argument {'battle_0|127.0.0.1|8888': 0.9302191343399888} expected to be of bytearray, bytes, float, int, or str type") in call handler 'report_load'
2021-04-15 00:58:56,726 - ERROR - RpcHandler - [RpcHandler.py:273]: Exception TypeError("Argument {'battle_0|127.0.0.1|8888': 0.15622992326530455} expected to be of bytearray, bytes, float, int, or str type") in call handler 'report_load'
2021-04-15 01:01:37,985 - DEBUG - ServerEntity.LoadCollector - [ServerEntity.py:25]: __init__ create entity LoadCollector with id 60771ff1d164120c4c899d2b mem_id=2071959793568
2021-04-15 01:01:37,987 - DEBUG - server.EntityManager - [EntityManager.py:139]: addentity  entity id  60771ff1d164120c4c899d2b 
2021-04-15 01:01:37,996 - DEBUG - ServiceNode - [EtcdSupport.py:533]: we have create ServiceFinder
2021-04-15 01:01:38,001 - DEBUG - ServiceFinder - [EtcdSupport.py:352]: _init_info, now_url: http://127.0.0.1:2381/v2/keys?recursive=true
2021-04-15 01:01:38,005 - DEBUG - ServiceRegister - [EtcdSupport.py:155]: _do_regist: now_url: http://127.0.0.1:2379/v2/keys/services/dispatcher_service/127.0.0.1|9100
2021-04-15 01:01:38,012 - DEBUG - TcpServer - [TcpServer.py:189]: Server on ('127.0.0.1', 9100)
2021-04-15 01:01:38,025 - DEBUG - ServiceFinder - [EtcdSupport.py:323]: add service node info--> dispatcher_service: ('127.0.0.1', 9100)
2021-04-15 01:01:38,026 - DEBUG - ServiceFinder - [EtcdSupport.py:323]: add service node info--> battle_server: ('127.0.0.1', 8888)
2021-04-15 01:01:38,028 - DEBUG - ServiceFinder - [EtcdSupport.py:277]: init service info from etcd success, will going to watch, at etcd index -> 27
2021-04-15 01:01:38,033 - DEBUG - ServiceRegister - [EtcdSupport.py:163]: regist service : dispatcher_service success, {"action":"set","node":{"key":"/services/dispatcher_service/127.0.0.1|9100","value":"","expiration":"2021-04-14T17:04:38.0227061Z","ttl":180,"modifiedIndex":28,"createdIndex":28},"prevNode":{"key":"/services/dispatcher_service/127.0.0.1|9100","value":"","expiration":"2021-04-14T17:01:38.0809715Z","ttl":1,"modifiedIndex":26,"createdIndex":26}}

2021-04-15 01:01:38,038 - DEBUG - ServiceFinder - [EtcdSupport.py:422]: recv watch set service node info--> dispatcher_service: ('127.0.0.1', 9100) - [28]
2021-04-15 01:01:38,040 - DEBUG - ServiceFinder - [EtcdSupport.py:299]: duplicate service info  -> dispatcher_service:('127.0.0.1', 9100)
2021-04-15 01:01:41,310 - DEBUG - ServerEntity.LoadCollector - [ServerEntity.py:25]: __init__ create entity LoadCollector with id 60771ff5d1641204d0e54598 mem_id=2185226451408
2021-04-15 01:01:41,311 - DEBUG - server.EntityManager - [EntityManager.py:139]: addentity  entity id  60771ff5d1641204d0e54598 
2021-04-15 01:01:41,327 - DEBUG - ServiceNode - [EtcdSupport.py:533]: we have create ServiceFinder
2021-04-15 01:01:41,338 - DEBUG - ServiceFinder - [EtcdSupport.py:352]: _init_info, now_url: http://127.0.0.1:2379/v2/keys?recursive=true
2021-04-15 01:01:41,345 - DEBUG - ServiceRegister - [EtcdSupport.py:155]: _do_regist: now_url: http://127.0.0.1:2381/v2/keys/services/dispatcher_service/127.0.0.1|9100
2021-04-15 01:01:41,359 - DEBUG - TcpServer - [TcpServer.py:189]: Server on ('127.0.0.1', 9100)
2021-04-15 01:01:41,380 - DEBUG - ServiceFinder - [EtcdSupport.py:323]: add service node info--> dispatcher_service: ('127.0.0.1', 9100)
2021-04-15 01:01:41,384 - DEBUG - ServiceFinder - [EtcdSupport.py:323]: add service node info--> battle_server: ('127.0.0.1', 8888)
2021-04-15 01:01:41,387 - DEBUG - ServiceFinder - [EtcdSupport.py:277]: init service info from etcd success, will going to watch, at etcd index -> 28
2021-04-15 01:01:41,394 - DEBUG - ServiceRegister - [EtcdSupport.py:163]: regist service : dispatcher_service success, {"action":"set","node":{"key":"/services/dispatcher_service/127.0.0.1|9100","value":"","expiration":"2021-04-14T17:04:41.3749301Z","ttl":180,"modifiedIndex":29,"createdIndex":29},"prevNode":{"key":"/services/dispatcher_service/127.0.0.1|9100","value":"","expiration":"2021-04-14T17:04:38.0227061Z","ttl":177,"modifiedIndex":28,"createdIndex":28}}

2021-04-15 01:01:41,411 - DEBUG - ServiceFinder - [EtcdSupport.py:422]: recv watch set service node info--> dispatcher_service: ('127.0.0.1', 9100) - [29]
2021-04-15 01:01:41,413 - DEBUG - ServiceFinder - [EtcdSupport.py:299]: duplicate service info  -> dispatcher_service:('127.0.0.1', 9100)
2021-04-15 01:01:45,060 - DEBUG - ServiceFinder - [EtcdSupport.py:433]: recv watch expire, info--> battle_server: ('127.0.0.1', 8888) - [30]
2021-04-15 01:01:50,121 - DEBUG - ServiceFinder - [EtcdSupport.py:422]: recv watch set service node info--> battle_server: ('127.0.0.1', 8888) - [31]
2021-04-15 01:01:56,095 - DEBUG - TcpServer - [TcpServer.py:175]: ('127.0.0.1', 1615) is connected !!!!
2021-04-15 01:03:01,309 - ERROR - RpcHandler - [RpcHandler.py:273]: Exception TypeError("Argument {'battle_0|127.0.0.1|8888': 1.2576376308759865} expected to be of bytearray, bytes, float, int, or str type") in call handler 'report_load'
2021-04-15 01:03:01,321 - WARNING - TcpConn - [TcpConn.py:173]: connection is closed by error: [WinError 10053] An established connection was aborted by the software in your host machine
2021-04-15 01:03:01,330 - DEBUG - TcpServer - [TcpServer.py:175]: ('127.0.0.1', 1616) is connected !!!!
2021-04-15 01:03:01,344 - DEBUG - TcpServer - [TcpServer.py:175]: ('127.0.0.1', 1617) is connected !!!!
2021-04-15 01:03:01,359 - DEBUG - TcpServer - [TcpServer.py:175]: ('127.0.0.1', 1618) is connected !!!!
2021-04-15 01:03:01,366 - DEBUG - ServiceFinder - [EtcdSupport.py:475]: etcd watch timeout, rest watch index 31 -> 31
2021-04-15 01:04:34,883 - ERROR - RpcHandler - [RpcHandler.py:273]: Exception TypeError("Argument {'battle_0|127.0.0.1|8888': 0.15586323153642864} expected to be of bytearray, bytes, float, int, or str type") in call handler 'report_load'
2021-04-15 01:04:34,889 - WARNING - TcpConn - [TcpConn.py:173]: the peer has performed an orderly shutdown (recv 0 byte).
2021-04-15 01:04:34,898 - DEBUG - TcpServer - [TcpServer.py:175]: ('127.0.0.1', 1619) is connected !!!!
2021-04-15 01:04:36,744 - ERROR - RpcHandler - [RpcHandler.py:273]: Exception TypeError("Argument {'battle_0|127.0.0.1|8888': 0.16081108304801978} expected to be of bytearray, bytes, float, int, or str type") in call handler 'report_load'
2021-04-15 01:04:36,751 - WARNING - TcpConn - [TcpConn.py:173]: the peer has performed an orderly shutdown (recv 0 byte).
2021-04-15 01:04:36,759 - DEBUG - TcpServer - [TcpServer.py:175]: ('127.0.0.1', 1620) is connected !!!!
2021-04-15 01:04:36,772 - ERROR - RpcHandler - [RpcHandler.py:273]: Exception TypeError("Argument {'battle_0|127.0.0.1|8888': 0.16081108304801978} expected to be of bytearray, bytes, float, int, or str type") in call handler 'report_load'
2021-04-15 01:04:36,778 - WARNING - TcpConn - [TcpConn.py:173]: the peer has performed an orderly shutdown (recv 0 byte).
2021-04-15 01:04:36,787 - DEBUG - TcpServer - [TcpServer.py:175]: ('127.0.0.1', 1621) is connected !!!!
2021-04-15 01:04:36,790 - DEBUG - ServiceRegister - [EtcdSupport.py:196]: outside, time.time()=1618419876.7874813, refresh service dispatcher_service, now_url: http://127.0.0.1:2381/v2/keys/services/dispatcher_service/127.0.0.1|9100
2021-04-15 01:04:36,801 - ERROR - RpcHandler - [RpcHandler.py:273]: Exception TypeError("Argument {'battle_0|127.0.0.1|8888': 0.15957499910516643} expected to be of bytearray, bytes, float, int, or str type") in call handler 'report_load'
2021-04-15 01:04:36,806 - WARNING - TcpConn - [TcpConn.py:173]: the peer has performed an orderly shutdown (recv 0 byte).
2021-04-15 01:04:36,810 - WARNING - TcpConn - [TcpConn.py:173]: the peer has performed an orderly shutdown (recv 0 byte).
2021-04-15 01:04:36,820 - DEBUG - TcpServer - [TcpServer.py:175]: ('127.0.0.1', 1622) is connected !!!!
2021-04-15 01:04:36,836 - DEBUG - TcpServer - [TcpServer.py:175]: ('127.0.0.1', 1623) is connected !!!!
2021-04-15 01:04:36,845 - DEBUG - ServiceFinder - [EtcdSupport.py:475]: etcd watch timeout, rest watch index 31 -> 31
2021-04-15 01:04:36,850 - ERROR - RpcHandler - [RpcHandler.py:273]: Exception TypeError("Argument {'battle_0|127.0.0.1|8888': 0.15555428437694857} expected to be of bytearray, bytes, float, int, or str type") in call handler 'report_load'
2021-04-15 01:04:36,855 - WARNING - TcpConn - [TcpConn.py:173]: the peer has performed an orderly shutdown (recv 0 byte).
2021-04-15 01:04:36,859 - WARNING - TcpConn - [TcpConn.py:173]: the peer has performed an orderly shutdown (recv 0 byte).
2021-04-15 01:04:36,868 - DEBUG - TcpServer - [TcpServer.py:175]: ('127.0.0.1', 1624) is connected !!!!
2021-04-15 01:04:36,887 - DEBUG - TcpServer - [TcpServer.py:175]: ('127.0.0.1', 1625) is connected !!!!
2021-04-15 01:04:36,897 - ERROR - RpcHandler - [RpcHandler.py:273]: Exception TypeError("Argument {'battle_0|127.0.0.1|8888': 0.311767524412026} expected to be of bytearray, bytes, float, int, or str type") in call handler 'report_load'
2021-04-15 01:04:36,902 - ERROR - RpcHandler - [RpcHandler.py:273]: Exception TypeError("Argument {'battle_0|127.0.0.1|8888': 0.15621324003507742} expected to be of bytearray, bytes, float, int, or str type") in call handler 'report_load'
2021-04-15 01:04:36,907 - WARNING - TcpConn - [TcpConn.py:173]: the peer has performed an orderly shutdown (recv 0 byte).
2021-04-15 01:04:36,911 - WARNING - TcpConn - [TcpConn.py:173]: the peer has performed an orderly shutdown (recv 0 byte).
2021-04-15 01:04:36,920 - DEBUG - TcpServer - [TcpServer.py:175]: ('127.0.0.1', 1628) is connected !!!!
2021-04-15 01:04:36,939 - DEBUG - TcpServer - [TcpServer.py:175]: ('127.0.0.1', 1629) is connected !!!!
2021-04-15 01:04:36,951 - ERROR - RpcHandler - [RpcHandler.py:273]: Exception TypeError("Argument {'battle_0|127.0.0.1|8888': 0.1560742152707722} expected to be of bytearray, bytes, float, int, or str type") in call handler 'report_load'
2021-04-15 01:04:36,958 - WARNING - TcpConn - [TcpConn.py:173]: the peer has performed an orderly shutdown (recv 0 byte).
2021-04-15 01:04:36,962 - WARNING - TcpConn - [TcpConn.py:173]: the peer has performed an orderly shutdown (recv 0 byte).
2021-04-15 01:04:36,971 - DEBUG - TcpServer - [TcpServer.py:175]: ('127.0.0.1', 1632) is connected !!!!
2021-04-15 01:04:36,987 - DEBUG - TcpServer - [TcpServer.py:175]: ('127.0.0.1', 1633) is connected !!!!
2021-04-15 01:04:36,996 - ERROR - RpcHandler - [RpcHandler.py:273]: Exception TypeError("Argument {'battle_0|127.0.0.1|8888': 0.15547276664471474} expected to be of bytearray, bytes, float, int, or str type") in call handler 'report_load'
2021-04-15 01:04:37,002 - DEBUG - ServiceRegister - [EtcdSupport.py:214]: time.time()=1618419876.9994807, refresh service success: dispatcher_service: {"action":"set","node":{"key":"/services/dispatcher_service/127.0.0.1|9100","value":"","expiration":"2021-04-14T17:07:36.9454801Z","ttl":180,"modifiedIndex":33,"createdIndex":33},"prevNode":{"key":"/services/dispatcher_service/127.0.0.1|9100","value":"","expiration":"2021-04-14T17:04:41.3749301Z","ttl":5,"modifiedIndex":29,"createdIndex":29}}
, now_url: http://127.0.0.1:2381/v2/keys/services/dispatcher_service/127.0.0.1|9100
2021-04-15 01:04:37,006 - WARNING - TcpConn - [TcpConn.py:173]: the peer has performed an orderly shutdown (recv 0 byte).
2021-04-15 01:04:37,010 - WARNING - TcpConn - [TcpConn.py:173]: the peer has performed an orderly shutdown (recv 0 byte).
2021-04-15 01:04:37,017 - DEBUG - TcpServer - [TcpServer.py:175]: ('127.0.0.1', 1634) is connected !!!!
2021-04-15 01:04:37,035 - DEBUG - TcpServer - [TcpServer.py:175]: ('127.0.0.1', 1635) is connected !!!!
2021-04-15 01:04:37,042 - ERROR - RpcHandler - [RpcHandler.py:273]: Exception TypeError("Argument {'battle_0|127.0.0.1|8888': 0.4678727187625533} expected to be of bytearray, bytes, float, int, or str type") in call handler 'report_load'
2021-04-15 01:04:37,048 - ERROR - RpcHandler - [RpcHandler.py:273]: Exception TypeError("Argument {'battle_0|127.0.0.1|8888': 0.15631436226454518} expected to be of bytearray, bytes, float, int, or str type") in call handler 'report_load'
2021-04-15 01:04:37,052 - WARNING - TcpConn - [TcpConn.py:173]: the peer has performed an orderly shutdown (recv 0 byte).
2021-04-15 01:04:37,056 - WARNING - TcpConn - [TcpConn.py:173]: the peer has performed an orderly shutdown (recv 0 byte).
2021-04-15 01:04:37,065 - DEBUG - TcpServer - [TcpServer.py:175]: ('127.0.0.1', 1636) is connected !!!!
2021-04-15 01:04:37,081 - DEBUG - TcpServer - [TcpServer.py:175]: ('127.0.0.1', 1637) is connected !!!!
2021-04-15 01:04:37,089 - ERROR - RpcHandler - [RpcHandler.py:273]: Exception TypeError("Argument {'battle_0|127.0.0.1|8888': 0.15604597184429309} expected to be of bytearray, bytes, float, int, or str type") in call handler 'report_load'
2021-04-15 01:04:37,093 - WARNING - TcpConn - [TcpConn.py:173]: the peer has performed an orderly shutdown (recv 0 byte).
2021-04-15 01:04:37,098 - WARNING - TcpConn - [TcpConn.py:173]: the peer has performed an orderly shutdown (recv 0 byte).
2021-04-15 01:04:37,106 - DEBUG - TcpServer - [TcpServer.py:175]: ('127.0.0.1', 1638) is connected !!!!
2021-04-15 01:04:37,121 - DEBUG - TcpServer - [TcpServer.py:175]: ('127.0.0.1', 1639) is connected !!!!
2021-04-15 01:04:37,130 - ERROR - RpcHandler - [RpcHandler.py:273]: Exception TypeError("Argument {'battle_0|127.0.0.1|8888': 0.15575221575446402} expected to be of bytearray, bytes, float, int, or str type") in call handler 'report_load'
2021-04-15 01:04:37,135 - WARNING - TcpConn - [TcpConn.py:173]: the peer has performed an orderly shutdown (recv 0 byte).
2021-04-15 01:04:37,139 - WARNING - TcpConn - [TcpConn.py:173]: the peer has performed an orderly shutdown (recv 0 byte).
2021-04-15 01:04:37,147 - DEBUG - TcpServer - [TcpServer.py:175]: ('127.0.0.1', 1642) is connected !!!!
2021-04-15 01:04:37,163 - DEBUG - TcpServer - [TcpServer.py:175]: ('127.0.0.1', 1643) is connected !!!!
2021-04-15 01:04:37,172 - ERROR - RpcHandler - [RpcHandler.py:273]: Exception TypeError("Argument {'battle_0|127.0.0.1|8888': 0.31181063574392454} expected to be of bytearray, bytes, float, int, or str type") in call handler 'report_load'
2021-04-15 01:04:37,177 - ERROR - RpcHandler - [RpcHandler.py:273]: Exception TypeError("Argument {'battle_0|127.0.0.1|8888': 0.317160767522249} expected to be of bytearray, bytes, float, int, or str type") in call handler 'report_load'
2021-04-15 01:04:37,181 - WARNING - TcpConn - [TcpConn.py:173]: the peer has performed an orderly shutdown (recv 0 byte).
2021-04-15 01:04:37,185 - WARNING - TcpConn - [TcpConn.py:173]: the peer has performed an orderly shutdown (recv 0 byte).
2021-04-15 01:04:37,195 - DEBUG - TcpServer - [TcpServer.py:175]: ('127.0.0.1', 1644) is connected !!!!
2021-04-15 01:04:37,214 - DEBUG - TcpServer - [TcpServer.py:175]: ('127.0.0.1', 1645) is connected !!!!
2021-04-15 01:04:37,234 - ERROR - RpcHandler - [RpcHandler.py:273]: Exception TypeError("Argument {'battle_0|127.0.0.1|8888': 0.31704275724280107} expected to be of bytearray, bytes, float, int, or str type") in call handler 'report_load'
2021-04-15 01:04:37,238 - WARNING - TcpConn - [TcpConn.py:173]: the peer has performed an orderly shutdown (recv 0 byte).
2021-04-15 01:04:37,242 - WARNING - TcpConn - [TcpConn.py:173]: the peer has performed an orderly shutdown (recv 0 byte).
2021-04-15 01:04:37,249 - DEBUG - TcpServer - [TcpServer.py:175]: ('127.0.0.1', 1646) is connected !!!!
2021-04-15 01:04:37,265 - DEBUG - TcpServer - [TcpServer.py:175]: ('127.0.0.1', 1647) is connected !!!!
2021-04-15 01:04:37,272 - ERROR - RpcHandler - [RpcHandler.py:273]: Exception TypeError("Argument {'battle_0|127.0.0.1|8888': 0.1552129903723705} expected to be of bytearray, bytes, float, int, or str type") in call handler 'report_load'
2021-04-15 01:04:37,276 - WARNING - TcpConn - [TcpConn.py:173]: the peer has performed an orderly shutdown (recv 0 byte).
2021-04-15 01:04:37,280 - WARNING - TcpConn - [TcpConn.py:173]: the peer has performed an orderly shutdown (recv 0 byte).
2021-04-15 01:04:37,289 - DEBUG - TcpServer - [TcpServer.py:175]: ('127.0.0.1', 1650) is connected !!!!
2021-04-15 01:04:37,305 - DEBUG - TcpServer - [TcpServer.py:175]: ('127.0.0.1', 1651) is connected !!!!
2021-04-15 01:04:37,314 - ERROR - RpcHandler - [RpcHandler.py:273]: Exception TypeError("Argument {'battle_0|127.0.0.1|8888': 0.3112553953530795} expected to be of bytearray, bytes, float, int, or str type") in call handler 'report_load'
2021-04-15 01:04:37,320 - ERROR - RpcHandler - [RpcHandler.py:273]: Exception TypeError("Argument {'battle_0|127.0.0.1|8888': 0.31190448739573406} expected to be of bytearray, bytes, float, int, or str type") in call handler 'report_load'
2021-04-15 01:04:37,323 - WARNING - TcpConn - [TcpConn.py:173]: the peer has performed an orderly shutdown (recv 0 byte).
2021-04-15 01:04:37,327 - WARNING - TcpConn - [TcpConn.py:173]: the peer has performed an orderly shutdown (recv 0 byte).
2021-04-15 01:04:37,335 - DEBUG - TcpServer - [TcpServer.py:175]: ('127.0.0.1', 1652) is connected !!!!
2021-04-15 01:04:37,350 - DEBUG - TcpServer - [TcpServer.py:175]: ('127.0.0.1', 1653) is connected !!!!
2021-04-15 01:04:37,358 - ERROR - RpcHandler - [RpcHandler.py:273]: Exception TypeError("Argument {'battle_0|127.0.0.1|8888': 0.46697345354681774} expected to be of bytearray, bytes, float, int, or str type") in call handler 'report_load'
2021-04-15 01:04:37,362 - WARNING - TcpConn - [TcpConn.py:173]: the peer has performed an orderly shutdown (recv 0 byte).
2021-04-15 01:04:37,367 - WARNING - TcpConn - [TcpConn.py:173]: the peer has performed an orderly shutdown (recv 0 byte).
2021-04-15 01:04:37,379 - DEBUG - TcpServer - [TcpServer.py:175]: ('127.0.0.1', 1654) is connected !!!!
2021-04-15 01:04:37,396 - DEBUG - TcpServer - [TcpServer.py:175]: ('127.0.0.1', 1655) is connected !!!!
2021-04-15 01:04:37,405 - ERROR - RpcHandler - [RpcHandler.py:273]: Exception TypeError("Argument {'battle_0|127.0.0.1|8888': 0.15582995094647387} expected to be of bytearray, bytes, float, int, or str type") in call handler 'report_load'
2021-04-15 01:04:37,409 - WARNING - TcpConn - [TcpConn.py:173]: the peer has performed an orderly shutdown (recv 0 byte).
2021-04-15 01:04:37,413 - WARNING - TcpConn - [TcpConn.py:173]: the peer has performed an orderly shutdown (recv 0 byte).
2021-04-15 01:04:37,421 - DEBUG - TcpServer - [TcpServer.py:175]: ('127.0.0.1', 1656) is connected !!!!
2021-04-15 01:04:37,437 - DEBUG - TcpServer - [TcpServer.py:175]: ('127.0.0.1', 1657) is connected !!!!
2021-04-15 01:04:37,445 - ERROR - RpcHandler - [RpcHandler.py:273]: Exception TypeError("Argument {'battle_0|127.0.0.1|8888': 0.46970523275938214} expected to be of bytearray, bytes, float, int, or str type") in call handler 'report_load'
2021-04-15 01:04:37,450 - ERROR - RpcHandler - [RpcHandler.py:273]: Exception TypeError("Argument {'battle_0|127.0.0.1|8888': 0.15548696797802647} expected to be of bytearray, bytes, float, int, or str type") in call handler 'report_load'
2021-04-15 01:04:37,454 - WARNING - TcpConn - [TcpConn.py:173]: the peer has performed an orderly shutdown (recv 0 byte).
2021-04-15 01:04:37,459 - WARNING - TcpConn - [TcpConn.py:173]: the peer has performed an orderly shutdown (recv 0 byte).
2021-04-15 01:04:37,468 - DEBUG - TcpServer - [TcpServer.py:175]: ('127.0.0.1', 1658) is connected !!!!
2021-04-15 01:04:37,483 - DEBUG - TcpServer - [TcpServer.py:175]: ('127.0.0.1', 1659) is connected !!!!
2021-04-15 01:04:37,491 - ERROR - RpcHandler - [RpcHandler.py:273]: Exception TypeError("Argument {'battle_0|127.0.0.1|8888': 0.15554830325937968} expected to be of bytearray, bytes, float, int, or str type") in call handler 'report_load'
2021-04-15 01:04:37,497 - WARNING - TcpConn - [TcpConn.py:173]: the peer has performed an orderly shutdown (recv 0 byte).
2021-04-15 01:04:37,501 - WARNING - TcpConn - [TcpConn.py:173]: the peer has performed an orderly shutdown (recv 0 byte).
2021-04-15 01:04:37,510 - DEBUG - TcpServer - [TcpServer.py:175]: ('127.0.0.1', 1660) is connected !!!!
2021-04-15 01:04:37,523 - DEBUG - TcpServer - [TcpServer.py:175]: ('127.0.0.1', 1661) is connected !!!!
2021-04-15 01:04:37,529 - ERROR - RpcHandler - [RpcHandler.py:273]: Exception TypeError("Argument {'battle_0|127.0.0.1|8888': 0.15742096343954812} expected to be of bytearray, bytes, float, int, or str type") in call handler 'report_load'
2021-04-15 01:04:37,534 - WARNING - TcpConn - [TcpConn.py:173]: the peer has performed an orderly shutdown (recv 0 byte).
2021-04-15 01:04:38,094 - ERROR - RpcHandler - [RpcHandler.py:273]: Exception TypeError("Argument {'battle_0|127.0.0.1|8888': 0.31274184601178484} expected to be of bytearray, bytes, float, int, or str type") in call handler 'report_load'
2021-04-15 01:04:44,086 - ERROR - RpcHandler - [RpcHandler.py:273]: Exception TypeError("Argument {'battle_0|127.0.0.1|8888': 0.1553208825722367} expected to be of bytearray, bytes, float, int, or str type") in call handler 'report_load'
2021-04-15 01:04:44,364 - WARNING - TcpConn - [TcpConn.py:173]: the peer has performed an orderly shutdown (recv 0 byte).
2021-04-15 01:04:44,375 - DEBUG - TcpServer - [TcpServer.py:175]: ('127.0.0.1', 1666) is connected !!!!
2021-04-15 01:04:50,085 - ERROR - RpcHandler - [RpcHandler.py:273]: Exception TypeError("Argument {'battle_0|127.0.0.1|8888': 0.15812771534694914} expected to be of bytearray, bytes, float, int, or str type") in call handler 'report_load'
2021-04-15 01:04:52,369 - WARNING - TcpConn - [TcpConn.py:173]: the peer has performed an orderly shutdown (recv 0 byte).
2021-04-15 01:04:52,382 - DEBUG - TcpServer - [TcpServer.py:175]: ('127.0.0.1', 1667) is connected !!!!
2021-04-15 01:04:56,097 - ERROR - RpcHandler - [RpcHandler.py:273]: Exception TypeError("Argument {'battle_0|127.0.0.1|8888': 0.0} expected to be of bytearray, bytes, float, int, or str type") in call handler 'report_load'
2021-04-15 01:05:00,366 - WARNING - TcpConn - [TcpConn.py:173]: the peer has performed an orderly shutdown (recv 0 byte).
2021-04-15 01:05:00,379 - DEBUG - TcpServer - [TcpServer.py:175]: ('127.0.0.1', 1668) is connected !!!!
2021-04-15 01:05:02,112 - ERROR - RpcHandler - [RpcHandler.py:273]: Exception TypeError("Argument {'battle_0|127.0.0.1|8888': 0.0} expected to be of bytearray, bytes, float, int, or str type") in call handler 'report_load'
2021-04-15 01:05:08,106 - ERROR - RpcHandler - [RpcHandler.py:273]: Exception TypeError("Argument {'battle_0|127.0.0.1|8888': 0.3138371946134392} expected to be of bytearray, bytes, float, int, or str type") in call handler 'report_load'
2021-04-15 01:05:08,367 - WARNING - TcpConn - [TcpConn.py:173]: the peer has performed an orderly shutdown (recv 0 byte).
2021-04-15 01:05:08,377 - DEBUG - TcpServer - [TcpServer.py:175]: ('127.0.0.1', 1670) is connected !!!!
2021-04-15 01:05:14,105 - ERROR - RpcHandler - [RpcHandler.py:273]: Exception TypeError("Argument {'battle_0|127.0.0.1|8888': 0.3142177298948517} expected to be of bytearray, bytes, float, int, or str type") in call handler 'report_load'
2021-04-15 01:05:16,378 - WARNING - TcpConn - [TcpConn.py:173]: the peer has performed an orderly shutdown (recv 0 byte).
2021-04-15 01:05:16,390 - DEBUG - TcpServer - [TcpServer.py:175]: ('127.0.0.1', 1671) is connected !!!!
2021-04-15 01:05:20,104 - ERROR - RpcHandler - [RpcHandler.py:273]: Exception TypeError("Argument {'battle_0|127.0.0.1|8888': 0.3138459008826952} expected to be of bytearray, bytes, float, int, or str type") in call handler 'report_load'
2021-04-15 01:05:24,365 - WARNING - TcpConn - [TcpConn.py:173]: the peer has performed an orderly shutdown (recv 0 byte).
2021-04-15 01:05:24,377 - DEBUG - TcpServer - [TcpServer.py:175]: ('127.0.0.1', 1673) is connected !!!!
2021-04-15 01:05:26,111 - ERROR - RpcHandler - [RpcHandler.py:273]: Exception TypeError("Argument {'battle_0|127.0.0.1|8888': 0.6287155827837626} expected to be of bytearray, bytes, float, int, or str type") in call handler 'report_load'
2021-04-15 01:05:32,111 - ERROR - RpcHandler - [RpcHandler.py:273]: Exception TypeError("Argument {'battle_0|127.0.0.1|8888': 0.3149585546812243} expected to be of bytearray, bytes, float, int, or str type") in call handler 'report_load'
2021-04-15 01:05:32,384 - WARNING - TcpConn - [TcpConn.py:173]: heartbeat timeout
2021-04-15 01:05:32,397 - DEBUG - TcpServer - [TcpServer.py:175]: ('127.0.0.1', 1674) is connected !!!!
2021-04-15 01:05:38,110 - ERROR - RpcHandler - [RpcHandler.py:273]: Exception TypeError("Argument {'battle_0|127.0.0.1|8888': 0.3142301228182477} expected to be of bytearray, bytes, float, int, or str type") in call handler 'report_load'
2021-04-15 01:05:38,857 - DEBUG - ServiceFinder - [EtcdSupport.py:475]: etcd watch timeout, rest watch index 31 -> 33
2021-04-15 01:05:40,373 - WARNING - TcpConn - [TcpConn.py:173]: the peer has performed an orderly shutdown (recv 0 byte).
2021-04-15 01:05:40,384 - DEBUG - TcpServer - [TcpServer.py:175]: ('127.0.0.1', 1677) is connected !!!!
2021-04-15 01:05:44,104 - ERROR - RpcHandler - [RpcHandler.py:273]: Exception TypeError("Argument {'battle_0|127.0.0.1|8888': 0.15725355287787487} expected to be of bytearray, bytes, float, int, or str type") in call handler 'report_load'
2021-04-15 01:05:48,412 - WARNING - TcpConn - [TcpConn.py:173]: the peer has performed an orderly shutdown (recv 0 byte).
2021-04-15 01:05:48,423 - DEBUG - TcpServer - [TcpServer.py:175]: ('127.0.0.1', 1678) is connected !!!!
2021-04-15 01:05:50,107 - ERROR - RpcHandler - [RpcHandler.py:273]: Exception TypeError("Argument {'battle_0|127.0.0.1|8888': 0.3139631862066012} expected to be of bytearray, bytes, float, int, or str type") in call handler 'report_load'
2021-04-15 01:05:56,102 - ERROR - RpcHandler - [RpcHandler.py:273]: Exception TypeError("Argument {'battle_0|127.0.0.1|8888': 0.0} expected to be of bytearray, bytes, float, int, or str type") in call handler 'report_load'
2021-04-15 01:05:56,389 - WARNING - TcpConn - [TcpConn.py:173]: heartbeat timeout
2021-04-15 01:05:56,403 - DEBUG - TcpServer - [TcpServer.py:175]: ('127.0.0.1', 1679) is connected !!!!
2021-04-15 01:06:02,104 - ERROR - RpcHandler - [RpcHandler.py:273]: Exception TypeError("Argument {'battle_0|127.0.0.1|8888': 0.0} expected to be of bytearray, bytes, float, int, or str type") in call handler 'report_load'
2021-04-15 01:06:04,405 - WARNING - TcpConn - [TcpConn.py:173]: the peer has performed an orderly shutdown (recv 0 byte).
2021-04-15 01:06:04,417 - DEBUG - TcpServer - [TcpServer.py:175]: ('127.0.0.1', 1680) is connected !!!!
2021-04-15 01:06:08,104 - ERROR - RpcHandler - [RpcHandler.py:273]: Exception TypeError("Argument {'battle_0|127.0.0.1|8888': 0.3139314353434248} expected to be of bytearray, bytes, float, int, or str type") in call handler 'report_load'
2021-04-15 01:06:09,266 - DEBUG - ServerEntity.LoadCollector - [ServerEntity.py:25]: __init__ create entity LoadCollector with id 60772101d164121fb4e5d7e8 mem_id=2410307612576
2021-04-15 01:06:09,268 - DEBUG - server.EntityManager - [EntityManager.py:139]: addentity  entity id  60772101d164121fb4e5d7e8 
2021-04-15 01:06:09,283 - DEBUG - ServiceNode - [EtcdSupport.py:533]: we have create ServiceFinder
2021-04-15 01:06:09,290 - DEBUG - ServiceFinder - [EtcdSupport.py:352]: _init_info, now_url: http://127.0.0.1:2379/v2/keys?recursive=true
2021-04-15 01:06:09,294 - DEBUG - ServiceRegister - [EtcdSupport.py:155]: _do_regist: now_url: http://127.0.0.1:2383/v2/keys/services/dispatcher_service/127.0.0.1|9100
2021-04-15 01:06:09,306 - DEBUG - TcpServer - [TcpServer.py:189]: Server on ('127.0.0.1', 9100)
2021-04-15 01:06:09,325 - DEBUG - ServiceFinder - [EtcdSupport.py:323]: add service node info--> dispatcher_service: ('127.0.0.1', 9100)
2021-04-15 01:06:09,327 - DEBUG - ServiceFinder - [EtcdSupport.py:323]: add service node info--> battle_server: ('127.0.0.1', 8888)
2021-04-15 01:06:09,332 - DEBUG - ServiceFinder - [EtcdSupport.py:277]: init service info from etcd success, will going to watch, at etcd index -> 34
2021-04-15 01:06:09,340 - DEBUG - ServiceRegister - [EtcdSupport.py:163]: regist service : dispatcher_service success, {"action":"set","node":{"key":"/services/dispatcher_service/127.0.0.1|9100","value":"","expiration":"2021-04-14T17:09:09.3218593Z","ttl":180,"modifiedIndex":35,"createdIndex":35},"prevNode":{"key":"/services/dispatcher_service/127.0.0.1|9100","value":"","expiration":"2021-04-14T17:07:36.9454801Z","ttl":88,"modifiedIndex":33,"createdIndex":33}}

2021-04-15 01:06:09,356 - DEBUG - ServiceFinder - [EtcdSupport.py:422]: recv watch set service node info--> dispatcher_service: ('127.0.0.1', 9100) - [35]
2021-04-15 01:06:09,357 - DEBUG - ServiceFinder - [EtcdSupport.py:299]: duplicate service info  -> dispatcher_service:('127.0.0.1', 9100)
2021-04-15 01:06:09,723 - DEBUG - TcpServer - [TcpServer.py:175]: ('127.0.0.1', 1681) is connected !!!!
2021-04-15 01:06:09,737 - DEBUG - TcpServer - [TcpServer.py:175]: ('127.0.0.1', 1682) is connected !!!!
2021-04-15 01:06:10,165 - WARNING - TcpConn - [TcpConn.py:173]: connection is closed by error: [WinError 64] The specified network name is no longer available
2021-04-15 01:06:10,167 - WARNING - TcpConn - [TcpConn.py:173]: connection is closed by error: [WinError 64] The specified network name is no longer available
2021-04-15 01:06:10,984 - DEBUG - ServiceFinder - [EtcdSupport.py:422]: recv watch set service node info--> battle_server: ('127.0.0.1', 8888) - [36]
2021-04-15 01:06:10,985 - DEBUG - ServiceFinder - [EtcdSupport.py:299]: duplicate service info  -> battle_server:('127.0.0.1', 8888)
2021-04-15 01:06:16,957 - DEBUG - TcpServer - [TcpServer.py:175]: ('127.0.0.1', 1700) is connected !!!!
2021-04-15 01:07:00,873 - DEBUG - TcpServer - [TcpServer.py:175]: ('127.0.0.1', 1705) is connected !!!!
2021-04-15 01:07:11,994 - DEBUG - ServiceFinder - [EtcdSupport.py:475]: etcd watch timeout, rest watch index 36 -> 36
2021-04-15 01:07:24,925 - DEBUG - ServerEntity.LoadCollector - [ServerEntity.py:25]: __init__ create entity LoadCollector with id 6077214cd1641213dc1f203c mem_id=2467434882432
2021-04-15 01:07:24,927 - DEBUG - server.EntityManager - [EntityManager.py:139]: addentity  entity id  6077214cd1641213dc1f203c 
2021-04-15 01:07:24,937 - DEBUG - ServiceNode - [EtcdSupport.py:533]: we have create ServiceFinder
2021-04-15 01:07:24,942 - DEBUG - ServiceFinder - [EtcdSupport.py:352]: _init_info, now_url: http://127.0.0.1:2381/v2/keys?recursive=true
2021-04-15 01:07:24,946 - DEBUG - ServiceRegister - [EtcdSupport.py:155]: _do_regist: now_url: http://127.0.0.1:2383/v2/keys/services/dispatcher_service/127.0.0.1|9100
2021-04-15 01:07:24,954 - DEBUG - TcpServer - [TcpServer.py:189]: Server on ('127.0.0.1', 9100)
2021-04-15 01:07:24,965 - DEBUG - ServiceFinder - [EtcdSupport.py:323]: add service node info--> dispatcher_service: ('127.0.0.1', 9100)
2021-04-15 01:07:24,966 - DEBUG - ServiceFinder - [EtcdSupport.py:323]: add service node info--> battle_server: ('127.0.0.1', 8888)
2021-04-15 01:07:24,968 - DEBUG - ServiceFinder - [EtcdSupport.py:277]: init service info from etcd success, will going to watch, at etcd index -> 36
2021-04-15 01:07:24,973 - DEBUG - ServiceRegister - [EtcdSupport.py:163]: regist service : dispatcher_service success, {"action":"set","node":{"key":"/services/dispatcher_service/127.0.0.1|9100","value":"","expiration":"2021-04-14T17:10:24.9627708Z","ttl":180,"modifiedIndex":37,"createdIndex":37},"prevNode":{"key":"/services/dispatcher_service/127.0.0.1|9100","value":"","expiration":"2021-04-14T17:09:09.3218593Z","ttl":105,"modifiedIndex":35,"createdIndex":35}}

2021-04-15 01:07:24,978 - DEBUG - ServiceFinder - [EtcdSupport.py:422]: recv watch set service node info--> dispatcher_service: ('127.0.0.1', 9100) - [37]
2021-04-15 01:07:24,980 - DEBUG - ServiceFinder - [EtcdSupport.py:299]: duplicate service info  -> dispatcher_service:('127.0.0.1', 9100)
2021-04-15 01:07:27,802 - DEBUG - TcpServer - [TcpServer.py:175]: ('127.0.0.1', 1718) is connected !!!!
2021-04-15 01:07:27,805 - ERROR - RpcHandler - [RpcHandler.py:273]: Exception TypeError("'_asyncio.Future' object is not subscriptable") in call handler 'pick_lowest_load_service_addr'
2021-04-15 01:07:27,807 - CRITICAL - RpcHandler - [RpcHandler.py:274]: on_traceback, type:<class 'TypeError'>, value:'_asyncio.Future' object is not subscriptable, traceback:<class 'TypeError'>
'_asyncio.Future' object is not subscriptable
  File "C:\Users\b\Documents\github\realtime-server\pycharm2020.1.3\script\RpcHandler.py", line 267, in handle_rpc
    locals={'self': <RpcHandler.RpcHandler object at 0x0000023E7EAAD040>, 'rpc_msg': b'\x96\x01\x01\xadLoadCollector\xbdpick_lowest_load_service_addr\x91\xadbattle_server\x80', '_rpc_msg_tuple': (1, 1, 'LoadCollector', 'pick_lowest_load_service_addr', ('battle_server',), {}), '_rpc_type': 1, '_entity_type_str': 'LoadCollector', '_method_name': 'pick_lowest_load_service_addr', '_method_args': ('battle_server',), '_method_kwargs': {}, '_method': <bound method LoadCollector.pick_lowest_load_service_addr of <server_entity.LoadCollector.LoadCollector object at 0x0000023E7E946580>>, 'e': TypeError("'_asyncio.Future' object is not subscriptable")}
  File "C:\Users\b\Documents\github\realtime-server\pycharm2020.1.3\script\RpcHandler.py", line 229, in handle_request_notify_rpc
    locals={'_method': <bound method LoadCollector.pick_lowest_load_service_addr of <server_entity.LoadCollector.LoadCollector object at 0x0000023E7E946580>>, '_method_name': 'pick_lowest_load_service_addr', '_method_args': ('battle_server',), '_method_kwargs': {}, '_is_rpc_func': True, '_method_res': <coroutine object LoadCollector.pick_lowest_load_service_addr at 0x0000023E7EB6BBC0>}
  File "C:\Users\b\Documents\github\realtime-server\pycharm2020.1.3\script\server_entity\LoadCollector.py", line 53, in pick_lowest_load_service_addr
    locals={'self': <server_entity.LoadCollector.LoadCollector object at 0x0000023E7E946580>, 'etcd_tag': 'battle_server', '_res_list': <Future pending created at C:\Program Files\Python38\lib\asyncio\base_events.py:422>, '_ret': None}
2021-04-15 01:07:27,831 - WARNING - TcpConn - [TcpConn.py:173]: connection is closed by error: [WinError 64] The specified network name is no longer available
2021-04-15 01:08:30,978 - DEBUG - ServiceFinder - [EtcdSupport.py:475]: etcd watch timeout, rest watch index 37 -> 37
2021-04-15 01:08:35,554 - DEBUG - ServerEntity.LoadCollector - [ServerEntity.py:25]: __init__ create entity LoadCollector with id 60772193d1641208dcb73d3b mem_id=2355390211360
2021-04-15 01:08:35,556 - DEBUG - server.EntityManager - [EntityManager.py:139]: addentity  entity id  60772193d1641208dcb73d3b 
2021-04-15 01:08:35,566 - DEBUG - ServiceNode - [EtcdSupport.py:533]: we have create ServiceFinder
2021-04-15 01:08:35,572 - DEBUG - ServiceFinder - [EtcdSupport.py:352]: _init_info, now_url: http://127.0.0.1:2379/v2/keys?recursive=true
2021-04-15 01:08:35,576 - DEBUG - ServiceRegister - [EtcdSupport.py:155]: _do_regist: now_url: http://127.0.0.1:2379/v2/keys/services/dispatcher_service/127.0.0.1|9100
2021-04-15 01:08:35,585 - DEBUG - TcpServer - [TcpServer.py:189]: Server on ('127.0.0.1', 9100)
2021-04-15 01:08:35,596 - DEBUG - ServiceFinder - [EtcdSupport.py:323]: add service node info--> dispatcher_service: ('127.0.0.1', 9100)
2021-04-15 01:08:35,597 - DEBUG - ServiceFinder - [EtcdSupport.py:323]: add service node info--> battle_server: ('127.0.0.1', 8888)
2021-04-15 01:08:35,599 - DEBUG - ServiceFinder - [EtcdSupport.py:277]: init service info from etcd success, will going to watch, at etcd index -> 37
2021-04-15 01:08:35,604 - DEBUG - ServiceRegister - [EtcdSupport.py:163]: regist service : dispatcher_service success, {"action":"set","node":{"key":"/services/dispatcher_service/127.0.0.1|9100","value":"","expiration":"2021-04-14T17:11:35.5935046Z","ttl":180,"modifiedIndex":38,"createdIndex":38},"prevNode":{"key":"/services/dispatcher_service/127.0.0.1|9100","value":"","expiration":"2021-04-14T17:10:24.9627708Z","ttl":110,"modifiedIndex":37,"createdIndex":37}}

2021-04-15 01:08:35,610 - DEBUG - ServiceFinder - [EtcdSupport.py:422]: recv watch set service node info--> dispatcher_service: ('127.0.0.1', 9100) - [38]
2021-04-15 01:08:35,611 - DEBUG - ServiceFinder - [EtcdSupport.py:299]: duplicate service info  -> dispatcher_service:('127.0.0.1', 9100)
2021-04-15 01:08:37,716 - DEBUG - TcpServer - [TcpServer.py:175]: ('127.0.0.1', 1770) is connected !!!!
2021-04-15 01:08:39,748 - WARNING - TcpConn - [TcpConn.py:173]: connection is closed by error: [WinError 64] The specified network name is no longer available
