2021-07-04 22:06:48,419 - WARNING - RudpConn - ["C:\Users\b\Documents\github\realtime-server\pycharm2020.1.3\script\RudpConn.py:69"]: try reconnect rudp: ('127.0.0.1', 9100) ... 1
2021-07-04 22:06:49,014 - WARNING - RudpConn - ["C:\Users\b\Documents\github\realtime-server\pycharm2020.1.3\script\RudpConn.py:69"]: try reconnect rudp: ('127.0.0.1', 9100) ... 2
2021-07-04 22:06:49,634 - WARNING - RudpConn - ["C:\Users\b\Documents\github\realtime-server\pycharm2020.1.3\script\RudpConn.py:69"]: try reconnect rudp: ('127.0.0.1', 9100) ... 3
2021-07-04 22:06:50,260 - WARNING - RudpConn - ["C:\Users\b\Documents\github\realtime-server\pycharm2020.1.3\script\RudpConn.py:69"]: try reconnect rudp: ('127.0.0.1', 9100) ... 4
2021-07-04 22:06:50,881 - WARNING - RudpConn - ["C:\Users\b\Documents\github\realtime-server\pycharm2020.1.3\script\RudpConn.py:69"]: try reconnect rudp: ('127.0.0.1', 9100) ... 5
2021-07-04 22:06:51,504 - WARNING - RudpConn - ["C:\Users\b\Documents\github\realtime-server\pycharm2020.1.3\script\RudpConn.py:69"]: try reconnect rudp: ('127.0.0.1', 9100) ... 6
2021-07-04 22:06:51,508 - ERROR - RudpConn - ["C:\Users\b\Documents\github\realtime-server\pycharm2020.1.3\script\RudpConn.py:78"]: try 6 times , still can't connect rudp remote addr: ('127.0.0.1', 9100)
2021-07-04 22:12:09,894 - INFO - RudpProtocol - [ConnMgr.py:130]: ('127.0.0.1', 9100) is connected !!!!
2021-07-04 22:24:38,179 - WARNING - RudpConn - ["C:\Users\b\Documents\github\realtime-server\pycharm2020.1.3\script\RudpConn.py:69"]: try reconnect rudp: ('127.0.0.1', 9102) ... 1
2021-07-04 22:24:38,799 - WARNING - RudpConn - ["C:\Users\b\Documents\github\realtime-server\pycharm2020.1.3\script\RudpConn.py:69"]: try reconnect rudp: ('127.0.0.1', 9102) ... 2
2021-07-04 22:24:39,423 - WARNING - RudpConn - ["C:\Users\b\Documents\github\realtime-server\pycharm2020.1.3\script\RudpConn.py:69"]: try reconnect rudp: ('127.0.0.1', 9102) ... 3
2021-07-04 22:24:40,031 - WARNING - RudpConn - ["C:\Users\b\Documents\github\realtime-server\pycharm2020.1.3\script\RudpConn.py:69"]: try reconnect rudp: ('127.0.0.1', 9102) ... 4
2021-07-04 22:24:40,651 - WARNING - RudpConn - ["C:\Users\b\Documents\github\realtime-server\pycharm2020.1.3\script\RudpConn.py:69"]: try reconnect rudp: ('127.0.0.1', 9102) ... 5
2021-07-04 22:24:41,260 - WARNING - RudpConn - ["C:\Users\b\Documents\github\realtime-server\pycharm2020.1.3\script\RudpConn.py:69"]: try reconnect rudp: ('127.0.0.1', 9102) ... 6
2021-07-04 22:24:41,261 - ERROR - RudpConn - ["C:\Users\b\Documents\github\realtime-server\pycharm2020.1.3\script\RudpConn.py:78"]: try 6 times , still can't connect rudp remote addr: ('127.0.0.1', 9102)
2021-07-04 22:25:27,145 - INFO - RudpProtocol - [ConnMgr.py:130]: ('127.0.0.1', 9100) is connected !!!!
2021-07-04 22:25:27,182 - WARNING - RpcHandler - ["C:\Users\b\Documents\github\realtime-server\pycharm2020.1.3\script\RpcHandler.py:79"]: self.rpc_handler_id=b'`\xe1\xc4\xd7\xb3\xa0\xf4M\x1d\x81\x8d\x8d' RpcHandler Destroy!
2021-07-04 22:25:27,183 - DEBUG - __main__ - [RudpClient.py:69]: lobby server info: ('gate_0', '127.0.0.1', 9201)
2021-07-04 22:25:27,185 - INFO - ServerEntity.Avatar - [ServerEntity.py:25]: __init__ create entity Avatar with id 60e1c4d7b3a0f44d1d818d8e mem_id=2694645559696
2021-07-04 22:25:27,187 - INFO - server.EntityManager - [EntityManager.py:139]: addentity  entity id  60e1c4d7b3a0f44d1d818d8e 
2021-07-04 22:25:27,196 - INFO - RudpProtocol - [ConnMgr.py:130]: ('127.0.0.1', 9201) is connected !!!!
