2021-07-05 01:22:46,529 - DEBUG - RpcHandler - [RpcHandler.py:218]: _handle_create_conn: addr=('127.0.0.1', 9100)
2021-07-05 01:22:48,600 - ERROR - TcpConn - ["C:\Users\b\Documents\github\realtime-server\pycharm2020.1.3\script\TcpConn.py:54"]: [WinError 1225] The remote computer refused the network connection
2021-07-05 01:22:49,211 - WARNING - TcpConn - ["C:\Users\b\Documents\github\realtime-server\pycharm2020.1.3\script\TcpConn.py:57"]: try reconnect tcp: ('127.0.0.1', 9100) ... 1
2021-07-05 01:22:51,252 - ERROR - TcpConn - ["C:\Users\b\Documents\github\realtime-server\pycharm2020.1.3\script\TcpConn.py:54"]: [WinError 1225] The remote computer refused the network connection
2021-07-05 01:22:51,859 - WARNING - TcpConn - ["C:\Users\b\Documents\github\realtime-server\pycharm2020.1.3\script\TcpConn.py:57"]: try reconnect tcp: ('127.0.0.1', 9100) ... 2
2021-07-05 01:22:53,885 - ERROR - TcpConn - ["C:\Users\b\Documents\github\realtime-server\pycharm2020.1.3\script\TcpConn.py:54"]: [WinError 1225] The remote computer refused the network connection
2021-07-05 01:22:54,493 - WARNING - TcpConn - ["C:\Users\b\Documents\github\realtime-server\pycharm2020.1.3\script\TcpConn.py:57"]: try reconnect tcp: ('127.0.0.1', 9100) ... 3
2021-07-05 01:22:56,543 - ERROR - TcpConn - ["C:\Users\b\Documents\github\realtime-server\pycharm2020.1.3\script\TcpConn.py:54"]: [WinError 1225] The remote computer refused the network connection
2021-07-05 01:22:57,145 - WARNING - TcpConn - ["C:\Users\b\Documents\github\realtime-server\pycharm2020.1.3\script\TcpConn.py:57"]: try reconnect tcp: ('127.0.0.1', 9100) ... 4
2021-07-05 01:22:59,185 - ERROR - TcpConn - ["C:\Users\b\Documents\github\realtime-server\pycharm2020.1.3\script\TcpConn.py:54"]: [WinError 1225] The remote computer refused the network connection
2021-07-05 01:22:59,778 - WARNING - TcpConn - ["C:\Users\b\Documents\github\realtime-server\pycharm2020.1.3\script\TcpConn.py:57"]: try reconnect tcp: ('127.0.0.1', 9100) ... 5
2021-07-05 01:23:01,827 - ERROR - TcpConn - ["C:\Users\b\Documents\github\realtime-server\pycharm2020.1.3\script\TcpConn.py:54"]: [WinError 1225] The remote computer refused the network connection
2021-07-05 01:23:02,437 - WARNING - TcpConn - ["C:\Users\b\Documents\github\realtime-server\pycharm2020.1.3\script\TcpConn.py:57"]: try reconnect tcp: ('127.0.0.1', 9100) ... 6
2021-07-05 01:23:02,439 - ERROR - TcpConn - ["C:\Users\b\Documents\github\realtime-server\pycharm2020.1.3\script\TcpConn.py:65"]: try 6 times , still can't connect tcp remote addr: ('127.0.0.1', 9100)
2021-07-05 01:23:52,136 - DEBUG - RpcHandler - [RpcHandler.py:218]: _handle_create_conn: addr=('127.0.0.1', 9100)
2021-07-05 01:23:54,214 - ERROR - TcpConn - ["C:\Users\b\Documents\github\realtime-server\pycharm2020.1.3\script\TcpConn.py:54"]: [WinError 1225] The remote computer refused the network connection
2021-07-05 01:23:54,823 - WARNING - TcpConn - ["C:\Users\b\Documents\github\realtime-server\pycharm2020.1.3\script\TcpConn.py:57"]: try reconnect tcp: ('127.0.0.1', 9100) ... 1
2021-07-05 01:23:56,872 - ERROR - TcpConn - ["C:\Users\b\Documents\github\realtime-server\pycharm2020.1.3\script\TcpConn.py:54"]: [WinError 1225] The remote computer refused the network connection
2021-07-05 01:23:57,480 - WARNING - TcpConn - ["C:\Users\b\Documents\github\realtime-server\pycharm2020.1.3\script\TcpConn.py:57"]: try reconnect tcp: ('127.0.0.1', 9100) ... 2
2021-07-05 01:23:59,519 - ERROR - TcpConn - ["C:\Users\b\Documents\github\realtime-server\pycharm2020.1.3\script\TcpConn.py:54"]: [WinError 1225] The remote computer refused the network connection
2021-07-05 01:24:00,127 - WARNING - TcpConn - ["C:\Users\b\Documents\github\realtime-server\pycharm2020.1.3\script\TcpConn.py:57"]: try reconnect tcp: ('127.0.0.1', 9100) ... 3
2021-07-05 01:24:02,181 - ERROR - TcpConn - ["C:\Users\b\Documents\github\realtime-server\pycharm2020.1.3\script\TcpConn.py:54"]: [WinError 1225] The remote computer refused the network connection
2021-07-05 01:24:02,788 - WARNING - TcpConn - ["C:\Users\b\Documents\github\realtime-server\pycharm2020.1.3\script\TcpConn.py:57"]: try reconnect tcp: ('127.0.0.1', 9100) ... 4
2021-07-05 01:24:04,839 - ERROR - TcpConn - ["C:\Users\b\Documents\github\realtime-server\pycharm2020.1.3\script\TcpConn.py:54"]: [WinError 1225] The remote computer refused the network connection
2021-07-05 01:24:05,445 - WARNING - TcpConn - ["C:\Users\b\Documents\github\realtime-server\pycharm2020.1.3\script\TcpConn.py:57"]: try reconnect tcp: ('127.0.0.1', 9100) ... 5
2021-07-05 01:24:07,471 - ERROR - TcpConn - ["C:\Users\b\Documents\github\realtime-server\pycharm2020.1.3\script\TcpConn.py:54"]: [WinError 1225] The remote computer refused the network connection
2021-07-05 01:24:08,074 - WARNING - TcpConn - ["C:\Users\b\Documents\github\realtime-server\pycharm2020.1.3\script\TcpConn.py:57"]: try reconnect tcp: ('127.0.0.1', 9100) ... 6
2021-07-05 01:24:08,075 - ERROR - TcpConn - ["C:\Users\b\Documents\github\realtime-server\pycharm2020.1.3\script\TcpConn.py:65"]: try 6 times , still can't connect tcp remote addr: ('127.0.0.1', 9100)
2021-07-05 01:24:25,136 - DEBUG - RpcHandler - [RpcHandler.py:218]: _handle_create_conn: addr=('127.0.0.1', 9100)
2021-07-05 01:25:16,686 - DEBUG - RpcHandler - [RpcHandler.py:218]: _handle_create_conn: addr=('127.0.0.1', 9100)
2021-07-05 01:25:16,700 - INFO - RudpProtocol - [ConnMgr.py:131]: RUDP ROLE_TYPE_ACTIVE peer_addr=('127.0.0.1', 9100) is connected !!!!
2021-07-05 01:25:16,743 - DEBUG - __main__ - [RudpClient.py:69]: lobby server info: ('gate_0', '127.0.0.1', 9201)
2021-07-05 01:25:16,745 - INFO - ServerEntity.Avatar - [ServerEntity.py:25]: __init__ create entity Avatar with id 60e1eefc9248d00db60f4a69 mem_id=1575171596928
2021-07-05 01:25:16,746 - INFO - server.EntityManager - [EntityManager.py:139]: addentity  entity id  60e1eefc9248d00db60f4a69 
2021-07-05 01:25:16,754 - INFO - RudpProtocol - [ConnMgr.py:131]: RUDP ROLE_TYPE_ACTIVE peer_addr=('127.0.0.1', 9201) is connected !!!!
2021-07-05 01:30:43,317 - DEBUG - RpcHandler - [RpcHandler.py:218]: _handle_create_conn: addr=('127.0.0.1', 9100)
2021-07-05 01:30:43,327 - INFO - RudpProtocol - [ConnMgr.py:131]: RUDP ROLE_TYPE_ACTIVE peer_addr=('127.0.0.1', 9100) is connected !!!!
2021-07-05 01:30:43,348 - DEBUG - __main__ - [RudpClient.py:69]: lobby server info: ('gate_0', '127.0.0.1', 9201)
2021-07-05 01:30:43,350 - INFO - ServerEntity.Avatar - [ServerEntity.py:25]: __init__ create entity Avatar with id 60e1f043b3313c7a15ccf491 mem_id=2073719735248
2021-07-05 01:30:43,351 - INFO - server.EntityManager - [EntityManager.py:139]: addentity  entity id  60e1f043b3313c7a15ccf491 
2021-07-05 01:30:43,361 - INFO - RudpProtocol - [ConnMgr.py:131]: RUDP ROLE_TYPE_ACTIVE peer_addr=('127.0.0.1', 9201) is connected !!!!
2021-07-05 01:32:07,070 - DEBUG - RpcHandler - [RpcHandler.py:218]: _handle_create_conn: addr=('127.0.0.1', 9100)
2021-07-05 01:32:07,079 - INFO - RudpProtocol - [ConnMgr.py:131]: RUDP ROLE_TYPE_ACTIVE peer_addr=('127.0.0.1', 9100) is connected !!!!
2021-07-05 01:32:07,113 - DEBUG - __main__ - [RudpClient.py:69]: lobby server info: ('gate_2', '127.0.0.1', 9203)
2021-07-05 01:32:07,114 - INFO - ServerEntity.Avatar - [ServerEntity.py:25]: __init__ create entity Avatar with id 60e1f0970cf375abff15a505 mem_id=2883088352112
2021-07-05 01:32:07,116 - INFO - server.EntityManager - [EntityManager.py:139]: addentity  entity id  60e1f0970cf375abff15a505 
2021-07-05 01:32:07,124 - INFO - RudpProtocol - [ConnMgr.py:131]: RUDP ROLE_TYPE_ACTIVE peer_addr=('127.0.0.1', 9203) is connected !!!!
2021-07-05 01:32:20,838 - DEBUG - RpcHandler - [RpcHandler.py:218]: _handle_create_conn: addr=('127.0.0.1', 9101)
2021-07-05 01:32:20,847 - INFO - RudpProtocol - [ConnMgr.py:131]: RUDP ROLE_TYPE_ACTIVE peer_addr=('127.0.0.1', 9101) is connected !!!!
2021-07-05 01:32:20,882 - DEBUG - __main__ - [RudpClient.py:69]: lobby server info: ('gate_2', '127.0.0.1', 9203)
2021-07-05 01:32:20,884 - INFO - ServerEntity.Avatar - [ServerEntity.py:25]: __init__ create entity Avatar with id 60e1f0a432989c705626c99a mem_id=2643402031312
2021-07-05 01:32:20,885 - INFO - server.EntityManager - [EntityManager.py:139]: addentity  entity id  60e1f0a432989c705626c99a 
2021-07-05 01:32:20,892 - INFO - RudpProtocol - [ConnMgr.py:131]: RUDP ROLE_TYPE_ACTIVE peer_addr=('127.0.0.1', 9203) is connected !!!!
2021-07-05 01:44:29,541 - DEBUG - RpcHandler - [RpcHandler.py:218]: _handle_create_conn: addr=('127.0.0.1', 9100)
2021-07-05 01:44:30,157 - WARNING - RudpConn - ["C:\Users\b\Documents\github\realtime-server\pycharm2020.1.3\script\RudpConn.py:67"]: try reconnect rudp: ('127.0.0.1', 9100) ... 1
2021-07-05 01:44:30,766 - WARNING - RudpConn - ["C:\Users\b\Documents\github\realtime-server\pycharm2020.1.3\script\RudpConn.py:67"]: try reconnect rudp: ('127.0.0.1', 9100) ... 2
2021-07-05 01:44:31,372 - WARNING - RudpConn - ["C:\Users\b\Documents\github\realtime-server\pycharm2020.1.3\script\RudpConn.py:67"]: try reconnect rudp: ('127.0.0.1', 9100) ... 3
2021-07-05 01:44:31,980 - WARNING - RudpConn - ["C:\Users\b\Documents\github\realtime-server\pycharm2020.1.3\script\RudpConn.py:67"]: try reconnect rudp: ('127.0.0.1', 9100) ... 4
2021-07-05 01:44:32,556 - ERROR - __main__ - ["C:/Users/b/Documents/github/realtime-server/pycharm2020.1.3/script/client/RudpClient.py:58"]: _err="request rpc timeout, rpc_fuc_name='pick_lowest_load_service_addr', rpc_fuc_args=['lobby_gate'], rpc_fuc_kwargs={}"
2021-07-05 01:44:32,560 - DEBUG - RpcHandler - [RpcHandler.py:218]: _handle_create_conn: addr=('127.0.0.1', 9101)
2021-07-05 01:44:32,567 - INFO - RudpProtocol - [ConnMgr.py:131]: RUDP ROLE_TYPE_ACTIVE peer_addr=('127.0.0.1', 9101) is connected !!!!
2021-07-05 01:44:32,569 - WARNING - RudpConn - ["C:\Users\b\Documents\github\realtime-server\pycharm2020.1.3\script\RudpConn.py:67"]: try reconnect rudp: ('127.0.0.1', 9100) ... 5
2021-07-05 01:44:32,607 - DEBUG - __main__ - [RudpClient.py:69]: lobby server info: ('gate_1', '127.0.0.1', 9202)
2021-07-05 01:44:32,610 - INFO - ServerEntity.Avatar - [ServerEntity.py:25]: __init__ create entity Avatar with id 60e1f38087da6316f141891f mem_id=2696939777904
2021-07-05 01:44:32,611 - INFO - server.EntityManager - [EntityManager.py:139]: addentity  entity id  60e1f38087da6316f141891f 
2021-07-05 01:44:32,621 - WARNING - RpcHandler - ["C:\Users\b\Documents\github\realtime-server\pycharm2020.1.3\script\RpcHandler.py:239"]: cancel _handle_create_conn task addr=('127.0.0.1', 9100)
2021-07-05 01:44:32,624 - INFO - RudpProtocol - [ConnMgr.py:131]: RUDP ROLE_TYPE_ACTIVE peer_addr=('127.0.0.1', 9202) is connected !!!!
