2021-06-26 21:59:42,206 - DEBUG - ServerEntity.ServerEntity - [ServerEntity.py:23]: __init__ create entity ServerEntity with id 60d732ce5ca44ca18bdff830 mem_id=2438522406512
2021-06-26 21:59:42,208 - DEBUG - server.EntityManager - [EntityManager.py:139]: addentity  entity id  60d732ce5ca44ca18bdff830 
2021-06-26 22:00:20,559 - DEBUG - ServerEntity.ServerEntity - [ServerEntity.py:23]: __init__ create entity ServerEntity with id 60d732f43bab41c70bded825 mem_id=1468015207808
2021-06-26 22:00:20,560 - DEBUG - server.EntityManager - [EntityManager.py:139]: addentity  entity id  60d732f43bab41c70bded825 
2021-06-26 22:17:14,233 - DEBUG - ServerEntity.ServerEntity - [ServerEntity.py:23]: __init__ create entity ServerEntity with id 60d736ea05785a9729808610 mem_id=2228301865024
2021-06-26 22:17:14,234 - DEBUG - server.EntityManager - [EntityManager.py:139]: addentity  entity id  60d736ea05785a9729808610 
2021-06-26 22:17:14,286 - DEBUG - __main__ - [TcpClient2.py:61]: bs: ('gate_0', '127.0.0.1', 9201)
2021-06-26 22:17:14,300 - DEBUG - ServerEntity.Avatar - [ServerEntity.py:23]: __init__ create entity Avatar with id 60d736ea05785a9729808611 mem_id=2228301868336
2021-06-26 22:17:14,304 - DEBUG - server.EntityManager - [EntityManager.py:139]: addentity  entity id  60d736ea05785a9729808611 
2021-06-26 22:17:22,331 - WARNING - TcpConn - [TcpConn.py:173]: the peer has performed an orderly shutdown (recv 0 byte).
2021-06-26 22:17:30,352 - WARNING - TcpConn - [TcpConn.py:173]: the peer has performed an orderly shutdown (recv 0 byte).
2021-06-26 22:17:38,387 - WARNING - TcpConn - [TcpConn.py:173]: the peer has performed an orderly shutdown (recv 0 byte).
2021-06-26 22:17:46,373 - WARNING - TcpConn - [TcpConn.py:173]: connection is closed by error: [WinError 64] The specified network name is no longer available
2021-06-26 22:17:48,424 - ERROR - RpcHandler - [RpcHandler.py:193]: [WinError 1225] The remote computer refused the network connection
2021-06-26 22:17:48,428 - WARNING - RpcHandler - [RpcHandler.py:195]: try reconnect ('127.0.0.1', 9201) ... 1
2021-06-26 22:26:16,486 - DEBUG - ServerEntity.ServerEntity - [ServerEntity.py:23]: __init__ create entity ServerEntity with id 60d739080f94ea798172579a mem_id=1675582251072
2021-06-26 22:26:16,487 - DEBUG - server.EntityManager - [EntityManager.py:139]: addentity  entity id  60d739080f94ea798172579a 
2021-06-26 22:26:16,522 - DEBUG - __main__ - [TcpClient2.py:61]: bs: ('gate_0', '127.0.0.1', 9201)
2021-06-26 22:26:16,529 - DEBUG - ServerEntity.Avatar - [ServerEntity.py:23]: __init__ create entity Avatar with id 60d739080f94ea798172579b mem_id=1675582254384
2021-06-26 22:26:16,533 - DEBUG - server.EntityManager - [EntityManager.py:139]: addentity  entity id  60d739080f94ea798172579b 
2021-06-26 22:26:24,565 - WARNING - TcpConn - [TcpConn.py:173]: the peer has performed an orderly shutdown (recv 0 byte).
2021-06-26 22:26:30,238 - WARNING - TcpConn - [TcpConn.py:173]: connection is closed by error: [WinError 64] The specified network name is no longer available
2021-06-26 22:26:32,253 - ERROR - RpcHandler - [RpcHandler.py:193]: [WinError 1225] The remote computer refused the network connection
2021-06-26 22:26:32,259 - WARNING - RpcHandler - [RpcHandler.py:195]: try reconnect ('127.0.0.1', 9201) ... 1
2021-06-26 22:26:32,873 - WARNING - RpcHandler - [RpcHandler.py:185]: bbb _try_connect_times=1, id(self._conn)= 1675582669632
2021-06-26 22:26:34,910 - ERROR - RpcHandler - [RpcHandler.py:193]: [WinError 1225] The remote computer refused the network connection
2021-06-26 22:26:34,916 - WARNING - RpcHandler - [RpcHandler.py:195]: try reconnect ('127.0.0.1', 9201) ... 2
2021-06-26 22:26:35,529 - WARNING - RpcHandler - [RpcHandler.py:185]: bbb _try_connect_times=2, id(self._conn)= 1675582669632
2021-06-26 22:26:37,559 - ERROR - RpcHandler - [RpcHandler.py:193]: [WinError 1225] The remote computer refused the network connection
2021-06-26 22:26:37,564 - WARNING - RpcHandler - [RpcHandler.py:195]: try reconnect ('127.0.0.1', 9201) ... 3
2021-06-26 22:26:38,177 - WARNING - RpcHandler - [RpcHandler.py:185]: bbb _try_connect_times=3, id(self._conn)= 1675582669632
2021-06-26 22:27:31,300 - DEBUG - ServerEntity.ServerEntity - [ServerEntity.py:23]: __init__ create entity ServerEntity with id 60d73953dd97898174566f02 mem_id=2779233136896
2021-06-26 22:27:31,301 - DEBUG - server.EntityManager - [EntityManager.py:139]: addentity  entity id  60d73953dd97898174566f02 
2021-06-26 22:27:31,337 - DEBUG - __main__ - [TcpClient2.py:61]: bs: ('gate_0', '127.0.0.1', 9201)
2021-06-26 22:27:31,347 - DEBUG - ServerEntity.Avatar - [ServerEntity.py:23]: __init__ create entity Avatar with id 60d73953dd97898174566f03 mem_id=2779233140160
2021-06-26 22:27:31,350 - DEBUG - server.EntityManager - [EntityManager.py:139]: addentity  entity id  60d73953dd97898174566f03 
2021-06-26 22:27:39,384 - WARNING - TcpConn - [TcpConn.py:173]: heartbeat timeout
2021-06-26 22:27:47,419 - WARNING - TcpConn - [TcpConn.py:173]: heartbeat timeout
2021-06-26 22:27:55,445 - WARNING - TcpConn - [TcpConn.py:173]: heartbeat timeout
2021-06-26 22:28:03,472 - WARNING - TcpConn - [TcpConn.py:173]: heartbeat timeout
2021-06-26 22:28:11,502 - WARNING - TcpConn - [TcpConn.py:173]: heartbeat timeout
2021-06-26 22:28:19,537 - WARNING - TcpConn - [TcpConn.py:173]: heartbeat timeout
2021-06-26 22:28:27,563 - WARNING - TcpConn - [TcpConn.py:173]: heartbeat timeout
2021-06-26 22:28:35,595 - WARNING - TcpConn - [TcpConn.py:173]: heartbeat timeout
2021-06-26 22:28:43,627 - WARNING - TcpConn - [TcpConn.py:173]: heartbeat timeout
2021-06-26 22:28:51,654 - WARNING - TcpConn - [TcpConn.py:173]: heartbeat timeout
2021-06-26 22:28:59,672 - WARNING - TcpConn - [TcpConn.py:173]: heartbeat timeout
2021-06-26 22:29:07,718 - WARNING - TcpConn - [TcpConn.py:173]: heartbeat timeout
2021-06-26 22:29:15,757 - WARNING - TcpConn - [TcpConn.py:173]: heartbeat timeout
2021-06-26 22:29:23,781 - WARNING - TcpConn - [TcpConn.py:173]: heartbeat timeout
2021-06-26 22:29:31,819 - WARNING - TcpConn - [TcpConn.py:173]: heartbeat timeout
2021-06-26 22:29:39,849 - WARNING - TcpConn - [TcpConn.py:173]: heartbeat timeout
2021-06-26 22:29:47,874 - WARNING - TcpConn - [TcpConn.py:173]: heartbeat timeout
2021-06-26 22:29:55,920 - WARNING - TcpConn - [TcpConn.py:173]: heartbeat timeout
2021-06-26 22:30:03,959 - WARNING - TcpConn - [TcpConn.py:173]: heartbeat timeout
2021-06-26 22:30:11,993 - WARNING - TcpConn - [TcpConn.py:173]: heartbeat timeout
2021-06-26 22:30:20,003 - WARNING - TcpConn - [TcpConn.py:173]: heartbeat timeout
2021-06-26 22:30:28,046 - WARNING - TcpConn - [TcpConn.py:173]: heartbeat timeout
2021-06-26 22:30:36,060 - WARNING - TcpConn - [TcpConn.py:173]: heartbeat timeout
2021-06-26 22:30:44,090 - WARNING - TcpConn - [TcpConn.py:173]: heartbeat timeout
2021-06-26 22:30:52,120 - WARNING - TcpConn - [TcpConn.py:173]: heartbeat timeout
2021-06-26 22:31:00,129 - WARNING - TcpConn - [TcpConn.py:173]: heartbeat timeout
2021-06-26 22:31:08,157 - WARNING - TcpConn - [TcpConn.py:173]: heartbeat timeout
2021-06-26 22:33:07,739 - DEBUG - ServerEntity.ServerEntity - [ServerEntity.py:23]: __init__ create entity ServerEntity with id 60d73aa3c1f2a7beabaa416f mem_id=2239021715760
2021-06-26 22:33:07,739 - DEBUG - server.EntityManager - [EntityManager.py:139]: addentity  entity id  60d73aa3c1f2a7beabaa416f 
2021-06-26 22:33:07,771 - DEBUG - __main__ - [TcpClient2.py:61]: bs: ('gate_0', '127.0.0.1', 9201)
2021-06-26 22:33:07,801 - DEBUG - ServerEntity.Avatar - [ServerEntity.py:23]: __init__ create entity Avatar with id 60d73aa3c1f2a7beabaa4170 mem_id=2239021719024
2021-06-26 22:33:07,802 - DEBUG - server.EntityManager - [EntityManager.py:139]: addentity  entity id  60d73aa3c1f2a7beabaa4170 
2021-06-26 22:33:15,836 - WARNING - TcpConn - [TcpConn.py:173]: heartbeat timeout
2021-06-26 22:33:23,855 - WARNING - TcpConn - [TcpConn.py:173]: heartbeat timeout
2021-06-26 22:33:31,860 - WARNING - TcpConn - [TcpConn.py:173]: heartbeat timeout
2021-06-26 22:33:39,890 - WARNING - TcpConn - [TcpConn.py:173]: heartbeat timeout
2021-06-26 22:33:47,932 - WARNING - TcpConn - [TcpConn.py:173]: heartbeat timeout
2021-06-26 22:33:55,970 - WARNING - TcpConn - [TcpConn.py:173]: heartbeat timeout
2021-06-26 22:34:04,009 - WARNING - TcpConn - [TcpConn.py:173]: heartbeat timeout
2021-06-26 22:34:12,034 - WARNING - TcpConn - [TcpConn.py:173]: heartbeat timeout
2021-06-26 22:34:20,064 - WARNING - TcpConn - [TcpConn.py:173]: heartbeat timeout
2021-06-26 22:34:28,099 - WARNING - TcpConn - [TcpConn.py:173]: heartbeat timeout
2021-06-26 22:34:36,129 - WARNING - TcpConn - [TcpConn.py:173]: heartbeat timeout
2021-06-26 22:34:44,164 - WARNING - TcpConn - [TcpConn.py:173]: heartbeat timeout
2021-06-26 22:34:52,194 - WARNING - TcpConn - [TcpConn.py:173]: heartbeat timeout
2021-06-26 22:35:00,223 - WARNING - TcpConn - [TcpConn.py:173]: heartbeat timeout
2021-06-26 22:35:08,256 - WARNING - TcpConn - [TcpConn.py:173]: heartbeat timeout
2021-06-26 22:35:09,378 - WARNING - TcpConn - [TcpConn.py:173]: connection is closed by error: [WinError 64] The specified network name is no longer available
2021-06-26 22:35:25,654 - DEBUG - ServerEntity.ServerEntity - [ServerEntity.py:23]: __init__ create entity ServerEntity with id 60d73b2d54395f3c8f249010 mem_id=1607035912832
2021-06-26 22:35:25,655 - DEBUG - server.EntityManager - [EntityManager.py:139]: addentity  entity id  60d73b2d54395f3c8f249010 
2021-06-26 22:35:25,691 - DEBUG - __main__ - [TcpClient2.py:61]: bs: ('gate_0', '127.0.0.1', 9201)
2021-06-26 22:35:25,706 - DEBUG - ServerEntity.Avatar - [ServerEntity.py:23]: __init__ create entity Avatar with id 60d73b2d54395f3c8f249011 mem_id=1607035915856
2021-06-26 22:35:25,711 - DEBUG - server.EntityManager - [EntityManager.py:139]: addentity  entity id  60d73b2d54395f3c8f249011 
2021-06-26 22:35:33,735 - WARNING - TcpConn - [TcpConn.py:173]: heartbeat timeout
2021-06-26 22:35:41,759 - WARNING - TcpConn - [TcpConn.py:173]: heartbeat timeout
2021-06-26 22:35:49,794 - WARNING - TcpConn - [TcpConn.py:173]: heartbeat timeout
2021-06-26 22:35:57,821 - WARNING - TcpConn - [TcpConn.py:173]: heartbeat timeout
2021-06-26 22:36:05,845 - WARNING - TcpConn - [TcpConn.py:173]: heartbeat timeout
2021-06-26 22:36:13,874 - WARNING - TcpConn - [TcpConn.py:173]: heartbeat timeout
2021-06-26 22:36:21,901 - WARNING - TcpConn - [TcpConn.py:173]: heartbeat timeout
2021-06-26 22:36:29,935 - WARNING - TcpConn - [TcpConn.py:173]: heartbeat timeout
2021-06-26 22:36:37,971 - WARNING - TcpConn - [TcpConn.py:173]: heartbeat timeout
2021-06-26 22:36:38,753 - WARNING - TcpConn - [TcpConn.py:173]: connection is closed by error: [WinError 64] The specified network name is no longer available
2021-06-26 22:36:40,792 - ERROR - RpcHandler - [RpcHandler.py:193]: [WinError 1225] The remote computer refused the network connection
2021-06-26 22:36:40,795 - WARNING - RpcHandler - [RpcHandler.py:195]: try reconnect ('127.0.0.1', 9201) ... 1
2021-06-26 22:36:41,408 - WARNING - RpcHandler - [RpcHandler.py:185]: bbb _try_connect_times=1, id(self._conn)= 1607036333888
2021-06-26 22:36:41,422 - WARNING - RpcHandler - [RpcHandler.py:190]: aaa _try_connect_times=2, id(self._conn)= 1607036572144
2021-06-26 22:36:41,425 - WARNING - RpcHandler - [RpcHandler.py:212]: rrr _try_connect_times=2, id(self._conn)= 1607036572144
2021-06-26 22:36:43,992 - DEBUG - ServerEntity.ServerEntity - [ServerEntity.py:23]: __init__ create entity ServerEntity with id 60d73b7b03f40cc3a35e112b mem_id=2534013326048
2021-06-26 22:36:43,993 - DEBUG - server.EntityManager - [EntityManager.py:139]: addentity  entity id  60d73b7b03f40cc3a35e112b 
2021-06-26 22:36:44,032 - DEBUG - __main__ - [TcpClient2.py:61]: bs: ('gate_0', '127.0.0.1', 9201)
2021-06-26 22:36:44,043 - DEBUG - ServerEntity.Avatar - [ServerEntity.py:23]: __init__ create entity Avatar with id 60d73b7c03f40cc3a35e112c mem_id=2534013329072
2021-06-26 22:36:44,046 - DEBUG - server.EntityManager - [EntityManager.py:139]: addentity  entity id  60d73b7c03f40cc3a35e112c 
2021-06-26 22:36:52,061 - WARNING - TcpConn - [TcpConn.py:173]: heartbeat timeout
2021-06-26 22:37:00,087 - WARNING - TcpConn - [TcpConn.py:173]: heartbeat timeout
2021-06-26 22:37:08,087 - WARNING - TcpConn - [TcpConn.py:173]: heartbeat timeout
2021-06-26 22:37:16,095 - WARNING - TcpConn - [TcpConn.py:173]: heartbeat timeout
2021-06-26 22:37:24,118 - WARNING - TcpConn - [TcpConn.py:173]: heartbeat timeout
2021-06-26 22:37:32,163 - WARNING - TcpConn - [TcpConn.py:173]: heartbeat timeout
2021-06-26 22:37:40,196 - WARNING - TcpConn - [TcpConn.py:173]: heartbeat timeout
2021-06-26 22:37:47,423 - WARNING - TcpConn - [TcpConn.py:173]: connection is closed by error: [WinError 64] The specified network name is no longer available
2021-06-26 22:37:49,480 - ERROR - RpcHandler - [RpcHandler.py:193]: [WinError 1225] The remote computer refused the network connection
2021-06-26 22:37:49,483 - WARNING - RpcHandler - [RpcHandler.py:195]: try reconnect ('127.0.0.1', 9201) ... 1
2021-06-26 22:37:50,080 - WARNING - RpcHandler - [RpcHandler.py:185]: bbb _try_connect_times=1, id(self._conn)= 2534013761760
2021-06-26 22:40:25,723 - DEBUG - ServerEntity.ServerEntity - [ServerEntity.py:23]: __init__ create entity ServerEntity with id 60d73c592209a55c793b747c mem_id=2201818169504
2021-06-26 22:40:25,724 - DEBUG - server.EntityManager - [EntityManager.py:139]: addentity  entity id  60d73c592209a55c793b747c 
2021-06-26 22:40:25,766 - DEBUG - __main__ - [TcpClient2.py:61]: bs: ('gate_0', '127.0.0.1', 9201)
2021-06-26 22:40:25,778 - DEBUG - ServerEntity.Avatar - [ServerEntity.py:23]: __init__ create entity Avatar with id 60d73c592209a55c793b747d mem_id=2201818170272
2021-06-26 22:40:25,783 - DEBUG - server.EntityManager - [EntityManager.py:139]: addentity  entity id  60d73c592209a55c793b747d 
2021-06-26 22:40:33,808 - WARNING - TcpConn - [TcpConn.py:173]: the peer has performed an orderly shutdown (recv 0 byte).
2021-06-26 22:40:41,844 - WARNING - TcpConn - [TcpConn.py:173]: the peer has performed an orderly shutdown (recv 0 byte).
2021-06-26 22:40:49,886 - WARNING - TcpConn - [TcpConn.py:173]: the peer has performed an orderly shutdown (recv 0 byte).
2021-06-26 22:40:57,925 - WARNING - TcpConn - [TcpConn.py:173]: the peer has performed an orderly shutdown (recv 0 byte).
2021-06-26 22:41:05,969 - WARNING - TcpConn - [TcpConn.py:173]: the peer has performed an orderly shutdown (recv 0 byte).
2021-06-26 22:41:14,019 - WARNING - TcpConn - [TcpConn.py:173]: the peer has performed an orderly shutdown (recv 0 byte).
2021-06-26 22:41:22,060 - WARNING - TcpConn - [TcpConn.py:173]: the peer has performed an orderly shutdown (recv 0 byte).
2021-06-26 22:41:30,096 - WARNING - TcpConn - [TcpConn.py:173]: the peer has performed an orderly shutdown (recv 0 byte).
2021-06-26 22:41:38,136 - WARNING - TcpConn - [TcpConn.py:173]: the peer has performed an orderly shutdown (recv 0 byte).
2021-06-26 22:41:41,016 - WARNING - TcpConn - [TcpConn.py:173]: connection is closed by error: [WinError 64] The specified network name is no longer available
2021-06-26 22:42:52,696 - DEBUG - ServerEntity.ServerEntity - [ServerEntity.py:23]: __init__ create entity ServerEntity with id 60d73cecac87676607ccc9f6 mem_id=3017252786528
2021-06-26 22:42:52,697 - DEBUG - server.EntityManager - [EntityManager.py:139]: addentity  entity id  60d73cecac87676607ccc9f6 
2021-06-26 22:42:52,740 - DEBUG - __main__ - [TcpClient2.py:69]: bs: ('gate_0', '127.0.0.1', 9201)
2021-06-26 22:45:58,357 - DEBUG - ServerEntity.ServerEntity - [ServerEntity.py:23]: __init__ create entity ServerEntity with id 60d73da692c5cf4d54ae6215 mem_id=2180608225536
2021-06-26 22:45:58,357 - DEBUG - server.EntityManager - [EntityManager.py:139]: addentity  entity id  60d73da692c5cf4d54ae6215 
2021-06-26 22:46:09,281 - DEBUG - ServerEntity.ServerEntity - [ServerEntity.py:23]: __init__ create entity ServerEntity with id 60d73db12e92a2542d139986 mem_id=2570145693808
2021-06-26 22:46:09,281 - DEBUG - server.EntityManager - [EntityManager.py:139]: addentity  entity id  60d73db12e92a2542d139986 
2021-06-26 22:46:09,313 - DEBUG - __main__ - [TcpClient2.py:70]: bs: ('lobby_0', '127.0.0.1', 10001)
2021-06-26 22:46:09,321 - DEBUG - ServerEntity.Avatar - [ServerEntity.py:23]: __init__ create entity Avatar with id 60d73db12e92a2542d139987 mem_id=2570145697024
2021-06-26 22:46:09,324 - DEBUG - server.EntityManager - [EntityManager.py:139]: addentity  entity id  60d73db12e92a2542d139987 
2021-06-26 22:47:17,270 - DEBUG - ServerEntity.ServerEntity - [ServerEntity.py:23]: __init__ create entity ServerEntity with id 60d73df53afe1f52e2e7ef9d mem_id=2485788475504
2021-06-26 22:47:17,271 - DEBUG - server.EntityManager - [EntityManager.py:139]: addentity  entity id  60d73df53afe1f52e2e7ef9d 
2021-06-26 22:47:17,302 - DEBUG - __main__ - [TcpClient2.py:70]: bs: ('lobby_0', '127.0.0.1', 10001)
2021-06-26 22:47:17,311 - DEBUG - ServerEntity.Avatar - [ServerEntity.py:23]: __init__ create entity Avatar with id 60d73df53afe1f52e2e7ef9e mem_id=2485788478720
2021-06-26 22:47:17,315 - DEBUG - server.EntityManager - [EntityManager.py:139]: addentity  entity id  60d73df53afe1f52e2e7ef9e 
2021-06-26 22:48:36,133 - DEBUG - ServerEntity.ServerEntity - [ServerEntity.py:23]: __init__ create entity ServerEntity with id 60d73e442ef0df252c1082b0 mem_id=1947844731088
2021-06-26 22:48:36,134 - DEBUG - server.EntityManager - [EntityManager.py:139]: addentity  entity id  60d73e442ef0df252c1082b0 
2021-06-26 22:48:36,163 - DEBUG - __main__ - [TcpClient2.py:71]: bs: ('gate_0', '127.0.0.1', 9201)
2021-06-26 22:48:36,172 - DEBUG - ServerEntity.Avatar - [ServerEntity.py:23]: __init__ create entity Avatar with id 60d73e442ef0df252c1082b1 mem_id=1947844734304
2021-06-26 22:48:36,176 - DEBUG - server.EntityManager - [EntityManager.py:139]: addentity  entity id  60d73e442ef0df252c1082b1 
2021-06-26 22:48:44,181 - WARNING - TcpConn - [TcpConn.py:173]: the peer has performed an orderly shutdown (recv 0 byte).
2021-06-26 22:50:25,997 - DEBUG - ServerEntity.ServerEntity - [ServerEntity.py:23]: __init__ create entity ServerEntity with id 60d73eb13516560a14db4830 mem_id=1952086294832
2021-06-26 22:50:25,997 - DEBUG - server.EntityManager - [EntityManager.py:139]: addentity  entity id  60d73eb13516560a14db4830 
2021-06-26 22:50:26,030 - DEBUG - __main__ - [TcpClient2.py:71]: bs: ('gate_0', '127.0.0.1', 9201)
2021-06-26 22:50:26,038 - DEBUG - ServerEntity.Avatar - [ServerEntity.py:23]: __init__ create entity Avatar with id 60d73eb23516560a14db4831 mem_id=1952086298048
2021-06-26 22:50:26,042 - DEBUG - server.EntityManager - [EntityManager.py:139]: addentity  entity id  60d73eb23516560a14db4831 
2021-06-26 22:50:34,059 - WARNING - TcpConn - [TcpConn.py:173]: the peer has performed an orderly shutdown (recv 0 byte).
2021-06-26 22:50:42,076 - WARNING - TcpConn - [TcpConn.py:173]: the peer has performed an orderly shutdown (recv 0 byte).
2021-06-26 22:50:50,104 - WARNING - TcpConn - [TcpConn.py:173]: the peer has performed an orderly shutdown (recv 0 byte).
2021-06-26 22:50:58,120 - WARNING - TcpConn - [TcpConn.py:173]: the peer has performed an orderly shutdown (recv 0 byte).
2021-06-26 22:51:06,127 - WARNING - TcpConn - [TcpConn.py:173]: the peer has performed an orderly shutdown (recv 0 byte).
2021-06-26 22:51:14,170 - WARNING - TcpConn - [TcpConn.py:173]: the peer has performed an orderly shutdown (recv 0 byte).
2021-06-26 22:51:22,202 - WARNING - TcpConn - [TcpConn.py:173]: the peer has performed an orderly shutdown (recv 0 byte).
2021-06-26 22:51:28,703 - WARNING - TcpConn - [TcpConn.py:173]: connection is closed by error: [WinError 64] The specified network name is no longer available
2021-06-26 22:51:38,772 - WARNING - TcpConn - [TcpConn.py:173]: the peer has performed an orderly shutdown (recv 0 byte).
2021-06-26 22:51:46,807 - WARNING - TcpConn - [TcpConn.py:173]: the peer has performed an orderly shutdown (recv 0 byte).
2021-06-26 22:52:49,489 - DEBUG - ServerEntity.ServerEntity - [ServerEntity.py:23]: __init__ create entity ServerEntity with id 60d73f41aaf053240f811081 mem_id=3109338153264
2021-06-26 22:52:49,489 - DEBUG - server.EntityManager - [EntityManager.py:139]: addentity  entity id  60d73f41aaf053240f811081 
2021-06-26 22:52:49,516 - DEBUG - __main__ - [TcpClient2.py:71]: bs: ('gate_0', '127.0.0.1', 9201)
2021-06-26 22:52:49,524 - DEBUG - ServerEntity.Avatar - [ServerEntity.py:23]: __init__ create entity Avatar with id 60d73f41aaf053240f811082 mem_id=3109338156480
2021-06-26 22:52:49,527 - DEBUG - server.EntityManager - [EntityManager.py:139]: addentity  entity id  60d73f41aaf053240f811082 
2021-06-26 22:52:57,558 - WARNING - TcpConn - [TcpConn.py:173]: the peer has performed an orderly shutdown (recv 0 byte).
2021-06-26 22:53:05,590 - WARNING - TcpConn - [TcpConn.py:173]: the peer has performed an orderly shutdown (recv 0 byte).
2021-06-26 22:53:13,607 - WARNING - TcpConn - [TcpConn.py:173]: the peer has performed an orderly shutdown (recv 0 byte).
2021-06-26 22:53:21,635 - WARNING - TcpConn - [TcpConn.py:173]: the peer has performed an orderly shutdown (recv 0 byte).
2021-06-26 22:53:29,666 - WARNING - TcpConn - [TcpConn.py:173]: the peer has performed an orderly shutdown (recv 0 byte).
2021-06-26 22:53:37,692 - WARNING - TcpConn - [TcpConn.py:173]: the peer has performed an orderly shutdown (recv 0 byte).
2021-06-26 22:53:45,723 - WARNING - TcpConn - [TcpConn.py:173]: the peer has performed an orderly shutdown (recv 0 byte).
2021-06-26 22:53:53,752 - WARNING - TcpConn - [TcpConn.py:173]: the peer has performed an orderly shutdown (recv 0 byte).
2021-06-26 22:55:47,396 - DEBUG - ServerEntity.ServerEntity - [ServerEntity.py:23]: __init__ create entity ServerEntity with id 60d73ff3640d21bc3f3c0673 mem_id=1665603404080
2021-06-26 22:55:47,396 - DEBUG - server.EntityManager - [EntityManager.py:139]: addentity  entity id  60d73ff3640d21bc3f3c0673 
2021-06-26 22:55:47,424 - DEBUG - __main__ - [TcpClient2.py:71]: bs: ('gate_0', '127.0.0.1', 9201)
2021-06-26 22:55:47,431 - DEBUG - ServerEntity.Avatar - [ServerEntity.py:23]: __init__ create entity Avatar with id 60d73ff3640d21bc3f3c0674 mem_id=1665603407296
2021-06-26 22:55:47,435 - DEBUG - server.EntityManager - [EntityManager.py:139]: addentity  entity id  60d73ff3640d21bc3f3c0674 
2021-06-26 22:55:55,468 - WARNING - TcpConn - [TcpConn.py:173]: the peer has performed an orderly shutdown (recv 0 byte).
2021-06-26 22:56:03,516 - WARNING - TcpConn - [TcpConn.py:173]: the peer has performed an orderly shutdown (recv 0 byte).
2021-06-26 22:56:09,207 - WARNING - TcpConn - [TcpConn.py:173]: connection is closed by error: [WinError 64] The specified network name is no longer available
2021-06-26 22:59:31,189 - DEBUG - ServerEntity.ServerEntity - [ServerEntity.py:23]: __init__ create entity ServerEntity with id 60d740d38263dea034332182 mem_id=3033257083184
2021-06-26 22:59:31,190 - DEBUG - server.EntityManager - [EntityManager.py:139]: addentity  entity id  60d740d38263dea034332182 
2021-06-26 22:59:31,221 - DEBUG - __main__ - [TcpClient2.py:71]: bs: ('gate_0', '127.0.0.1', 9201)
2021-06-26 22:59:31,230 - DEBUG - ServerEntity.Avatar - [ServerEntity.py:23]: __init__ create entity Avatar with id 60d740d38263dea034332183 mem_id=3033257086400
2021-06-26 22:59:31,233 - DEBUG - server.EntityManager - [EntityManager.py:139]: addentity  entity id  60d740d38263dea034332183 
2021-06-26 22:59:37,349 - ERROR - RpcHandler - [RpcHandler.py:297]: unknown RPC type: 145
2021-06-26 22:59:39,240 - WARNING - TcpConn - [TcpConn.py:173]: the peer has performed an orderly shutdown (recv 0 byte).
2021-06-26 22:59:47,277 - WARNING - TcpConn - [TcpConn.py:173]: the peer has performed an orderly shutdown (recv 0 byte).
2021-06-26 22:59:55,313 - WARNING - TcpConn - [TcpConn.py:173]: the peer has performed an orderly shutdown (recv 0 byte).
2021-06-26 23:00:03,361 - WARNING - TcpConn - [TcpConn.py:173]: the peer has performed an orderly shutdown (recv 0 byte).
2021-06-26 23:00:11,395 - WARNING - TcpConn - [TcpConn.py:173]: the peer has performed an orderly shutdown (recv 0 byte).
2021-06-26 23:00:19,415 - WARNING - TcpConn - [TcpConn.py:173]: the peer has performed an orderly shutdown (recv 0 byte).
2021-06-26 23:00:27,441 - WARNING - TcpConn - [TcpConn.py:173]: the peer has performed an orderly shutdown (recv 0 byte).
2021-06-26 23:00:35,476 - WARNING - TcpConn - [TcpConn.py:173]: the peer has performed an orderly shutdown (recv 0 byte).
2021-06-26 23:00:43,499 - WARNING - TcpConn - [TcpConn.py:173]: the peer has performed an orderly shutdown (recv 0 byte).
2021-06-26 23:00:51,526 - WARNING - TcpConn - [TcpConn.py:173]: the peer has performed an orderly shutdown (recv 0 byte).
2021-06-26 23:07:02,980 - DEBUG - ServerEntity.ServerEntity - [ServerEntity.py:23]: __init__ create entity ServerEntity with id 60d74296a27552585aee9f0b mem_id=2279293317472
2021-06-26 23:07:02,980 - DEBUG - server.EntityManager - [EntityManager.py:139]: addentity  entity id  60d74296a27552585aee9f0b 
2021-06-26 23:07:03,011 - DEBUG - __main__ - [TcpClient2.py:71]: bs: ('gate_0', '127.0.0.1', 9201)
2021-06-26 23:07:03,019 - DEBUG - ServerEntity.Avatar - [ServerEntity.py:23]: __init__ create entity Avatar with id 60d74297a27552585aee9f0c mem_id=2279293320688
2021-06-26 23:07:03,022 - DEBUG - server.EntityManager - [EntityManager.py:139]: addentity  entity id  60d74297a27552585aee9f0c 
2021-06-26 23:07:11,031 - WARNING - TcpConn - [TcpConn.py:173]: the peer has performed an orderly shutdown (recv 0 byte).
2021-06-26 23:07:19,062 - WARNING - TcpConn - [TcpConn.py:173]: the peer has performed an orderly shutdown (recv 0 byte).
2021-06-26 23:07:27,080 - WARNING - TcpConn - [TcpConn.py:173]: the peer has performed an orderly shutdown (recv 0 byte).
2021-06-26 23:07:32,319 - WARNING - TcpConn - [TcpConn.py:173]: connection is closed by error: [WinError 64] The specified network name is no longer available
2021-06-26 23:15:35,786 - DEBUG - ServerEntity.ServerEntity - [ServerEntity.py:23]: __init__ create entity ServerEntity with id 60d7449701b643bc91e27579 mem_id=2230888358048
2021-06-26 23:15:35,786 - DEBUG - server.EntityManager - [EntityManager.py:139]: addentity  entity id  60d7449701b643bc91e27579 
2021-06-26 23:15:35,814 - DEBUG - __main__ - [TcpClient2.py:71]: bs: ('gate_0', '127.0.0.1', 9201)
2021-06-26 23:15:35,821 - DEBUG - ServerEntity.Avatar - [ServerEntity.py:23]: __init__ create entity Avatar with id 60d7449701b643bc91e2757a mem_id=2230888361264
2021-06-26 23:15:35,824 - DEBUG - server.EntityManager - [EntityManager.py:139]: addentity  entity id  60d7449701b643bc91e2757a 
2021-06-26 23:15:41,912 - ERROR - RpcHandler - [RpcHandler.py:297]: unknown RPC type: 145
2021-06-26 23:15:43,850 - WARNING - TcpConn - [TcpConn.py:173]: the peer has performed an orderly shutdown (recv 0 byte).
2021-06-26 23:15:51,873 - WARNING - TcpConn - [TcpConn.py:173]: the peer has performed an orderly shutdown (recv 0 byte).
2021-06-26 23:20:14,305 - DEBUG - ServerEntity.ServerEntity - [ServerEntity.py:23]: __init__ create entity ServerEntity with id 60d745aed21dfdaccf649bb6 mem_id=2333630202160
2021-06-26 23:20:14,305 - DEBUG - server.EntityManager - [EntityManager.py:139]: addentity  entity id  60d745aed21dfdaccf649bb6 
2021-06-26 23:20:14,335 - DEBUG - __main__ - [TcpClient2.py:71]: bs: ('gate_0', '127.0.0.1', 9201)
2021-06-26 23:20:14,344 - DEBUG - ServerEntity.Avatar - [ServerEntity.py:23]: __init__ create entity Avatar with id 60d745aed21dfdaccf649bb7 mem_id=2333630205376
2021-06-26 23:20:14,347 - DEBUG - server.EntityManager - [EntityManager.py:139]: addentity  entity id  60d745aed21dfdaccf649bb7 
2021-06-26 23:20:22,376 - WARNING - TcpConn - [TcpConn.py:173]: the peer has performed an orderly shutdown (recv 0 byte).
2021-06-26 23:20:30,392 - WARNING - TcpConn - [TcpConn.py:173]: the peer has performed an orderly shutdown (recv 0 byte).
2021-06-26 23:20:38,420 - WARNING - TcpConn - [TcpConn.py:173]: the peer has performed an orderly shutdown (recv 0 byte).
2021-06-26 23:20:39,270 - WARNING - TcpConn - [TcpConn.py:173]: connection is closed by error: [WinError 64] The specified network name is no longer available
2021-06-26 23:22:46,615 - DEBUG - ServerEntity.ServerEntity - [ServerEntity.py:24]: __init__ create entity ServerEntity with id 60d746467a3684f8eca28c96 mem_id=2742985027888
2021-06-26 23:22:46,615 - DEBUG - server.EntityManager - [EntityManager.py:139]: addentity  entity id  60d746467a3684f8eca28c96 
2021-06-26 23:22:46,658 - DEBUG - __main__ - [TcpClient2.py:71]: bs: ('gate_0', '127.0.0.1', 9201)
2021-06-26 23:22:46,666 - DEBUG - ServerEntity.Avatar - [ServerEntity.py:24]: __init__ create entity Avatar with id 60d746467a3684f8eca28c97 mem_id=2742985031344
2021-06-26 23:22:46,671 - DEBUG - server.EntityManager - [EntityManager.py:139]: addentity  entity id  60d746467a3684f8eca28c97 
2021-06-26 23:22:52,784 - ERROR - RpcHandler - [RpcHandler.py:297]: unknown RPC type: 145
2021-06-26 23:22:54,695 - WARNING - TcpConn - [TcpConn.py:173]: the peer has performed an orderly shutdown (recv 0 byte).
2021-06-26 23:23:02,728 - WARNING - TcpConn - [TcpConn.py:173]: the peer has performed an orderly shutdown (recv 0 byte).
2021-06-26 23:23:10,752 - WARNING - TcpConn - [TcpConn.py:173]: the peer has performed an orderly shutdown (recv 0 byte).
2021-06-26 23:23:14,918 - WARNING - TcpConn - [TcpConn.py:173]: connection is closed by error: [WinError 64] The specified network name is no longer available
2021-06-26 23:23:33,433 - DEBUG - ServerEntity.ServerEntity - [ServerEntity.py:24]: __init__ create entity ServerEntity with id 60d74675ae2c0adc137e0619 mem_id=1996045025488
2021-06-26 23:23:33,433 - DEBUG - server.EntityManager - [EntityManager.py:139]: addentity  entity id  60d74675ae2c0adc137e0619 
2021-06-26 23:23:33,465 - DEBUG - __main__ - [TcpClient2.py:71]: bs: ('gate_0', '127.0.0.1', 9201)
2021-06-26 23:23:33,472 - DEBUG - ServerEntity.Avatar - [ServerEntity.py:24]: __init__ create entity Avatar with id 60d74675ae2c0adc137e061a mem_id=1996045028944
2021-06-26 23:23:33,476 - DEBUG - server.EntityManager - [EntityManager.py:139]: addentity  entity id  60d74675ae2c0adc137e061a 
2021-06-26 23:23:39,594 - ERROR - RpcHandler - [RpcHandler.py:297]: unknown RPC type: 145
2021-06-26 23:23:41,498 - WARNING - TcpConn - [TcpConn.py:173]: the peer has performed an orderly shutdown (recv 0 byte).
2021-06-26 23:23:49,522 - WARNING - TcpConn - [TcpConn.py:173]: the peer has performed an orderly shutdown (recv 0 byte).
2021-06-26 23:23:55,370 - WARNING - TcpConn - [TcpConn.py:173]: connection is closed by error: [WinError 64] The specified network name is no longer available
2021-06-26 23:25:16,737 - DEBUG - ServerEntity.ServerEntity - [ServerEntity.py:24]: __init__ create entity ServerEntity with id 60d746dc2ab73a762fc21156 mem_id=1512579727520
2021-06-26 23:25:16,738 - DEBUG - server.EntityManager - [EntityManager.py:139]: addentity  entity id  60d746dc2ab73a762fc21156 
2021-06-26 23:25:16,775 - DEBUG - __main__ - [TcpClient2.py:71]: bs: ('lobby_0', '127.0.0.1', 10001)
2021-06-26 23:25:16,785 - DEBUG - ServerEntity.Avatar - [ServerEntity.py:24]: __init__ create entity Avatar with id 60d746dc2ab73a762fc21157 mem_id=1512579730976
2021-06-26 23:25:16,789 - DEBUG - server.EntityManager - [EntityManager.py:139]: addentity  entity id  60d746dc2ab73a762fc21157 
2021-06-26 23:25:48,593 - WARNING - TcpConn - [TcpConn.py:173]: connection is closed by error: [WinError 64] The specified network name is no longer available
2021-06-26 23:25:50,630 - ERROR - RpcHandler - [RpcHandler.py:193]: [WinError 1225] The remote computer refused the network connection
2021-06-26 23:25:50,633 - WARNING - RpcHandler - [RpcHandler.py:195]: try reconnect ('127.0.0.1', 10001) ... 1
2021-06-26 23:25:51,238 - WARNING - RpcHandler - [RpcHandler.py:185]: bbb _try_connect_times=1, id(self._conn)= 1512580158320
2021-06-26 23:25:53,281 - ERROR - RpcHandler - [RpcHandler.py:193]: [WinError 1225] The remote computer refused the network connection
2021-06-26 23:25:53,284 - WARNING - RpcHandler - [RpcHandler.py:195]: try reconnect ('127.0.0.1', 10001) ... 2
2021-06-26 23:25:53,892 - WARNING - RpcHandler - [RpcHandler.py:185]: bbb _try_connect_times=2, id(self._conn)= 1512580158320
2021-06-26 23:32:11,337 - DEBUG - ServerEntity.ServerEntity - [ServerEntity.py:24]: __init__ create entity ServerEntity with id 60d7487b7a9b67ed66a35e84 mem_id=1228148062528
2021-06-26 23:32:11,337 - DEBUG - server.EntityManager - [EntityManager.py:139]: addentity  entity id  60d7487b7a9b67ed66a35e84 
2021-06-26 23:32:11,344 - CRITICAL - ServerEntity.ServerEntity - [ServerEntity.py:96]: on_traceback, type:<class 'AttributeError'>, value:'NoneType' object has no attribute 'is_connected', traceback:<class 'AttributeError'>
'NoneType' object has no attribute 'is_connected'
  File "C:\Users\b\Documents\github\realtime-server\pycharm2020.1.3\script\server_entity\ServerEntity.py", line 90, in call_remote_method
    locals={'self': <server_entity.ServerEntity.ServerEntity object at 0x0000011DF3543940>, 'rpc_fuc_name': 'pick_lowest_load_service_addr', 'rpc_fuc_args': ['battle_server'], 'rpc_fuc_kwargs': None, 'rpc_callback': None, 'rpc_need_reply': True, 'rpc_reply_timeout': None, 'rpc_remote_entity_type': 'LoadCollector', 'ip_port_tuple': None}
  File "C:\Users\b\Documents\github\realtime-server\pycharm2020.1.3\script\RpcHandler.py", line 134, in request_rpc
    locals={'self': <RpcHandler.RpcHandler object at 0x0000011DF3543D00>, 'rpc_fuc_name': 'pick_lowest_load_service_addr', 'rpc_fuc_args': ['battle_server'], 'rpc_fuc_kwargs': {}, 'rpc_callback': None, 'rpc_need_reply': True, 'rpc_reply_timeout': None, 'rpc_remote_entity_type': 'LoadCollector', 'ip_port_tuple': None, '_reply_id': 1, 'msg': (1, 1, 'LoadCollector', 'pick_lowest_load_service_addr', ['battle_server'], {}), '_reply_fut': <Future pending cb=[RpcHandler.request_rpc.<locals>.final_fut_cb() at C:\Users\b\Documents\github\realtime-server\pycharm2020.1.3\script\RpcHandler.py:125] created at C:\Program Files\Python38\lib\asyncio\base_events.py:422>, 'final_fut_cb': <function RpcHandler.request_rpc.<locals>.final_fut_cb at 0x0000011DF364DD30>, '_rpc_reply_fut_obj': <RpcHandler.RpcReplyFuture object at 0x0000011DF3638550>}
  File "C:\Users\b\Documents\github\realtime-server\pycharm2020.1.3\script\RpcHandler.py", line 163, in _send_rpc_msg
    locals={'self': <RpcHandler.RpcHandler object at 0x0000011DF3543D00>, 'msg': (1, 1, 'LoadCollector', 'pick_lowest_load_service_addr', ['battle_server'], {}), 'ip_port_tuple': None}
2021-06-26 23:34:22,628 - DEBUG - ServerEntity.ServerEntity - [ServerEntity.py:24]: __init__ create entity ServerEntity with id 60d748fee7fe97edf43f842d mem_id=2981532616352
2021-06-26 23:34:22,629 - DEBUG - server.EntityManager - [EntityManager.py:139]: addentity  entity id  60d748fee7fe97edf43f842d 
2021-06-26 23:35:00,671 - DEBUG - ServerEntity.ServerEntity - [ServerEntity.py:24]: __init__ create entity ServerEntity with id 60d74924836def87e41002ef mem_id=2429287937744
2021-06-26 23:35:00,671 - DEBUG - server.EntityManager - [EntityManager.py:139]: addentity  entity id  60d74924836def87e41002ef 
2021-06-26 23:37:04,207 - DEBUG - ServerEntity.ServerEntity - [ServerEntity.py:24]: __init__ create entity ServerEntity with id 60d749a059d70a51cd7cdfa1 mem_id=1501130077904
2021-06-26 23:37:04,207 - DEBUG - server.EntityManager - [EntityManager.py:139]: addentity  entity id  60d749a059d70a51cd7cdfa1 
2021-06-26 23:37:17,165 - CRITICAL - ServerEntity.ServerEntity - [ServerEntity.py:96]: on_traceback, type:<class 'AttributeError'>, value:'NoneType' object has no attribute 'is_connected', traceback:<class 'AttributeError'>
'NoneType' object has no attribute 'is_connected'
  File "C:\Users\b\Documents\github\realtime-server\pycharm2020.1.3\script\server_entity\ServerEntity.py", line 90, in call_remote_method
    locals={'self': <server_entity.ServerEntity.ServerEntity object at 0x0000015D825336D0>, 'rpc_fuc_name': 'pick_lowest_load_service_addr', 'rpc_fuc_args': ['battle_server'], 'rpc_fuc_kwargs': None, 'rpc_callback': None, 'rpc_need_reply': True, 'rpc_reply_timeout': 3, 'rpc_remote_entity_type': 'LoadCollector', 'ip_port_tuple': None}
  File "C:\Users\b\Documents\github\realtime-server\pycharm2020.1.3\script\RpcHandler.py", line 134, in request_rpc
    locals={'self': <RpcHandler.RpcHandler object at 0x0000015D82533D60>, 'rpc_fuc_name': 'pick_lowest_load_service_addr', 'rpc_fuc_args': ['battle_server'], 'rpc_fuc_kwargs': {}, 'rpc_callback': None, 'rpc_need_reply': True, 'rpc_reply_timeout': 3, 'rpc_remote_entity_type': 'LoadCollector', 'ip_port_tuple': None, '_reply_id': 1, 'msg': (1, 1, 'LoadCollector', 'pick_lowest_load_service_addr', ['battle_server'], {}), '_reply_fut': <Future pending cb=[RpcHandler.request_rpc.<locals>.final_fut_cb() at C:\Users\b\Documents\github\realtime-server\pycharm2020.1.3\script\RpcHandler.py:125] created at C:\Program Files\Python38\lib\asyncio\base_events.py:422>, 'final_fut_cb': <function RpcHandler.request_rpc.<locals>.final_fut_cb at 0x0000015D8266F280>, '_rpc_reply_fut_obj': <RpcHandler.RpcReplyFuture object at 0x0000015D82629C40>}
  File "C:\Users\b\Documents\github\realtime-server\pycharm2020.1.3\script\RpcHandler.py", line 163, in _send_rpc_msg
    locals={'self': <RpcHandler.RpcHandler object at 0x0000015D82533D60>, 'msg': (1, 1, 'LoadCollector', 'pick_lowest_load_service_addr', ['battle_server'], {}), 'ip_port_tuple': None}
2021-06-26 23:37:37,212 - DEBUG - ServerEntity.ServerEntity - [ServerEntity.py:24]: __init__ create entity ServerEntity with id 60d749c1ced78f9f13a0981a mem_id=2312338687600
2021-06-26 23:37:37,212 - DEBUG - server.EntityManager - [EntityManager.py:139]: addentity  entity id  60d749c1ced78f9f13a0981a 
2021-06-26 23:38:40,914 - DEBUG - ServerEntity.ServerEntity - [ServerEntity.py:24]: __init__ create entity ServerEntity with id 60d74a0044e2f79588e17701 mem_id=1694299080400
2021-06-26 23:38:40,914 - DEBUG - server.EntityManager - [EntityManager.py:139]: addentity  entity id  60d74a0044e2f79588e17701 
2021-06-26 23:38:47,411 - DEBUG - __main__ - [TcpClient.py:53]: bs: ('battle_0', '$BATTLE_SRV_IP$', 11001)
2021-06-26 23:39:03,379 - DEBUG - ServerEntity.ServerEntity - [ServerEntity.py:24]: __init__ create entity ServerEntity with id 60d74a1783bc37627e66b193 mem_id=1518845904640
2021-06-26 23:39:03,380 - DEBUG - server.EntityManager - [EntityManager.py:139]: addentity  entity id  60d74a1783bc37627e66b193 
2021-06-26 23:39:03,409 - DEBUG - __main__ - [TcpClient.py:53]: bs: ('battle_0', '$BATTLE_SRV_IP$', 11001)
2021-06-26 23:40:59,855 - DEBUG - ServerEntity.ServerEntity - [ServerEntity.py:24]: __init__ create entity ServerEntity with id 60d74a8bd5028bbf46b08dd6 mem_id=1967720187648
2021-06-26 23:40:59,855 - DEBUG - server.EntityManager - [EntityManager.py:139]: addentity  entity id  60d74a8bd5028bbf46b08dd6 
2021-06-26 23:40:59,885 - DEBUG - __main__ - [TcpClient.py:53]: bs: ('battle_0', '$BATTLE_SRV_IP$', 11001)
2021-06-26 23:41:37,758 - DEBUG - ServerEntity.ServerEntity - [ServerEntity.py:24]: __init__ create entity ServerEntity with id 60d74ab186decc3180d0d1cc mem_id=1642254645040
2021-06-26 23:41:37,759 - DEBUG - server.EntityManager - [EntityManager.py:139]: addentity  entity id  60d74ab186decc3180d0d1cc 
2021-06-26 23:41:37,792 - DEBUG - __main__ - [TcpClient.py:53]: bs: ('battle_0', '127.0.0.1', 11001)
2021-06-26 23:41:44,850 - DEBUG - ServerEntity.Puppet - [ServerEntity.py:24]: __init__ create entity Puppet with id 60d74ab886decc3180d0d1cd mem_id=1642236614256
2021-06-26 23:41:44,854 - DEBUG - server.EntityManager - [EntityManager.py:139]: addentity  entity id  60d74ab886decc3180d0d1cd 
2021-06-26 23:41:54,609 - WARNING - TcpConn - [TcpConn.py:173]: connection is closed by error: [WinError 64] The specified network name is no longer available
2021-06-26 23:42:25,775 - DEBUG - ServerEntity.ServerEntity - [ServerEntity.py:24]: __init__ create entity ServerEntity with id 60d74ae1ef973972a2b23319 mem_id=2005694480592
2021-06-26 23:42:25,775 - DEBUG - server.EntityManager - [EntityManager.py:139]: addentity  entity id  60d74ae1ef973972a2b23319 
2021-06-26 23:42:25,811 - DEBUG - __main__ - [TcpClient2.py:71]: bs: None
2021-06-26 23:42:56,663 - DEBUG - ServerEntity.ServerEntity - [ServerEntity.py:24]: __init__ create entity ServerEntity with id 60d74b00457831ef5c747539 mem_id=2429097275600
2021-06-26 23:42:56,663 - DEBUG - server.EntityManager - [EntityManager.py:139]: addentity  entity id  60d74b00457831ef5c747539 
2021-06-26 23:42:56,691 - DEBUG - __main__ - [TcpClient2.py:71]: bs: ('lobby_0', '127.0.0.1', 10001)
2021-06-26 23:42:56,699 - DEBUG - ServerEntity.Avatar - [ServerEntity.py:24]: __init__ create entity Avatar with id 60d74b00457831ef5c74753a mem_id=2429097279056
2021-06-26 23:42:56,701 - DEBUG - server.EntityManager - [EntityManager.py:139]: addentity  entity id  60d74b00457831ef5c74753a 
2021-06-26 23:43:27,964 - DEBUG - ServerEntity.ServerEntity - [ServerEntity.py:24]: __init__ create entity ServerEntity with id 60d74b1f58c5c069955f3fba mem_id=2864930685328
2021-06-26 23:43:27,964 - DEBUG - server.EntityManager - [EntityManager.py:139]: addentity  entity id  60d74b1f58c5c069955f3fba 
2021-06-26 23:43:27,993 - DEBUG - __main__ - [TcpClient2.py:71]: bs: ('lobby_0', '127.0.0.1', 10001)
2021-06-26 23:43:28,000 - DEBUG - ServerEntity.Avatar - [ServerEntity.py:24]: __init__ create entity Avatar with id 60d74b1f58c5c069955f3fbb mem_id=2864930688784
2021-06-26 23:43:28,003 - DEBUG - server.EntityManager - [EntityManager.py:139]: addentity  entity id  60d74b1f58c5c069955f3fbb 
2021-06-26 23:43:56,565 - WARNING - TcpConn - [TcpConn.py:173]: connection is closed by error: [WinError 64] The specified network name is no longer available
2021-06-26 23:50:06,003 - DEBUG - ServerEntity.ServerEntity - [ServerEntity.py:24]: __init__ create entity ServerEntity with id 60d74cad019cde250911b6c3 mem_id=2050975011120
2021-06-26 23:50:06,003 - DEBUG - server.EntityManager - [EntityManager.py:139]: addentity  entity id  60d74cad019cde250911b6c3 
2021-06-26 23:50:06,032 - DEBUG - __main__ - [TcpClient2.py:71]: bs: ('lobby_0', '127.0.0.1', 10001)
2021-06-26 23:50:06,039 - DEBUG - ServerEntity.Avatar - [ServerEntity.py:24]: __init__ create entity Avatar with id 60d74cae019cde250911b6c4 mem_id=2050975014576
2021-06-26 23:50:06,042 - DEBUG - server.EntityManager - [EntityManager.py:139]: addentity  entity id  60d74cae019cde250911b6c4 
2021-06-26 23:51:10,132 - WARNING - TcpConn - [TcpConn.py:173]: heartbeat timeout
2021-06-26 23:51:18,137 - WARNING - TcpConn - [TcpConn.py:173]: heartbeat timeout
2021-06-26 23:51:26,149 - WARNING - TcpConn - [TcpConn.py:173]: heartbeat timeout
2021-06-26 23:51:34,163 - WARNING - TcpConn - [TcpConn.py:173]: heartbeat timeout
2021-06-26 23:51:42,174 - WARNING - TcpConn - [TcpConn.py:173]: heartbeat timeout
2021-06-26 23:51:50,189 - WARNING - TcpConn - [TcpConn.py:173]: heartbeat timeout
2021-06-26 23:51:58,212 - WARNING - TcpConn - [TcpConn.py:173]: heartbeat timeout
2021-06-26 23:52:06,213 - WARNING - TcpConn - [TcpConn.py:173]: heartbeat timeout
2021-06-26 23:52:14,216 - WARNING - TcpConn - [TcpConn.py:173]: heartbeat timeout
2021-06-26 23:52:22,227 - WARNING - TcpConn - [TcpConn.py:173]: heartbeat timeout
2021-06-26 23:52:30,237 - WARNING - TcpConn - [TcpConn.py:173]: heartbeat timeout
2021-06-26 23:53:04,275 - WARNING - TcpConn - [TcpConn.py:173]: connection is closed by error: [WinError 64] The specified network name is no longer available
2021-06-26 23:53:11,608 - DEBUG - ServerEntity.ServerEntity - [ServerEntity.py:24]: __init__ create entity ServerEntity with id 60d74d67cb239584633549d5 mem_id=1627806769360
2021-06-26 23:53:11,609 - DEBUG - server.EntityManager - [EntityManager.py:139]: addentity  entity id  60d74d67cb239584633549d5 
2021-06-26 23:53:11,641 - DEBUG - __main__ - [TcpClient2.py:71]: bs: ('lobby_0', '127.0.0.1', 10001)
2021-06-26 23:53:11,649 - DEBUG - ServerEntity.Avatar - [ServerEntity.py:24]: __init__ create entity Avatar with id 60d74d67cb239584633549d6 mem_id=1627806772816
2021-06-26 23:53:11,652 - DEBUG - server.EntityManager - [EntityManager.py:139]: addentity  entity id  60d74d67cb239584633549d6 
2021-06-26 23:53:43,718 - WARNING - TcpConn - [TcpConn.py:173]: heartbeat timeout
2021-06-26 23:53:51,728 - WARNING - TcpConn - [TcpConn.py:173]: heartbeat timeout
2021-06-26 23:53:59,762 - WARNING - TcpConn - [TcpConn.py:173]: heartbeat timeout
2021-06-26 23:54:07,784 - WARNING - TcpConn - [TcpConn.py:173]: heartbeat timeout
2021-06-26 23:54:15,809 - WARNING - TcpConn - [TcpConn.py:173]: heartbeat timeout
2021-06-26 23:54:23,840 - WARNING - TcpConn - [TcpConn.py:173]: heartbeat timeout
2021-06-26 23:54:28,723 - WARNING - TcpConn - [TcpConn.py:173]: connection is closed by error: [WinError 64] The specified network name is no longer available
2021-06-26 23:56:51,778 - DEBUG - ServerEntity.ServerEntity - [ServerEntity.py:24]: __init__ create entity ServerEntity with id 60d74e4397533ed9a984bb78 mem_id=2792878903552
2021-06-26 23:56:51,779 - DEBUG - server.EntityManager - [EntityManager.py:139]: addentity  entity id  60d74e4397533ed9a984bb78 
2021-06-26 23:56:51,810 - DEBUG - __main__ - [TcpClient2.py:71]: bs: ('lobby_0', '127.0.0.1', 10001)
2021-06-26 23:56:51,817 - DEBUG - ServerEntity.Avatar - [ServerEntity.py:24]: __init__ create entity Avatar with id 60d74e4397533ed9a984bb79 mem_id=2792878907008
2021-06-26 23:56:51,820 - DEBUG - server.EntityManager - [EntityManager.py:139]: addentity  entity id  60d74e4397533ed9a984bb79 
