2021-06-26 22:02:52,647 - DEBUG - ServerEntity.ServerEntity - [ServerEntity.py:23]: __init__ create entity ServerEntity with id 60d7338c7a4de35d5c87578d mem_id=1543831541264
2021-06-26 22:02:52,648 - DEBUG - server.EntityManager - [EntityManager.py:139]: addentity  entity id  60d7338c7a4de35d5c87578d 
2021-06-26 22:02:52,742 - DEBUG - __main__ - [TcpClient2.py:61]: bs: ('gate_0', '127.0.0.1', 9201)
2021-06-26 22:02:52,765 - DEBUG - ServerEntity.Avatar - [ServerEntity.py:23]: __init__ create entity Avatar with id 60d7338c7a4de35d5c87578e mem_id=1543831540688
2021-06-26 22:02:52,775 - DEBUG - server.EntityManager - [EntityManager.py:139]: addentity  entity id  60d7338c7a4de35d5c87578e 
2021-06-26 22:03:00,817 - WARNING - TcpConn - [TcpConn.py:173]: the peer has performed an orderly shutdown (recv 0 byte).
2021-06-26 22:03:11,617 - WARNING - TcpConn - [TcpConn.py:173]: heartbeat timeout
2021-06-26 22:03:19,653 - WARNING - TcpConn - [TcpConn.py:173]: the peer has performed an orderly shutdown (recv 0 byte).
2021-06-26 22:03:27,698 - WARNING - TcpConn - [TcpConn.py:173]: the peer has performed an orderly shutdown (recv 0 byte).
2021-06-26 22:03:35,764 - WARNING - TcpConn - [TcpConn.py:173]: the peer has performed an orderly shutdown (recv 0 byte).
2021-06-26 22:13:38,090 - DEBUG - ServerEntity.ServerEntity - [ServerEntity.py:23]: __init__ create entity ServerEntity with id 60d7361275c05b16c44049a2 mem_id=2873612968048
2021-06-26 22:13:38,091 - DEBUG - server.EntityManager - [EntityManager.py:139]: addentity  entity id  60d7361275c05b16c44049a2 
2021-06-26 22:13:38,123 - DEBUG - __main__ - [TcpClient2.py:61]: bs: ('gate_0', '127.0.0.1', 9201)
2021-06-26 22:13:38,130 - DEBUG - ServerEntity.Avatar - [ServerEntity.py:23]: __init__ create entity Avatar with id 60d7361275c05b16c44049a3 mem_id=2873612971264
2021-06-26 22:13:38,134 - DEBUG - server.EntityManager - [EntityManager.py:139]: addentity  entity id  60d7361275c05b16c44049a3 
2021-06-26 22:13:46,156 - WARNING - TcpConn - [TcpConn.py:173]: the peer has performed an orderly shutdown (recv 0 byte).
2021-06-26 22:13:53,789 - WARNING - TcpConn - [TcpConn.py:173]: connection is closed by error: [WinError 64] The specified network name is no longer available
2021-06-26 22:13:55,842 - ERROR - RpcHandler - [RpcHandler.py:193]: [WinError 1225] The remote computer refused the network connection
2021-06-26 22:13:55,847 - WARNING - RpcHandler - [RpcHandler.py:195]: try reconnect ('127.0.0.1', 9201) ... 1
2021-06-26 22:13:56,448 - WARNING - RpcHandler - [RpcHandler.py:185]: bbb _try_connect_times=1, id(self._conn)= 2873613390704
2021-06-26 22:13:58,491 - ERROR - RpcHandler - [RpcHandler.py:193]: [WinError 1225] The remote computer refused the network connection
2021-06-26 22:13:58,496 - WARNING - RpcHandler - [RpcHandler.py:195]: try reconnect ('127.0.0.1', 9201) ... 2
2021-06-26 22:13:59,117 - WARNING - RpcHandler - [RpcHandler.py:185]: bbb _try_connect_times=2, id(self._conn)= 2873613390704
2021-06-26 22:14:01,164 - ERROR - RpcHandler - [RpcHandler.py:193]: [WinError 1225] The remote computer refused the network connection
2021-06-26 22:14:01,169 - WARNING - RpcHandler - [RpcHandler.py:195]: try reconnect ('127.0.0.1', 9201) ... 3
2021-06-26 22:14:01,790 - WARNING - RpcHandler - [RpcHandler.py:185]: bbb _try_connect_times=3, id(self._conn)= 2873613390704
2021-06-26 22:14:03,844 - ERROR - RpcHandler - [RpcHandler.py:193]: [WinError 1225] The remote computer refused the network connection
2021-06-26 22:14:03,850 - WARNING - RpcHandler - [RpcHandler.py:195]: try reconnect ('127.0.0.1', 9201) ... 4
2021-06-26 22:14:04,468 - WARNING - RpcHandler - [RpcHandler.py:185]: bbb _try_connect_times=4, id(self._conn)= 2873613390704
2021-06-26 22:14:06,513 - ERROR - RpcHandler - [RpcHandler.py:193]: [WinError 1225] The remote computer refused the network connection
2021-06-26 22:14:06,517 - WARNING - RpcHandler - [RpcHandler.py:195]: try reconnect ('127.0.0.1', 9201) ... 5
2021-06-26 22:14:07,136 - WARNING - RpcHandler - [RpcHandler.py:185]: bbb _try_connect_times=5, id(self._conn)= 2873613390704
